Workbook
Name Level2ManDays: 【別紙1】最適化条件の精度パターン!Level2ManDays
Name Level2ManDays: 【別紙2】最適化後のボクセル内パターン!Level2ManDays
Name Level2ManDays: 【別紙3】最適化後のボクセルが重複パターン!Level2ManDays
Name Level2ManDays: 【別紙4】最適化前の精度パターン!Level2ManDays
Name Level2ManDays: 【別紙5】最適化後の精度パターン!Level2ManDays
Name Level2ManDays: 変更履歴!Level2ManDays
Name Level2ManDays: [0]!Level2ManDays

Sheet 表紙
AB1: 最適化
B7: ="空間ID開発(GO言語版) "&AB1 -> 空間ID開発(GO言語版) 最適化
B17: 結合試験項目書
B20: =CONCATENATE(TEXT(MAX(変更履歴!C3:C7),"0.00"), "版") -> 1.00版
B23: 44956

Sheet 変更履歴
B2: 日時 | C2: 版 | D2: 変更箇所 | E2: 作業者 | F2: 変更内容
B3: 44956 | C3: 1 | D3: 全ページ | E3: α | F3: 新規改定

Sheet 集計
A1: 集計
B2: 試験シート | C2: 全項目数 | D2: 実施済み | E2: 未実施
B3: 1.結合試験 | C3: =VLOOKUP(B3,$B$8:$D$11,3,FALSE) -> 71 | D3: {=COUNTIF(INDIRECT(B3&"!$K$3:$K$1024"),"OK")-SUMPRODUCT((OFFSET(INDIRECT(B3&"!$K$3:$K$1024"),,)="OK")*(OFFSET(INDIRECT(B3&"!$M$3:$M$1024"),,)<>""))} -> 71 | E3: =C3-D3 -> 0
B4: 計 | C4: =SUM(C3:C3) -> 71 | D4: =SUM(D3:D3) -> 71 | E4: =SUM(E3:E3) -> 0
B6: 試験項目数内訳
B8: 1.結合試験 | C8: 全項目数 | D8: =SUM(D9:D11) -> 71
C9: 正常 | D9: {=COUNTIF(INDIRECT(B8&"!$E$3:$E$1024"),C9)-SUMPRODUCT((OFFSET(INDIRECT(B8&"!$E$3:$E$1024"),,)=C9)*(OFFSET(INDIRECT(B8&"!$M$3:$M$1024"),,)<>""))} -> 48
C10: 準正常 | D10: {=COUNTIF(INDIRECT(B8&"!$E$3:$E$1024"),C10)-SUMPRODUCT((OFFSET(INDIRECT(B8&"!$E$3:$E$1024"),,)=C10)*(OFFSET(INDIRECT(B8&"!$M$3:$M$1024"),,)<>""))} -> 23
C11: 異常 | D11: {=COUNTIF(INDIRECT(B8&"!$E$3:$E$1024"),C11)-SUMPRODUCT((OFFSET(INDIRECT(B8&"!$E$3:$E$1024"),,)=C11)*(OFFSET(INDIRECT(B8&"!$M$3:$M$1024"),,)<>""))} -> 0

Sheet 1.結合試験
A1: =MID(CELL("filename",$A$1),FIND("]",CELL("filename",$A$1))+3,31) -> 結合試験 | K1: OK, NG | R1: シート番号 | S1: =VALUE(MID(CELL("filename",$A$1),FIND("]",CELL("filename",$A$1))+1,2)) -> 1
A2: No | B2: 大項目 | C2: 中項目 | D2: 小項目 | E2: 試験種別 | F2: 優先度 | G2: 確認手順 | H2: 確認内容 | I2: 試験日 | J2: 試験者 | K2: 試験結果 | L2: 備考 | M2: 重複項目 | R2: 大番号 | S2: 中番号 | T2: 小番号
A3: =IF(B3<>"",表紙!$AB$1&"-"&"結合-"&TEXT($S$1,"00")&"-"&TEXT(R3,"00")&"-"&TEXT(S3,"00")&"-"&TEXT(T3,"０00"),"") -> 最適化-結合-01-01-01-001 | B3: パラメータ入力チェック(拡張空間ID) | C3: 精度閾値を超過した値を入力する | D3: 水平方向精度：36 | E3: 準正常 | G3: 1. 引数に以下を指定して、integrate.MergeExtendedSpatialIdsを呼び出す。 拡張空間ID配列：正常な任意の値 水平方向精度： 36 垂直方向精度： 正常な任意の値 | H3: ・以下のspatialIdErrorが返却されること - エラーコード：InputValueError - エラーメッセージ：入力チェックエラー | I3: 44958 | J3: 宮原 | K3: OK | R3: =IF(ROW()<>3,IF(B2<>B3,#REF!+1,#REF!),1) -> 1 | S3: =IF(B2=B3,IF(C2<>C3,#REF!+1,#REF!),1) -> 1 | T3: =IF(B2<>B3,1,IF(C2=C3,#REF!+1,1)) -> 1
A4: =IF(B4<>"",表紙!$AB$1&"-"&"結合-"&TEXT($S$1,"00")&"-"&TEXT(R4,"00")&"-"&TEXT(S4,"00")&"-"&TEXT(T4,"０00"),"") -> 最適化-結合-01-01-01-002 | B4: パラメータ入力チェック(拡張空間ID) | C4: 精度閾値を超過した値を入力する | D4: 水平方向精度：-1 | E4: 準正常 | G4: 1. 引数に以下を指定して、integrate.MergeExtendedSpatialIdsを呼び出す。 拡張空間ID配列：正常な任意の値 水平方向精度： -1 垂直方向精度： 正常な任意の値 | H4: ・以下のspatialIdErrorが返却されること - エラーコード：InputValueError - エラーメッセージ：入力チェックエラー | I4: 44958 | J4: 宮原 | K4: OK | R4: =IF(ROW()<>3,IF(B3<>B4,R3+1,R3),1) -> 1 | S4: =IF(B3=B4,IF(C3<>C4,S3+1,S3),1) -> 1 | T4: =IF(B3<>B4,1,IF(C3=C4,T3+1,1)) -> 2
A5: =IF(B5<>"",表紙!$AB$1&"-"&"結合-"&TEXT($S$1,"00")&"-"&TEXT(R5,"00")&"-"&TEXT(S5,"00")&"-"&TEXT(T5,"０00"),"") -> 最適化-結合-01-01-01-003 | B5: パラメータ入力チェック(拡張空間ID) | C5: 精度閾値を超過した値を入力する | D5: 垂直方向精度：36 | E5: 準正常 | G5: 1. 引数に以下を指定して、integrate.MergeExtendedSpatialIdsを呼び出す。 拡張空間ID配列：正常な任意の値 水平方向精度： 正常な任意の値 垂直方向精度 ： 36 | H5: ・以下のspatialIdErrorが返却されること - エラーコード：InputValueError - エラーメッセージ：入力チェックエラー | I5: 44958 | J5: 宮原 | K5: OK | R5: =IF(ROW()<>3,IF(B4<>B5,R4+1,R4),1) -> 1 | S5: =IF(B4=B5,IF(C4<>C5,S4+1,S4),1) -> 1 | T5: =IF(B4<>B5,1,IF(C4=C5,T4+1,1)) -> 3
A6: =IF(B6<>"",表紙!$AB$1&"-"&"結合-"&TEXT($S$1,"00")&"-"&TEXT(R6,"00")&"-"&TEXT(S6,"00")&"-"&TEXT(T6,"０00"),"") -> 最適化-結合-01-01-01-004 | B6: パラメータ入力チェック(拡張空間ID) | C6: 精度閾値を超過した値を入力する | D6: 垂直方向精度：-1 | E6: 準正常 | G6: 1. 引数に以下を指定して、integrate.MergeExtendedSpatialIdsを呼び出す。 拡張空間ID配列：正常な任意の値 水平方向精度 ： 正常な任意の値 垂直方向精度 ： -1 | H6: ・以下のspatialIdErrorが返却されること - エラーコード：InputValueError - エラーメッセージ：入力チェックエラー | I6: 44958 | J6: 宮原 | K6: OK | R6: =IF(ROW()<>3,IF(B5<>B6,R5+1,R5),1) -> 1 | S6: =IF(B5=B6,IF(C5<>C6,S5+1,S5),1) -> 1 | T6: =IF(B5<>B6,1,IF(C5=C6,T5+1,1)) -> 4
A7: =IF(B7<>"",表紙!$AB$1&"-"&"結合-"&TEXT($S$1,"00")&"-"&TEXT(R7,"00")&"-"&TEXT(S7,"00")&"-"&TEXT(T7,"０00"),"") -> 最適化-結合-01-01-01-005 | B7: パラメータ入力チェック(拡張空間ID) | C7: 精度閾値を超過した値を入力する | D7: 水平・垂直方向精度：36 | E7: 準正常 | G7: 1. 引数に以下を指定して、integrate.MergeExtendedSpatialIdsを呼び出す。 拡張空間ID配列：正常な任意の値 水平方向精度 ： 36 垂直方向精度 ： 36 | H7: ・以下のspatialIdErrorが返却されること - エラーコード：InputValueError - エラーメッセージ：入力チェックエラー | I7: 44958 | J7: 宮原 | K7: OK | R7: =IF(ROW()<>3,IF(B6<>B7,R6+1,R6),1) -> 1 | S7: =IF(B6=B7,IF(C6<>C7,S6+1,S6),1) -> 1 | T7: =IF(B6<>B7,1,IF(C6=C7,T6+1,1)) -> 5
A8: =IF(B8<>"",表紙!$AB$1&"-"&"結合-"&TEXT($S$1,"00")&"-"&TEXT(R8,"00")&"-"&TEXT(S8,"00")&"-"&TEXT(T8,"０00"),"") -> 最適化-結合-01-01-01-006 | B8: パラメータ入力チェック(拡張空間ID) | C8: 精度閾値を超過した値を入力する | D8: 水平・垂直方向精度：-1 | E8: 準正常 | G8: 1. 引数に以下を指定して、integrate.MergeExtendedSpatialIdsを呼び出す。 拡張空間ID配列：正常な任意の値 水平方向精度 ： -1 垂直方向精度 ： -1 | H8: ・以下のspatialIdErrorが返却されること - エラーコード：InputValueError - エラーメッセージ：入力チェックエラー | I8: 44958 | J8: 宮原 | K8: OK | R8: =IF(ROW()<>3,IF(B7<>B8,R7+1,R7),1) -> 1 | S8: =IF(B7=B8,IF(C7<>C8,S7+1,S7),1) -> 1 | T8: =IF(B7<>B8,1,IF(C7=C8,T7+1,1)) -> 6
A9: =IF(B9<>"",表紙!$AB$1&"-"&"結合-"&TEXT($S$1,"00")&"-"&TEXT(R9,"00")&"-"&TEXT(S9,"00")&"-"&TEXT(T9,"０00"),"") -> 最適化-結合-01-01-02-001 | B9: パラメータ入力チェック(拡張空間ID) | C9: 拡張空間IDフォーマット不正の拡張空間IDが入力される | D9: 区切り文字不足： 3個以下 | E9: 準正常 | G9: 1. 引数に以下を指定して、integrate.MergeExtendedSpatialIdsを呼び出す。 拡張空間ID：10/11/11/10/11, 10/10/10/10 水平方向精度： 正常な任意の値 垂直方向精度： 正常な任意の値 | H9: ・以下のspatialIdErrorが返却されること - エラーコード：InputValueError - エラーメッセージ：入力チェックエラー | I9: 44958 | J9: 宮原 | K9: OK | R9: =IF(ROW()<>3,IF(B8<>B9,R8+1,R8),1) -> 1 | S9: =IF(B8=B9,IF(C8<>C9,S8+1,S8),1) -> 2 | T9: =IF(B8<>B9,1,IF(C8=C9,T8+1,1)) -> 1
A10: =IF(B10<>"",表紙!$AB$1&"-"&"結合-"&TEXT($S$1,"00")&"-"&TEXT(R10,"00")&"-"&TEXT(S10,"00")&"-"&TEXT(T10,"０00"),"") -> 最適化-結合-01-01-02-002 | B10: パラメータ入力チェック(拡張空間ID) | C10: 拡張空間IDフォーマット不正の拡張空間IDが入力される | D10: 区切り文字過多： 5個以上 | E10: 準正常 | G10: 1. 引数に以下を指定して、integrate.MergeExtendedSpatialIdsを呼び出す。 拡張空間ID：10/11/11/10/11, 10/10/10/10/10/10 水平方向精度： 正常な任意の値 垂直方向精度： 正常な任意の値 | H10: ・以下のspatialIdErrorが返却されること - エラーコード：InputValueError - エラーメッセージ：入力チェックエラー | I10: 44958 | J10: 宮原 | K10: OK | R10: =IF(ROW()<>3,IF(B9<>B10,R9+1,R9),1) -> 1 | S10: =IF(B9=B10,IF(C9<>C10,S9+1,S9),1) -> 2 | T10: =IF(B9<>B10,1,IF(C9=C10,T9+1,1)) -> 2
A11: =IF(B11<>"",表紙!$AB$1&"-"&"結合-"&TEXT($S$1,"00")&"-"&TEXT(R11,"00")&"-"&TEXT(S11,"00")&"-"&TEXT(T11,"０00"),"") -> 最適化-結合-01-01-02-003 | B11: パラメータ入力チェック(拡張空間ID) | C11: 拡張空間IDフォーマット不正の拡張空間IDが入力される | D11: 利用不可の文字を含む | E11: 準正常 | G11: 1. 引数に以下を指定して、integrate.MergeExtendedSpatialIdsを呼び出す。 拡張空間ID：10/10/10/10/10/10, 10|11|11|10|11 水平方向精度： 正常な任意の値 垂直方向精度： 正常な任意の値 | H11: ・以下のspatialIdErrorが返却されること - エラーコード：InputValueError - エラーメッセージ：入力チェックエラー | I11: 44958 | J11: 宮原 | K11: OK | R11: =IF(ROW()<>3,IF(B10<>B11,R10+1,R10),1) -> 1 | S11: =IF(B10=B11,IF(C10<>C11,S10+1,S10),1) -> 2 | T11: =IF(B10<>B11,1,IF(C10=C11,T10+1,1)) -> 3
A12: =IF(B12<>"",表紙!$AB$1&"-"&"結合-"&TEXT($S$1,"00")&"-"&TEXT(R12,"00")&"-"&TEXT(S12,"00")&"-"&TEXT(T12,"０00"),"") -> 最適化-結合-01-01-02-004 | B12: パラメータ入力チェック(拡張空間ID) | C12: 拡張空間IDフォーマット不正の拡張空間IDが入力される | D12: 水平精度インデクス値無し | E12: 準正常 | G12: 1. 引数に以下を指定して、integrate.MergeExtendedSpatialIdsを呼び出す。 拡張空間ID：10/10/10/10/10, /11/11/10/11 水平方向精度： 正常な任意の値 垂直方向精度： 正常な任意の値 | H12: ・以下のspatialIdErrorが返却されること - エラーコード：InputValueError - エラーメッセージ：入力チェックエラー | I12: 44958 | J12: 宮原 | K12: OK | R12: =IF(ROW()<>3,IF(B11<>B12,R11+1,R11),1) -> 1 | S12: =IF(B11=B12,IF(C11<>C12,S11+1,S11),1) -> 2 | T12: =IF(B11<>B12,1,IF(C11=C12,T11+1,1)) -> 4
A13: =IF(B13<>"",表紙!$AB$1&"-"&"結合-"&TEXT($S$1,"00")&"-"&TEXT(R13,"00")&"-"&TEXT(S13,"00")&"-"&TEXT(T13,"０00"),"") -> 最適化-結合-01-01-02-005 | B13: パラメータ入力チェック(拡張空間ID) | C13: 拡張空間IDフォーマット不正の拡張空間IDが入力される | D13: 垂直精度インデクス値無し | E13: 準正常 | G13: 1. 引数に以下を指定して、integrate.MergeExtendedSpatialIdsを呼び出す。 拡張空間ID：10/10/10/10/10, 10/11/11//11 水平方向精度： 正常な任意の値 垂直方向精度： 正常な任意の値 | H13: ・以下のspatialIdErrorが返却されること - エラーコード：InputValueError - エラーメッセージ：入力チェックエラー | I13: 44958 | J13: 宮原 | K13: OK | R13: =IF(ROW()<>3,IF(B12<>B13,R12+1,R12),1) -> 1 | S13: =IF(B12=B13,IF(C12<>C13,S12+1,S12),1) -> 2 | T13: =IF(B12<>B13,1,IF(C12=C13,T12+1,1)) -> 5
A14: =IF(B14<>"",表紙!$AB$1&"-"&"結合-"&TEXT($S$1,"00")&"-"&TEXT(R14,"00")&"-"&TEXT(S14,"00")&"-"&TEXT(T14,"０00"),"") -> 最適化-結合-01-01-02-006 | B14: パラメータ入力チェック(拡張空間ID) | C14: 拡張空間IDフォーマット不正の拡張空間IDが入力される | D14: 経度インデクス値無し | E14: 準正常 | G14: 1. 引数に以下を指定して、integrate.MergeExtendedSpatialIdsを呼び出す。 拡張空間ID：10/10/10/10/10, 10//11/10/11 水平方向精度： 正常な任意の値 垂直方向精度： 正常な任意の値 | H14: ・以下のspatialIdErrorが返却されること - エラーコード：InputValueError - エラーメッセージ：入力チェックエラー | I14: 44958 | J14: 宮原 | K14: OK | R14: =IF(ROW()<>3,IF(B13<>B14,R13+1,R13),1) -> 1 | S14: =IF(B13=B14,IF(C13<>C14,S13+1,S13),1) -> 2 | T14: =IF(B13<>B14,1,IF(C13=C14,T13+1,1)) -> 6
A15: =IF(B15<>"",表紙!$AB$1&"-"&"結合-"&TEXT($S$1,"00")&"-"&TEXT(R15,"00")&"-"&TEXT(S15,"00")&"-"&TEXT(T15,"０00"),"") -> 最適化-結合-01-01-02-007 | B15: パラメータ入力チェック(拡張空間ID) | C15: 拡張空間IDフォーマット不正の拡張空間IDが入力される | D15: 緯度インデクス値無し | E15: 準正常 | G15: 1. 引数に以下を指定して、integrate.MergeExtendedSpatialIdsを呼び出す。 拡張空間ID：10/10/10/10/10, 10/11//10/11 水平方向精度： 正常な任意の値 垂直方向精度： 正常な任意の値 | H15: ・以下のspatialIdErrorが返却されること - エラーコード：InputValueError - エラーメッセージ：入力チェックエラー | I15: 44958 | J15: 宮原 | K15: OK | R15: =IF(ROW()<>3,IF(B14<>B15,R14+1,R14),1) -> 1 | S15: =IF(B14=B15,IF(C14<>C15,S14+1,S14),1) -> 2 | T15: =IF(B14<>B15,1,IF(C14=C15,T14+1,1)) -> 7
... A25: =IF(B25<>"",表紙!$AB$1&"-"&"結合-"&TEXT($S$1,"00")&"-"&TEXT(R25,"00")&"-"&TEXT(S25,"00")&"-"&TEXT(T25,"０00"),"") -> 最適化-結合-01-02-02-005 | B25: 最適化の試験パターンの網羅(拡張空間ID) | C25: 最適化後の水平/垂直方向精度が最適化条件を満たさないパターン | D25: 水平方向精度：マージ前と等しい 垂直方向精度：マージ前より大きい | E25: 正常 | G25: 1. 引数に以下を指定して、integrate.MergeExtendedSpatialIdsを呼び出す。 "【別紙1】最適化後の精度パターン"シート"拡張空間ID試験データ"のNo.9の「変換前拡張空間ID」「変換後水平方向精度」「変換後水平方向精度」 | H25: ・入力した座標パターンに対応した期待値が取得できること ・エラーインスタンスが返却されていないこと | I25: 44959 | J25: 宮原 | K25: OK | R25: =IF(ROW()<>3,IF(B24<>B25,R24+1,R24),1) -> 2 | S25: =IF(B24=B25,IF(C24<>C25,S24+1,S24),1) -> 2 | T25: =IF(B24<>B25,1,IF(C24=C25,T24+1,1)) -> 5
A26: =IF(B26<>"",表紙!$AB$1&"-"&"結合-"&TEXT($S$1,"00")&"-"&TEXT(R26,"00")&"-"&TEXT(S26,"00")&"-"&TEXT(T26,"０00"),"") -> 最適化-結合-01-02-03-001 | B26: 最適化の試験パターンの網羅(拡張空間ID) | C26: 最適化後のボクセル内を満たす拡張空間ID群を入力 | D26: 同じ精度の拡張空間IDの組み合わせ | E26: 正常 | M26: =$A$17 -> 最適化-結合-01-02-01-001 | R26: =IF(ROW()<>3,IF(B25<>B26,R25+1,R25),1) -> 2 | S26: =IF(B25=B26,IF(C25<>C26,S25+1,S25),1) -> 3 | T26: =IF(B25<>B26,1,IF(C25=C26,T25+1,1)) -> 1
A27: =IF(B27<>"",表紙!$AB$1&"-"&"結合-"&TEXT($S$1,"00")&"-"&TEXT(R27,"00")&"-"&TEXT(S27,"00")&"-"&TEXT(T27,"０00"),"") -> 最適化-結合-01-02-03-002 | B27: 最適化の試験パターンの網羅(拡張空間ID) | C27: 最適化後のボクセル内を満たす拡張空間ID群を入力 | D27: 異なる精度の拡張空間IDの組み合わせ | E27: 正常 | G27: 1. 引数に以下を指定して、integrate.MergeExtendedSpatialIdsを呼び出す。 "【別紙2】最適化後のボクセル内パターン"シート"拡張空間ID試験データ"のNo.2の「変換前拡張空間ID」「変換後水平方向精度」「変換後水平方向精度」 | H27: ・入力した座標パターンに対応した期待値が取得できること ・エラーインスタンスが返却されていないこと | I27: 44959 | J27: 宮原 | K27: OK | R27: =IF(ROW()<>3,IF(B26<>B27,R26+1,R26),1) -> 2 | S27: =IF(B26=B27,IF(C26<>C27,S26+1,S26),1) -> 3 | T27: =IF(B26<>B27,1,IF(C26=C27,T26+1,1)) -> 2
A28: =IF(B28<>"",表紙!$AB$1&"-"&"結合-"&TEXT($S$1,"00")&"-"&TEXT(R28,"00")&"-"&TEXT(S28,"00")&"-"&TEXT(T28,"０00"),"") -> 最適化-結合-01-02-03-003 | B28: 最適化の試験パターンの網羅(拡張空間ID) | C28: 最適化後のボクセル内を満たす拡張空間ID群を入力 | D28: 同じ範囲に重なっている拡張空間IDが複数ある | E28: 正常 | G28: 1. 引数に以下を指定して、integrate.MergeExtendedSpatialIdsを呼び出す。 "【別紙2】最適化後のボクセル内パターン"シート"拡張空間ID試験データ"のNo.3の「変換前拡張空間ID」「変換後水平方向精度」「変換後水平方向精度」 | H28: ・入力した座標パターンに対応した期待値が取得できること ・エラーインスタンスが返却されていないこと | I28: 44959 | J28: 宮原 | K28: OK | R28: =IF(ROW()<>3,IF(B27<>B28,R27+1,R27),1) -> 2 | S28: =IF(B27=B28,IF(C27<>C28,S27+1,S27),1) -> 3 | T28: =IF(B27<>B28,1,IF(C27=C28,T27+1,1)) -> 3
A29: =IF(B29<>"",表紙!$AB$1&"-"&"結合-"&TEXT($S$1,"00")&"-"&TEXT(R29,"00")&"-"&TEXT(S29,"00")&"-"&TEXT(T29,"０00"),"") -> 最適化-結合-01-02-04-001 | B29: 最適化の試験パターンの網羅(拡張空間ID) | C29: 最適化後のボクセル内を満たさない拡張空間ID群を入力 | D29: 同じ精度の拡張空間IDの組み合わせ | E29: 正常 | G29: 1. 引数に以下を指定して、integrate.MergeExtendedSpatialIdsを呼び出す。 "【別紙2】最適化後のボクセル内パターン"シート"拡張空間ID試験データ"のNo.4の「変換前拡張空間ID」「変換後水平方向精度」「変換後水平方向精度」 | H29: ・入力した座標パターンに対応した期待値が取得できること ・エラーインスタンスが返却されていないこと | I29: 44959 | J29: 宮原 | K29: OK | R29: =IF(ROW()<>3,IF(B28<>B29,R28+1,R28),1) -> 2 | S29: =IF(B28=B29,IF(C28<>C29,S28+1,S28),1) -> 4 | T29: =IF(B28<>B29,1,IF(C28=C29,T28+1,1)) -> 1
A30: =IF(B30<>"",表紙!$AB$1&"-"&"結合-"&TEXT($S$1,"00")&"-"&TEXT(R30,"00")&"-"&TEXT(S30,"00")&"-"&TEXT(T30,"０00"),"") -> 最適化-結合-01-02-04-002 | B30: 最適化の試験パターンの網羅(拡張空間ID) | C30: 最適化後のボクセル内を満たさない拡張空間ID群を入力 | D30: 異なる精度の拡張空間IDの組み合わせ | E30: 正常 | G30: 1. 引数に以下を指定して、integrate.MergeExtendedSpatialIdsを呼び出す。 "【別紙2】最適化後のボクセル内パターン"シート"拡張空間ID試験データ"のNo.5の「変換前拡張空間ID」「変換後水平方向精度」「変換後水平方向精度」 | H30: ・入力した座標パターンに対応した期待値が取得できること ・エラーインスタンスが返却されていないこと | I30: 44959 | J30: 宮原 | K30: OK | R30: =IF(ROW()<>3,IF(B29<>B30,R29+1,R29),1) -> 2 | S30: =IF(B29=B30,IF(C29<>C30,S29+1,S29),1) -> 4 | T30: =IF(B29<>B30,1,IF(C29=C30,T29+1,1)) -> 2
A31: =IF(B31<>"",表紙!$AB$1&"-"&"結合-"&TEXT($S$1,"00")&"-"&TEXT(R31,"00")&"-"&TEXT(S31,"00")&"-"&TEXT(T31,"０00"),"") -> 最適化-結合-01-02-04-003 | B31: 最適化の試験パターンの網羅(拡張空間ID) | C31: 最適化後のボクセル内を満たさない拡張空間ID群を入力 | D31: 同じ範囲に重なっている拡張空間IDが複数ある | E31: 正常 | G31: 1. 引数に以下を指定して、integrate.MergeExtendedSpatialIdsを呼び出す。 "【別紙2】最適化後のボクセル内パターン"シート"拡張空間ID試験データ"のNo.6の「変換前拡張空間ID」「変換後水平方向精度」「変換後水平方向精度」 | H31: ・入力した座標パターンに対応した期待値が取得できること ・エラーインスタンスが返却されていないこと | I31: 44959 | J31: 宮原 | K31: OK | R31: =IF(ROW()<>3,IF(B30<>B31,R30+1,R30),1) -> 2 | S31: =IF(B30=B31,IF(C30<>C31,S30+1,S30),1) -> 4 | T31: =IF(B30<>B31,1,IF(C30=C31,T30+1,1)) -> 3
A32: =IF(B32<>"",表紙!$AB$1&"-"&"結合-"&TEXT($S$1,"00")&"-"&TEXT(R32,"00")&"-"&TEXT(S32,"00")&"-"&TEXT(T32,"０00"),"") -> 最適化-結合-01-02-05-001 | B32: 最適化の試験パターンの網羅(拡張空間ID) | C32: 最適化後のボクセル内を満たす/満たさない拡張空間ID群を同時に入力 | D32: - | E32: 正常 | G32: 1. 引数に以下を指定して、integrate.MergeExtendedSpatialIdsを呼び出す。 拡張空間ID： ["21/20/21/21/20", "21/20/21/21/21", "21/21/21/21/20", "21/21/21/21/21", "21/20/20/21/20", "21/20/20/21/21", "21/21/20/21/20", "21/21/20/21/21", "21/20/21/21/22", "21/20/21/21/23", "21/21/21/21/22", "21/21/21/21/23", "21/20/20/21/22", "21/20/20/21/23", "21/21/20/21/22"] 水平方向精度：20 垂直方向精度：20 | H32: ・以下の拡張空間IDが取得できること [20/10/10/20/10 21/20/21/21/22 21/20/21/21/23 21/21/21/21/22 21/21/21/21/23 21/20/20/21/22 21/20/20/21/23 21/21/20/21/22] ・エラーインスタンスが返却されていないこと | I32: 44959 | J32: 宮原 | K32: OK | R32: =IF(ROW()<>3,IF(B31<>B32,R31+1,R31),1) -> 2 | S32: =IF(B31=B32,IF(C31<>C32,S31+1,S31),1) -> 5 | T32: =IF(B31<>B32,1,IF(C31=C32,T31+1,1)) -> 1
A33: =IF(B33<>"",表紙!$AB$1&"-"&"結合-"&TEXT($S$1,"00")&"-"&TEXT(R33,"00")&"-"&TEXT(S33,"00")&"-"&TEXT(T33,"０00"),"") -> 最適化-結合-01-02-06-001 | B33: 最適化の試験パターンの網羅(拡張空間ID) | C33: 最適化後の精度以上/未満の拡張空間IDを同時に入力 | D33: - | E33: 正常 | G33: 1. 引数に以下を指定して、integrate.MergeExtendedSpatialIdsを呼び出す。 拡張空間ID： ["20/10/10/21/20", "20/10/10/21/21", "19/5/5/19/5"] 水平方向精度：20 垂直方向精度：20 | H33: ・以下の拡張空間IDが取得できること [20/10/10/20/10 19/5/5/19/5] ・エラーインスタンスが返却されていないこと | I33: 44959 | J33: 宮原 | K33: OK | R33: =IF(ROW()<>3,IF(B32<>B33,R32+1,R32),1) -> 2 | S33: =IF(B32=B33,IF(C32<>C33,S32+1,S32),1) -> 6 | T33: =IF(B32<>B33,1,IF(C32=C33,T32+1,1)) -> 1
A34: =IF(B34<>"",表紙!$AB$1&"-"&"結合-"&TEXT($S$1,"00")&"-"&TEXT(R34,"00")&"-"&TEXT(S34,"00")&"-"&TEXT(T34,"０00"),"") -> 最適化-結合-01-02-07-001 | B34: 最適化の試験パターンの網羅(拡張空間ID) | C34: 最適化後のボクセルが重複する拡張空間ID群を入力 | D34: 重複解消後の拡張空間IDが1つ | E34: 正常 | G34: 1. 引数に以下を指定して、integrate.MergeExtendedSpatialIdsを呼び出す。 "【別紙3】最適化後のボクセルが重複パターン"シート"拡張空間ID試験データ"のNo.1の「変換前拡張空間ID」「変換後水平方向精度」「変換後水平方向精度」 | H34: ・入力した座標パターンに対応した期待値が取得できること ・エラーインスタンスが返却されていないこと | I34: 44959 | J34: 宮原 | K34: OK | R34: =IF(ROW()<>3,IF(B33<>B34,R33+1,R33),1) -> 2 | S34: =IF(B33=B34,IF(C33<>C34,S33+1,S33),1) -> 7 | T34: =IF(B33<>B34,1,IF(C33=C34,T33+1,1)) -> 1
A35: =IF(B35<>"",表紙!$AB$1&"-"&"結合-"&TEXT($S$1,"00")&"-"&TEXT(R35,"00")&"-"&TEXT(S35,"00")&"-"&TEXT(T35,"０00"),"") -> 最適化-結合-01-02-07-002 | B35: 最適化の試験パターンの網羅(拡張空間ID) | C35: 最適化後のボクセルが重複する拡張空間ID群を入力 | D35: 重複解消後の拡張空間IDが複数 | E35: 正常 | G35: 1. 引数に以下を指定して、integrate.MergeExtendedSpatialIdsを呼び出す。 "【別紙3】最適化後のボクセルが重複パターン"シート"拡張空間ID試験データ"のNo.2の「変換前拡張空間ID」「変換後水平方向精度」「変換後水平方向精度」 | H35: ・入力した座標パターンに対応した期待値が取得できること ・エラーインスタンスが返却されていないこと | I35: 44959 | J35: 宮原 | K35: OK | R35: =IF(ROW()<>3,IF(B34<>B35,R34+1,R34),1) -> 2 | S35: =IF(B34=B35,IF(C34<>C35,S34+1,S34),1) -> 7 | T35: =IF(B34<>B35,1,IF(C34=C35,T34+1,1)) -> 2
A36: =IF(B36<>"",表紙!$AB$1&"-"&"結合-"&TEXT($S$1,"00")&"-"&TEXT(R36,"00")&"-"&TEXT(S36,"00")&"-"&TEXT(T36,"０00"),"") -> 最適化-結合-01-02-08-001 | B36: 最適化の試験パターンの網羅(拡張空間ID) | C36: 最適化後のボクセルが重複しない拡張空間ID群を入力 | D36: 重複解消後の拡張空間IDが1つ | E36: 正常 | G36: 1. 引数に以下を指定して、integrate.MergeExtendedSpatialIdsを呼び出す。 "【別紙3】最適化後のボクセルが重複パターン"シート"拡張空間ID試験データ"のNo.3の「変換前拡張空間ID」「変換後水平方向精度」「変換後水平方向精度」 | H36: ・入力した座標パターンに対応した期待値が取得できること ・エラーインスタンスが返却されていないこと | I36: 44960 | J36: 宮原 | K36: OK | R36: =IF(ROW()<>3,IF(B35<>B36,R35+1,R35),1) -> 2 | S36: =IF(B35=B36,IF(C35<>C36,S35+1,S35),1) -> 8 | T36: =IF(B35<>B36,1,IF(C35=C36,T35+1,1)) -> 1
A37: =IF(B37<>"",表紙!$AB$1&"-"&"結合-"&TEXT($S$1,"00")&"-"&TEXT(R37,"00")&"-"&TEXT(S37,"00")&"-"&TEXT(T37,"０00"),"") -> 最適化-結合-01-02-08-002 | B37: 最適化の試験パターンの網羅(拡張空間ID) | C37: 最適化後のボクセルが重複しない拡張空間ID群を入力 | D37: 重複解消後の拡張空間IDが複数 | E37: 正常 | G37: 1. 引数に以下を指定して、integrate.MergeExtendedSpatialIdsを呼び出す。 "【別紙3】最適化後のボクセルが重複パターン"シート"拡張空間ID試験データ"のNo.4の「変換前拡張空間ID」「変換後水平方向精度」「変換後水平方向精度」 | H37: ・入力した座標パターンに対応した期待値が取得できること ・エラーインスタンスが返却されていないこと | I37: 44960 | J37: 宮原 | K37: OK | R37: =IF(ROW()<>3,IF(B36<>B37,R36+1,R36),1) -> 2 | S37: =IF(B36=B37,IF(C36<>C37,S36+1,S36),1) -> 8 | T37: =IF(B36<>B37,1,IF(C36=C37,T36+1,1)) -> 2
A38: =IF(B38<>"",表紙!$AB$1&"-"&"結合-"&TEXT($S$1,"00")&"-"&TEXT(R38,"00")&"-"&TEXT(S38,"00")&"-"&TEXT(T38,"０00"),"") -> 最適化-結合-01-02-09-001 | B38: 最適化の試験パターンの網羅(拡張空間ID) | C38: 最適化前拡張空間IDの精度を変えても最適化結果が取得できる | D38: 最適化前水平方向精度：0 最適化後水平方向精度：1 | E38: 正常 | G38: 1. 引数に以下を指定して、integrate.MergeExtendedSpatialIdsを呼び出す。 "【別紙4】最適化前の精度パターン"シート"拡張空間ID試験データ"のNo.1の「変換前拡張空間ID」「変換後水平方向精度」「変換後水平方向精度」 | H38: ・入力した座標パターンに対応した期待値が取得できること ・エラーインスタンスが返却されていないこと | I38: 44960 | J38: 宮原 | K38: OK | R38: =IF(ROW()<>3,IF(B37<>B38,R37+1,R37),1) -> 2 | S38: =IF(B37=B38,IF(C37<>C38,S37+1,S37),1) -> 9 | T38: =IF(B37<>B38,1,IF(C37=C38,T37+1,1)) -> 1
... A58: =IF(B58<>"",表紙!$AB$1&"-"&"結合-"&TEXT($S$1,"00")&"-"&TEXT(R58,"00")&"-"&TEXT(S58,"00")&"-"&TEXT(T58,"０00"),"") -> 最適化-結合-01-04-02-001 | B58: 最適化の試験パターンの網羅(空間ID) | C58: 最適化後の精度が最適化条件を満たさないパターン | D58: 精度：マージ前より大きい | E58: 正常 | G58: 1. 引数に以下を指定して、integrate.MergeSpatialIdsを呼び出す。 "【別紙1】最適化後の精度パターン"シート"空間ID試験データ"のNo.3の「変換前空間ID」「変換後水平方向精度」「変換後水平方向精度」 | H58: ・入力した座標パターンに対応した期待値が取得できること ・エラーインスタンスが返却されていないこと | I58: 44963 | J58: 宮原 | K58: OK | R58: =IF(ROW()<>3,IF(B57<>B58,R57+1,R57),1) -> 4 | S58: =IF(B57=B58,IF(C57<>C58,S57+1,S57),1) -> 2 | T58: =IF(B57<>B58,1,IF(C57=C58,T57+1,1)) -> 1
A59: =IF(B59<>"",表紙!$AB$1&"-"&"結合-"&TEXT($S$1,"00")&"-"&TEXT(R59,"00")&"-"&TEXT(S59,"00")&"-"&TEXT(T59,"０00"),"") -> 最適化-結合-01-04-03-001 | B59: 最適化の試験パターンの網羅(空間ID) | C59: 最適化後のボクセル内を満たす空間ID群を入力 | D59: 同じ精度の拡張空間IDの組み合わせ | E59: 正常 | M59: =$A$56 -> 最適化-結合-01-04-01-001 | R59: =IF(ROW()<>3,IF(B58<>B59,R58+1,R58),1) -> 4 | S59: =IF(B58=B59,IF(C58<>C59,S58+1,S58),1) -> 3 | T59: =IF(B58<>B59,1,IF(C58=C59,T58+1,1)) -> 1
A60: =IF(B60<>"",表紙!$AB$1&"-"&"結合-"&TEXT($S$1,"00")&"-"&TEXT(R60,"00")&"-"&TEXT(S60,"00")&"-"&TEXT(T60,"０00"),"") -> 最適化-結合-01-04-03-002 | B60: 最適化の試験パターンの網羅(空間ID) | C60: 最適化後のボクセル内を満たす空間ID群を入力 | D60: 異なる精度の拡張空間IDの組み合わせ | E60: 正常 | G60: 1. 引数に以下を指定して、integrate.MergeSpatialIdsを呼び出す。 "【別紙2】最適化後のボクセル内パターン"シート"空間ID試験データ"のNo.2の「変換前空間ID」「変換後水平方向精度」「変換後水平方向精度」 | H60: ・入力した座標パターンに対応した期待値が取得できること ・エラーインスタンスが返却されていないこと | I60: 44963 | J60: 宮原 | K60: OK | R60: =IF(ROW()<>3,IF(B59<>B60,R59+1,R59),1) -> 4 | S60: =IF(B59=B60,IF(C59<>C60,S59+1,S59),1) -> 3 | T60: =IF(B59<>B60,1,IF(C59=C60,T59+1,1)) -> 2
A61: =IF(B61<>"",表紙!$AB$1&"-"&"結合-"&TEXT($S$1,"00")&"-"&TEXT(R61,"00")&"-"&TEXT(S61,"00")&"-"&TEXT(T61,"０00"),"") -> 最適化-結合-01-04-03-003 | B61: 最適化の試験パターンの網羅(空間ID) | C61: 最適化後のボクセル内を満たす空間ID群を入力 | D61: 同じ範囲に重なっている拡張空間IDが複数ある | E61: 正常 | G61: 1. 引数に以下を指定して、integrate.MergeSpatialIdsを呼び出す。 "【別紙2】最適化後のボクセル内パターン"シート"空間ID試験データ"のNo.3の「変換前空間ID」「変換後水平方向精度」「変換後水平方向精度」 | H61: ・入力した座標パターンに対応した期待値が取得できること ・エラーインスタンスが返却されていないこと | I61: 44963 | J61: 宮原 | K61: OK | R61: =IF(ROW()<>3,IF(B60<>B61,R60+1,R60),1) -> 4 | S61: =IF(B60=B61,IF(C60<>C61,S60+1,S60),1) -> 3 | T61: =IF(B60<>B61,1,IF(C60=C61,T60+1,1)) -> 3
A62: =IF(B62<>"",表紙!$AB$1&"-"&"結合-"&TEXT($S$1,"00")&"-"&TEXT(R62,"00")&"-"&TEXT(S62,"00")&"-"&TEXT(T62,"０00"),"") -> 最適化-結合-01-04-04-001 | B62: 最適化の試験パターンの網羅(空間ID) | C62: 最適化後のボクセル内を満たさない空間ID群を入力 | D62: 同じ精度の拡張空間IDの組み合わせ | E62: 正常 | G62: 1. 引数に以下を指定して、integrate.MergeSpatialIdsを呼び出す。 "【別紙2】最適化後のボクセル内パターン"シート"空間ID試験データ"のNo.4の「変換前空間ID」「変換後水平方向精度」「変換後水平方向精度」 | H62: ・入力した座標パターンに対応した期待値が取得できること ・エラーインスタンスが返却されていないこと | I62: 44964 | J62: 宮原 | K62: OK | R62: =IF(ROW()<>3,IF(B61<>B62,R61+1,R61),1) -> 4 | S62: =IF(B61=B62,IF(C61<>C62,S61+1,S61),1) -> 4 | T62: =IF(B61<>B62,1,IF(C61=C62,T61+1,1)) -> 1
A63: =IF(B63<>"",表紙!$AB$1&"-"&"結合-"&TEXT($S$1,"00")&"-"&TEXT(R63,"00")&"-"&TEXT(S63,"00")&"-"&TEXT(T63,"０00"),"") -> 最適化-結合-01-04-04-002 | B63: 最適化の試験パターンの網羅(空間ID) | C63: 最適化後のボクセル内を満たさない空間ID群を入力 | D63: 異なる精度の拡張空間IDの組み合わせ | E63: 正常 | G63: 1. 引数に以下を指定して、integrate.MergeSpatialIdsを呼び出す。 "【別紙2】最適化後のボクセル内パターン"シート"空間ID試験データ"のNo.5の「変換前空間ID」「変換後水平方向精度」「変換後水平方向精度」 | H63: ・入力した座標パターンに対応した期待値が取得できること ・エラーインスタンスが返却されていないこと | I63: 44964 | J63: 宮原 | K63: OK | R63: =IF(ROW()<>3,IF(B62<>B63,R62+1,R62),1) -> 4 | S63: =IF(B62=B63,IF(C62<>C63,S62+1,S62),1) -> 4 | T63: =IF(B62<>B63,1,IF(C62=C63,T62+1,1)) -> 2
A64: =IF(B64<>"",表紙!$AB$1&"-"&"結合-"&TEXT($S$1,"00")&"-"&TEXT(R64,"00")&"-"&TEXT(S64,"00")&"-"&TEXT(T64,"０00"),"") -> 最適化-結合-01-04-04-003 | B64: 最適化の試験パターンの網羅(空間ID) | C64: 最適化後のボクセル内を満たさない空間ID群を入力 | D64: 同じ範囲に重なっている拡張空間IDが複数ある | E64: 正常 | G64: 1. 引数に以下を指定して、integrate.MergeSpatialIdsを呼び出す。 "【別紙2】最適化後のボクセル内パターン"シート"空間ID試験データ"のNo.6の「変換前空間ID」「変換後水平方向精度」「変換後水平方向精度」 | H64: ・入力した座標パターンに対応した期待値が取得できること ・エラーインスタンスが返却されていないこと | I64: 44964 | J64: 宮原 | K64: OK | R64: =IF(ROW()<>3,IF(B63<>B64,R63+1,R63),1) -> 4 | S64: =IF(B63=B64,IF(C63<>C64,S63+1,S63),1) -> 4 | T64: =IF(B63<>B64,1,IF(C63=C64,T63+1,1)) -> 3
A65: =IF(B65<>"",表紙!$AB$1&"-"&"結合-"&TEXT($S$1,"00")&"-"&TEXT(R65,"00")&"-"&TEXT(S65,"00")&"-"&TEXT(T65,"０00"),"") -> 最適化-結合-01-04-05-001 | B65: 最適化の試験パターンの網羅(空間ID) | C65: 最適化後のボクセル内を満たす/満たさない空間ID群を同時に入力 | D65: - | E65: 正常 | G65: 1. 引数に以下を指定して、integrate.MergeSpatialIdsを呼び出す。 空間ID： ["21/20/20/21", "21/21/20/21", "21/20/21/21", "21/21/21/21", "21/20/20/20", "21/21/20/20", "21/20/21/20", "21/21/21/20", "21/22/20/21", "21/23/20/21", "21/22/21/21", "21/23/21/21", "21/22/20/20", "21/23/20/20", "21/22/21/20"] 水平方向精度：20 垂直方向精度：20 | H65: ・以下の空間IDが取得できること [20/10/10/10 21/22/20/21 21/23/20/21 21/22/21/21 21/23/21/21 21/22/20/20 21/23/20/20 21/22/21/20] ・エラーインスタンスが返却されていないこと | I65: 44964 | J65: 宮原 | K65: OK | R65: =IF(ROW()<>3,IF(B64<>B65,R64+1,R64),1) -> 4 | S65: =IF(B64=B65,IF(C64<>C65,S64+1,S64),1) -> 5 | T65: =IF(B64<>B65,1,IF(C64=C65,T64+1,1)) -> 1
A66: =IF(B66<>"",表紙!$AB$1&"-"&"結合-"&TEXT($S$1,"00")&"-"&TEXT(R66,"00")&"-"&TEXT(S66,"00")&"-"&TEXT(T66,"０00"),"") -> 最適化-結合-01-04-06-001 | B66: 最適化の試験パターンの網羅(空間ID) | C66: 最適化後の精度以上/未満の空間IDを同時に入力 | D66: - | E66: 正常 | G66: 1. 引数に以下を指定して、integrate.MergeSpatialIdsを呼び出す。 空間ID： ["21/20/20/21", "21/21/20/21", "21/20/21/21", "21/21/21/21", "21/20/20/20", "21/21/20/20", "21/20/21/20", "21/21/21/20", "19/5/5/5"] 水平方向精度：20 垂直方向精度：20 | H66: ・以下の空間IDが取得できること [20/10/10/10 19/5/5/5] ・エラーインスタンスが返却されていないこと | I66: 44964 | J66: 宮原 | K66: OK | R66: =IF(ROW()<>3,IF(B65<>B66,R65+1,R65),1) -> 4 | S66: =IF(B65=B66,IF(C65<>C66,S65+1,S65),1) -> 6 | T66: =IF(B65<>B66,1,IF(C65=C66,T65+1,1)) -> 1
A67: =IF(B67<>"",表紙!$AB$1&"-"&"結合-"&TEXT($S$1,"00")&"-"&TEXT(R67,"00")&"-"&TEXT(S67,"00")&"-"&TEXT(T67,"０00"),"") -> 最適化-結合-01-04-07-001 | B67: 最適化の試験パターンの網羅(空間ID) | C67: 最適化後のボクセルが重複する空間ID群を入力 | D67: 重複解消後の拡張空間IDが1つ | E67: 正常 | G67: 1. 引数に以下を指定して、integrate.MergeSpatialIdsを呼び出す。 "【別紙3】最適化後のボクセルが重複パターン"シート"空間ID試験データ"のNo.1の「変換前空間ID」「変換後水平方向精度」「変換後水平方向精度」 | H67: ・入力した座標パターンに対応した期待値が取得できること ・エラーインスタンスが返却されていないこと | I67: 44964 | J67: 宮原 | K67: OK | R67: =IF(ROW()<>3,IF(B66<>B67,R66+1,R66),1) -> 4 | S67: =IF(B66=B67,IF(C66<>C67,S66+1,S66),1) -> 7 | T67: =IF(B66<>B67,1,IF(C66=C67,T66+1,1)) -> 1
A68: =IF(B68<>"",表紙!$AB$1&"-"&"結合-"&TEXT($S$1,"00")&"-"&TEXT(R68,"00")&"-"&TEXT(S68,"00")&"-"&TEXT(T68,"０00"),"") -> 最適化-結合-01-04-07-002 | B68: 最適化の試験パターンの網羅(空間ID) | C68: 最適化後のボクセルが重複する空間ID群を入力 | D68: 重複解消後の拡張空間IDが複数 | E68: 正常 | G68: 1. 引数に以下を指定して、integrate.MergeSpatialIdsを呼び出す。 "【別紙3】最適化後のボクセルが重複パターン"シート"空間ID試験データ"のNo.2の「変換前空間ID」「変換後水平方向精度」「変換後水平方向精度」 | H68: ・入力した座標パターンに対応した期待値が取得できること ・エラーインスタンスが返却されていないこと | I68: 44964 | J68: 宮原 | K68: OK | R68: =IF(ROW()<>3,IF(B67<>B68,R67+1,R67),1) -> 4 | S68: =IF(B67=B68,IF(C67<>C68,S67+1,S67),1) -> 7 | T68: =IF(B67<>B68,1,IF(C67=C68,T67+1,1)) -> 2
...

Sheet 【別紙1】最適化条件の精度パターン
A1: ■ 最適化条件の精度 試験データパターン
B2: 最適化前後の精度差に関する試験用データ
B4: 〇拡張空間ID試験データ
C5: 変換元として入力する"拡張空間ID"、"変換後の水平/垂直方向精度"及び、精度変換時に取得される期待値を以下に記載する。
C6: 試験実施時は以下に記載する入力値をAPIの引数に入力し、取得された値が期待値と同じであることを確認する。
C8: No | D8: 最適化条件 | E8: 精度パターン | F8: 変換前拡張空間ID | I8: 変換後水平方向精度 | L8: 変換後垂直方向精度 | O8: 期待値※1
C9: 1 | D9: 最適化条件を満たすパターン | E9: 水平方向精度：マージ前より小さい 垂直方向精度：マージ前より小さい | F9: 22/42/42/22/40, 22/43/42/22/41, 22/40/43/22/41, 22/40/40/22/42, 22/41/42/22/40, 22/42/42/22/42, 22/40/42/22/43, 22/40/40/22/40, 22/40/40/22/43, 22/41/40/22/43, 22/40/42/22/40, 22/43/42/22/43, 22/41/43/22/41, 22/42/40/22/41, 22/41/41/22/41, 22/42/42/22/43, 22/41/43/22/40, 22/41/40/22/42, 22/43/42/22/42, 22/40/43/22/40, 22/41/43/22/43, 22/43/43/22/41, 22/41/40/22/40, 22/40/41/22/40, 22/41/41/22/40, 22/40/43/22/42, 22/41/43/22/42, 22/43/43/22/43, 22/42/40/22/42, 22/40/41/22/42, 22/43/40/22/40, 22/42/41/22/40, 22/43/41/22/40, 22/40/42/22/42, 22/40/43/22/43, 22/42/43/22/43, 22/43/43/22/40, 22/43/40/22/43, 22/42/43/22/40, 22/40/41/22/41, 22/41/41/22/43, 22/43/40/22/41, 22/41/41/22/42, 22/41/42/22/43, 22/42/43/22/42, 22/43/43/22/42, 22/40/40/22/41, 22/41/40/22/41, 22/40/41/22/43, 22/42/41/22/41, 22/42/41/22/42, 22/43/40/22/42, 22/43/41/22/42, 22/43/41/22/43, 22/40/42/22/41, 22/42/42/22/41, 22/42/43/22/41, 22/42/40/22/40, 22/42/41/22/43, 22/41/42/22/42, 22/43/42/22/40, 22/42/40/22/43, 22/43/41/22/41, 22/41/42/22/41 | I9: 20 | L9: 20 | O9: [20/10/10/20/10]
C10: 2 | E10: 水平方向精度：マージ前より小さい 垂直方向精度：マージ前と等しい | F10: 22/40/40/22/10, 22/41/40/22/10, 22/42/42/22/10, 22/40/43/22/10, 22/41/43/22/10, 22/42/40/22/10, 22/43/40/22/10, 22/42/41/22/10, 22/43/41/22/10, 22/40/42/22/10, 22/41/42/22/10, 22/43/42/22/10, 22/42/43/22/10, 22/43/43/22/10, 22/40/41/22/10, 22/41/41/22/10 | I10: 20 | L10: 22 | O10: [20/10/10/22/10]
C11: 3 | E11: 水平方向精度：マージ前と等しい 垂直方向精度：マージ前より小さい | F11: 22/10/10/22/40, 22/10/10/22/41, 22/10/10/22/42, 22/10/10/22/43 | I11: 22 | L11: 20 | O11: [22/10/10/20/10]
C12: 4 | E12: 水平方向精度：マージ前と等しい 垂直方向精度：マージ前と等しい | F12: 22/10/10/22/10 | I12: 22 | L12: 22 | O12: [22/10/10/22/10]
C13: 5 | D13: 最適化条件を満たさないパターン | E13: 水平方向精度：マージ前より大きい 垂直方向精度：マージ前より小さい | F13: 21/20/20/22/40, 21/20/20/22/41, 21/20/20/22/42, 21/20/20/22/43, 21/20/21/22/40, 21/20/21/22/41, 21/20/21/22/42, 21/20/21/22/43, 21/21/20/22/40, 21/21/20/22/41, 21/21/20/22/42, 21/21/20/22/43, 21/21/21/22/40, 21/21/21/22/41, 21/21/21/22/42, 21/21/21/22/43 | I13: 22 | L13: 20 | O13: [21/20/20/22/40 21/20/20/22/41 21/20/20/22/42 21/20/20/22/43 21/20/21/22/40 21/20/21/22/41 21/20/21/22/42 21/20/21/22/43 21/21/20/22/40 21/21/20/22/41 21/21/20/22/42 21/21/20/22/43 21/21/21/22/40 21/21/21/22/41 21/21/21/22/42 21/21/21/22/43]
C14: 6 | E14: 水平方向精度：マージ前より大きい 垂直方向精度：マージ前と等しい | F14: 21/20/20/22/40, 21/20/20/22/41, 21/20/20/22/42, 21/20/20/22/43, 21/20/21/22/40, 21/20/21/22/41, 21/20/21/22/42, 21/20/21/22/43, 21/21/20/22/40, 21/21/20/22/41, 21/21/20/22/42, 21/21/20/22/43, 21/21/21/22/40, 21/21/21/22/41, 21/21/21/22/42, 21/21/21/22/43 | I14: 22 | L14: 22 | O14: [21/20/20/22/40 21/20/20/22/41 21/20/20/22/42 21/20/20/22/43 21/20/21/22/40 21/20/21/22/41 21/20/21/22/42 21/20/21/22/43 21/21/20/22/40 21/21/20/22/41 21/21/20/22/42 21/21/20/22/43 21/21/21/22/40 21/21/21/22/41 21/21/21/22/42 21/21/21/22/43]
C15: 7 | E15: 水平方向精度：マージ前より大きい 垂直方向精度：マージ前より大きい | F15: 21/20/20/22/40, 21/20/20/22/41, 21/20/20/22/42, 21/20/20/22/43, 21/20/21/22/40, 21/20/21/22/41, 21/20/21/22/42, 21/20/21/22/43, 21/21/20/22/40, 21/21/20/22/41, 21/21/20/22/42, 21/21/20/22/43, 21/21/21/22/40, 21/21/21/22/41, 21/21/21/22/42, 21/21/21/22/43 | I15: 22 | L15: 23 | O15: [21/20/20/22/40 21/20/20/22/41 21/20/20/22/42 21/20/20/22/43 21/20/21/22/40 21/20/21/22/41 21/20/21/22/42 21/20/21/22/43 21/21/20/22/40 21/21/20/22/41 21/21/20/22/42 21/21/20/22/43 21/21/21/22/40 21/21/21/22/41 21/21/21/22/42 21/21/21/22/43]
C16: 8 | E16: 水平方向精度：マージ前より小さい 垂直方向精度：マージ前より大きい | F16: 21/20/20/22/40, 21/20/20/22/41, 21/20/20/22/42, 21/20/20/22/43, 21/20/21/22/40, 21/20/21/22/41, 21/20/21/22/42, 21/20/21/22/43, 21/21/20/22/40, 21/21/20/22/41, 21/21/20/22/42, 21/21/20/22/43, 21/21/21/22/40, 21/21/21/22/41, 21/21/21/22/42, 21/21/21/22/43 | I16: 20 | L16: 23 | O16: [21/20/20/22/40 21/20/20/22/41 21/20/20/22/42 21/20/20/22/43 21/20/21/22/40 21/20/21/22/41 21/20/21/22/42 21/20/21/22/43 21/21/20/22/40 21/21/20/22/41 21/21/20/22/42 21/21/20/22/43 21/21/21/22/40 21/21/21/22/41 21/21/21/22/42 21/21/21/22/43]
C17: 9 | E17: 水平方向精度：マージ前と等しい 垂直方向精度：マージ前より大きい | F17: 21/20/20/22/40, 21/20/20/22/41, 21/20/20/22/42, 21/20/20/22/43, 21/20/21/22/40, 21/20/21/22/41, 21/20/21/22/42, 21/20/21/22/43, 21/21/20/22/40, 21/21/20/22/41, 21/21/20/22/42, 21/21/20/22/43, 21/21/21/22/40, 21/21/21/22/41, 21/21/21/22/42, 21/21/21/22/43 | I17: 21 | L17: 23 | O17: [21/20/20/22/40 21/20/20/22/41 21/20/20/22/42 21/20/20/22/43 21/20/21/22/40 21/20/21/22/41 21/20/21/22/42 21/20/21/22/43 21/21/20/22/40 21/21/20/22/41 21/21/20/22/42 21/21/20/22/43 21/21/21/22/40 21/21/21/22/41 21/21/21/22/42 21/21/21/22/43]
B21: 〇空間ID試験データ
C22: 変換元として入力する"空間ID"、"変換後の水平/垂直方向精度"及び、精度変換時に取得される期待値を以下に記載する。
C23: 試験実施時は以下に記載する入力値をAPIの引数に入力し、取得された値が期待値と同じであることを確認する。
C25: No | E25: 変換前後の精度差パターン | F25: 変換前空間ID | I25: 変換後精度 | L25: 期待値※1
C26: 1 | D26: 最適化条件を満たすパターン | E26: 精度：マージ前より小さい | F26: 22/40/40/40, 22/41/40/40, 22/42/40/40, 22/43/40/40, 22/40/40/41, 22/41/40/41, 22/42/40/41, 22/43/40/41, 22/40/40/42, 22/41/40/42, 22/42/40/42, 22/43/40/42, 22/40/40/43, 22/41/40/43, 22/42/40/43, 22/43/40/43, 22/40/41/40, 22/41/41/40, 22/42/41/40, 22/43/41/40, 22/40/41/41, 22/41/41/41, 22/42/41/41, 22/43/41/41, 22/40/41/42, 22/41/41/42, 22/42/41/42, 22/43/41/42, 22/40/41/43, 22/41/41/43, 22/42/41/43, 22/43/41/43, 22/40/42/40, 22/41/42/40, 22/42/42/40, 22/43/42/40, 22/40/42/41, 22/41/42/41, 22/42/42/41, 22/43/42/41, 22/40/42/42, 22/41/42/42, 22/42/42/42, 22/43/42/42, 22/40/42/43, 22/41/42/43, 22/42/42/43, 22/43/42/43, 22/40/43/40, 22/41/43/40, 22/42/43/40, 22/43/43/40, 22/40/43/41, 22/41/43/41, 22/42/43/41, 22/43/43/41, 22/40/43/42, 22/41/43/42, 22/42/43/42, 22/43/43/42, 22/40/43/43, 22/41/43/43, 22/42/43/43, 22/43/43/43 | I26: 20 | L26: [20/10/10/10]
C27: 2 | E27: 精度：マージ前と等しい | F27: 20/10/10/10 | I27: 20 | L27: [20/10/10/10]
C28: 3 | D28: 最適化条件を満たさないパターン | E28: 精度：マージ前より大きい | F28: 21/20/20/20, 21/21/20/20, 21/20/20/21, 21/21/20/21, 21/20/21/20, 21/21/21/20, 21/20/21/21, 21/21/21/21 | I28: 22 | L28: [21/20/20/20 21/21/20/20 21/20/20/21 21/21/20/21 21/20/21/20 21/21/21/20 21/20/21/21 21/21/21/21]
C31: ※1 配列に格納された空間IDの順番は不定

Sheet 【別紙2】最適化後のボクセル内パターン
A1: ■ 最適化後のボクセル内データ 試験データパターン
B2: 最適化後の拡張空間ID内における、最適化前の拡張空間IDの組み合わせ関する試験用データ
B4: 〇拡張空間ID試験データ
C5: 変換元として入力する"拡張空間ID"、"変換後の水平/垂直方向精度"及び、精度変換時に取得される期待値を以下に記載する。
C6: 試験実施時は以下に記載する入力値をAPIの引数に入力し、取得された値が期待値と同じであることを確認する。
C8: No | D8: ボクセル内パターン | E8: 空間ID組み合わせ | F8: 変換前拡張空間ID | I8: 変換後水平方向精度 | L8: 変換後垂直方向精度 | O8: 期待値※1
C9: 1 | D9: ボクセル内を満たす | E9: 同じ精度の拡張空間IDの組み合わせ | F9: 21/20/21/21/20, 21/20/21/21/21, 21/21/21/21/20, 21/21/21/21/21, 21/20/20/21/20, 21/20/20/21/21, 21/21/20/21/20, 21/21/20/21/21 | I9: 20 | L9: 20 | O9: [20/10/10/20/10]
C10: 2 | E10: 異なる精度の拡張空間IDの組み合わせ | F10: 21/20/21/21/20, 21/20/21/21/21, 21/21/21/21/20, 21/21/21/21/21, 21/20/20/21/20, 22/40/41/22/42, 22/40/41/22/43, 22/41/41/22/42, 22/41/41/22/43, 22/40/40/22/42, 22/40/40/22/43, 22/41/40/22/42, 22/41/40/22/43, 21/21/20/22/40, 21/21/20/22/41, 22/43/41/21/21, 22/42/40/21/21, 22/43/40/21/21, 22/42/41/21/21 | I10: 20 | L10: 20 | O10: [20/10/10/20/10]
C11: 3 | E11: 同じ範囲に重なっている拡張空間IDが複数ある | F11: 21/20/21/21/20, 21/20/21/21/21, 21/21/21/21/20, 21/21/21/21/21, 21/20/20/21/20, 22/40/41/22/42, 22/40/41/22/43, 22/41/41/22/42, 22/41/41/22/43, 22/40/40/22/42, 22/40/40/22/43, 22/41/40/22/42, 22/41/40/22/43, 21/21/20/22/40, 21/21/20/22/41, 22/43/41/21/21, 22/42/40/21/21, 22/43/40/21/21, 22/42/41/21/21, 21/21/20/21/20 | I11: 20 | L11: 20 | O11: [20/10/10/20/10]
C12: 4 | D12: ボクセル内を満たさない | E12: 同じ精度の拡張空間IDの組み合わせ | F12: 21/20/21/21/20, 21/20/21/21/21, 21/21/21/21/20, 21/21/21/21/21, 21/20/20/21/20, 21/21/20/21/20, 21/21/20/21/21 | I12: 20 | L12: 20 | O12: [21/20/21/21/20 21/20/21/21/21 21/21/21/21/20 21/21/21/21/21 21/20/20/21/20 21/21/20/21/20 21/21/20/21/21]
C13: 5 | E13: 異なる精度の拡張空間IDの組み合わせ | F13: 21/20/21/21/20, 21/20/21/21/21, 21/21/21/21/20, 21/21/21/21/21, 21/20/20/21/20, 22/40/41/22/42, 22/40/41/22/43, 22/41/41/22/42, 22/41/41/22/43, 22/40/40/22/42, 22/40/40/22/43, 22/41/40/22/42, 22/41/40/22/43, 21/21/20/22/40, 21/21/20/22/41, 22/43/41/21/21, 22/42/40/21/21, 22/43/40/21/21 | I13: 20 | L13: 20 | O13: [21/20/21/21/20 21/20/21/21/21 21/21/21/21/20 21/21/21/21/21 21/20/20/21/20 22/40/41/22/42 22/40/41/22/43 22/41/41/22/42 22/41/41/22/43 22/40/40/22/42 22/40/40/22/43 22/41/40/22/42 22/41/40/22/43 21/21/20/22/40 21/21/20/22/41 22/43/41/21/21 22/42/40/21/21 22/43/40/21/21]
C14: 6 | E14: 同じ範囲に重なっている拡張空間IDが複数ある | F14: 21/20/21/21/21, 21/21/21/21/20, 21/21/21/21/21, 21/20/20/21/20, 22/40/41/22/42, 22/40/41/22/43, 22/41/41/22/42, 22/41/41/22/43, 22/40/40/22/42, 22/40/40/22/43, 22/41/40/22/42, 22/41/40/22/43, 21/21/20/22/40, 21/21/20/22/41, 22/43/41/21/21, 22/42/40/21/21, 22/43/40/21/21, 22/42/41/21/21, 21/21/20/21/20 | I14: 20 | L14: 20 | O14: [21/20/21/21/21 21/21/21/21/20 21/21/21/21/21 21/20/20/21/20 22/40/41/22/42 22/40/41/22/43 22/41/41/22/42 22/41/41/22/43 22/40/40/22/42 22/40/40/22/43 22/41/40/22/42 22/41/40/22/43 21/21/20/22/40 21/21/20/22/41 22/43/41/21/21 22/42/40/21/21 22/43/40/21/21 22/42/41/21/21 21/21/20/21/20]
B18: 〇空間ID試験データ
C19: 変換元として入力する"空間ID"、"変換後の水平/垂直方向精度"及び、精度変換時に取得される期待値を以下に記載する。
C20: 試験実施時は以下に記載する入力値をAPIの引数に入力し、取得された値が期待値と同じであることを確認する。
C22: No | D22: ボクセル内パターン | E22: 空間ID組み合わせ | F22: 変換前空間ID | I22: 変換後精度 | L22: 期待値※1
C23: 1 | D23: ボクセル内を満たす | E23: 同じ精度の拡張空間IDの組み合わせ | F23: 21/20/20/21, 21/21/20/21, 21/20/21/21, 21/21/21/21, 21/20/20/20, 21/21/20/20, 21/20/21/20, 21/21/21/20 | I23: 20 | L23: [20/10/10/10]
C24: 2 | E24: 異なる精度の拡張空間IDの組み合わせ | F24: 21/20/20/21, 21/21/20/21, 21/20/21/21, 21/21/21/21, 21/20/20/20, 21/21/20/20, 21/20/21/20, 22/42/43/41, 22/43/43/41, 22/42/42/40, 22/43/42/40, 22/42/43/40, 22/43/43/40, 22/42/42/41, 22/43/42/41 | I24: 20 | L24: [20/10/10/10]
C25: 3 | E25: 同じ範囲に重なっている拡張空間IDが複数ある | F25: 21/20/20/21, 21/21/20/21, 21/20/21/21, 21/21/21/21, 21/20/20/20, 21/21/20/20, 21/20/21/20, 21/21/21/20, 22/42/43/41, 22/43/43/41, 22/42/42/40, 22/43/42/40, 22/42/43/40, 22/43/43/40, 22/42/42/41, 22/43/42/41 | I25: 20 | L25: [20/10/10/10]
C26: 4 | D26: ボクセル内を満たさない | E26: 同じ精度の拡張空間IDの組み合わせ | F26: 21/20/20/21, 21/21/20/21, 21/20/21/21, 21/21/21/21, 21/20/20/20, 21/21/20/20, 21/20/21/20 | I26: 20 | L26: [21/20/20/21 21/21/20/21 21/20/21/21 21/21/21/21 21/20/20/20 21/21/20/20 21/20/21/20]
C27: 5 | E27: 異なる精度の拡張空間IDの組み合わせ | F27: 21/20/20/21, 21/21/20/21, 21/20/21/21, 21/21/21/21, 21/20/20/20, 21/21/20/20, 21/20/21/20, 22/42/43/41, 22/43/43/41, 22/42/42/40, 22/43/42/40, 22/42/43/40, 22/43/43/40, 22/42/42/41 | I27: 20 | L27: [21/20/20/21 21/21/20/21 21/20/21/21 21/21/21/21 21/20/20/20 21/21/20/20 21/20/21/20 22/42/43/41 22/43/43/41 22/42/42/40 22/43/42/40 22/42/43/40 22/43/43/40 22/42/42/41]
C28: 6 | E28: 同じ範囲に重なっている拡張空間IDが複数ある | F28: 21/21/20/21, 21/20/21/21, 21/21/21/21, 21/20/20/20, 21/21/20/20, 21/20/21/20, 21/21/21/20, 22/42/43/41, 22/43/43/41, 22/42/42/40, 22/43/42/40, 22/42/43/40, 22/43/43/40, 22/42/42/41, 22/43/42/41 | I28: 20 | L28: [21/21/20/21 21/20/21/21 21/21/21/21 21/20/20/20 21/21/20/20 21/20/21/20 21/21/21/20 22/42/43/41 22/43/43/41 22/42/42/40 22/43/42/40 22/42/43/40 22/43/43/40 22/42/42/41 22/43/42/41]
C31: ※1 配列に格納された空間IDの順番は不定

Sheet 【別紙3】最適化後のボクセルが重複パターン
A1: ■ 最適化後のボクセルが重複 試験データパターン
B2: 最適化後の拡張空間ID内における、最適化後の拡張空間IDの重複有無に関する試験用データ
B4: 〇拡張空間ID試験データ
C5: 変換元として入力する"拡張空間ID"、"変換後の水平/垂直方向精度"及び、精度変換時に取得される期待値を以下に記載する。
C6: 試験実施時は以下に記載する入力値をAPIの引数に入力し、取得された値が期待値と同じであることを確認する。
C8: No | D8: 最適化後の重複有無 | E8: 空間ID組み合わせ | F8: 変換前拡張空間ID | I8: 変換後水平方向精度 | L8: 変換後垂直方向精度 | O8: 期待値※1
C9: 1 | D9: 重複あり | E9: 重複解消後の拡張空間IDが1つ | F9: 21/20/20/21/20, 21/20/20/21/21, 21/21/20/21/20, 21/21/20/21/21, 21/20/21/21/20, 21/20/21/21/21, 21/21/21/21/20, 21/21/21/21/21, 20/10/10/21/20, 20/10/10/21/21 | I9: 20 | L9: 20 | O9: [20/10/10/20/10]
C10: 2 | E10: 重複解消後の拡張空間IDが複数 | F10: 21/20/20/21/20, 21/20/20/21/21, 21/21/20/21/20, 21/21/20/21/21, 21/20/21/21/20, 21/20/21/21/21, 21/21/21/21/20, 21/21/21/21/21, 20/10/10/21/20, 20/10/10/21/21, 21/23/23/21/20, 21/23/23/21/21, 21/22/22/21/20, 21/22/22/21/21, 21/23/22/21/20, 21/23/22/21/21, 21/22/23/21/20, 21/22/23/21/21 | I10: 20 | L10: 20 | O10: [20/10/10/20/10 20/11/11/20/10]
C11: 3 | D11: 重複なし | E11: 重複解消後の拡張空間IDが1つ | F11: 21/20/20/21/20, 21/20/20/21/21, 21/21/20/21/20, 21/21/20/21/21, 21/20/21/21/20, 21/20/21/21/21, 21/21/21/21/20, 21/21/21/21/21 | I11: 20 | L11: 20 | O11: [20/10/10/20/10]
C12: 4 | E12: 重複解消後の拡張空間IDが複数 | F12: 21/20/20/21/20, 21/20/20/21/21, 21/21/20/21/20, 21/21/20/21/21, 21/20/21/21/20, 21/20/21/21/21, 21/21/21/21/20, 21/21/21/21/21, 21/23/23/21/20, 21/23/23/21/21, 21/22/22/21/20, 21/22/22/21/21, 21/23/22/21/20, 21/23/22/21/21, 21/22/23/21/20, 21/22/23/21/21 | I12: 20 | L12: 20 | O12: [20/10/10/20/10 20/11/11/20/10]
B16: 〇空間ID試験データ
C17: 変換元として入力する"空間ID"、"変換後の水平/垂直方向精度"及び、精度変換時に取得される期待値を以下に記載する。
C18: 試験実施時は以下に記載する入力値をAPIの引数に入力し、取得された値が期待値と同じであることを確認する。
C20: No | D20: 最適化後の重複有無 | E20: 空間ID組み合わせ | F20: 変換前空間ID | I20: 変換後精度 | L20: 期待値※1
C21: 1 | D21: 重複あり | E21: 重複解消後の拡張空間IDが1つ | F21: 21/20/20/20, 21/21/20/20, 21/20/21/20, 21/21/21/20, 21/20/20/21, 21/21/20/21, 21/20/21/21, 21/21/21/21, 22/42/40/41, 22/40/42/41, 22/40/40/41, 22/40/41/43, 22/43/41/40, 22/40/43/40, 22/41/41/41, 22/40/42/42, 22/40/40/43, 22/43/41/43, 22/42/43/43, 22/41/40/40, 22/40/43/41, 22/40/41/40, 22/41/42/42, 22/42/42/42, 22/40/43/42, 22/43/43/40, 22/40/41/41, 22/41/40/42, 22/43/41/42, 22/43/42/42, 22/43/42/40, 22/42/42/41, 22/43/41/41, 22/41/42/41, 22/42/40/42, 22/42/41/42, 22/42/43/42, 22/42/42/43, 22/40/40/40, 22/43/40/40, 22/41/41/42, 22/41/40/43, 22/43/40/43, 22/41/41/43, 22/41/42/43, 22/40/42/40, 22/42/43/41, 22/43/40/41, 22/43/40/42, 22/40/42/43, 22/43/42/43, 22/40/43/43, 22/41/41/40, 22/41/42/40, 22/41/43/42, 22/43/43/42, 22/42/42/40, 22/41/40/41, 22/41/43/41, 22/40/40/42, 22/42/41/43, 22/41/43/40, 22/42/41/41, 22/42/40/40, 22/42/43/40, 22/42/40/43, 22/41/43/43, 22/42/41/40, 22/43/43/41, 22/43/43/43, 22/43/42/41, 22/40/41/42 | I21: 20 | L21: [20/10/10/10]
C22: 2 | E22: 重複解消後の拡張空間IDが複数 | F22: 21/20/20/20, 21/21/20/20, 21/20/21/20, 21/21/21/20, 21/20/20/21, 21/21/20/21, 21/20/21/21, 21/21/21/21, 22/42/40/41, 22/40/42/41, 22/40/40/41, 22/40/41/43, 22/43/41/40, 22/40/43/40, 22/41/41/41, 22/40/42/42, 22/40/40/43, 22/43/41/43, 22/42/43/43, 22/41/40/40, 22/40/43/41, 22/40/41/40, 22/41/42/42, 22/42/42/42, 22/40/43/42, 22/43/43/40, 22/40/41/41, 22/41/40/42, 22/43/41/42, 22/43/42/42, 22/43/42/40, 22/42/42/41, 22/43/41/41, 22/41/42/41, 22/42/40/42, 22/42/41/42, 22/42/43/42, 22/42/42/43, 22/40/40/40, 22/43/40/40, 22/41/41/42, 22/41/40/43, 22/43/40/43, 22/41/41/43, 22/41/42/43, 22/40/42/40, 22/42/43/41, 22/43/40/41, 22/43/40/42, 22/40/42/43, 22/43/42/43, 22/40/43/43, 22/41/41/40, 22/41/42/40, 22/41/43/42, 22/43/43/42, 22/42/42/40, 22/41/40/41, 22/41/43/41, 22/40/40/42, 22/42/41/43, 22/41/43/40, 22/42/41/41, 22/42/40/40, 22/42/43/40, 22/42/40/43, 22/41/43/43, 22/42/41/40, 22/43/43/41, 22/43/43/43, 22/43/42/41, 22/40/41/42, 21/20/23/23, 21/21/23/23, 21/20/22/22, 21/21/22/22, 21/20/23/22, 21/21/23/22, 21/20/22/23, 21/21/22/23 | I22: 20 | L22: [20/10/10/10 20/10/11/11]
C23: 3 | D23: 重複なし | E23: 重複解消後の拡張空間IDが1つ | F23: 21/20/20/20, 21/21/20/20, 21/20/21/20, 21/21/21/20, 21/20/20/21, 21/21/20/21, 21/20/21/21, 21/21/21/21 | I23: 20 | L23: [20/10/10/10]
C24: 4 | E24: 重複解消後の拡張空間IDが複数 | F24: 21/20/20/20, 21/21/20/20, 21/20/21/20, 21/21/21/20, 21/20/20/21, 21/21/20/21, 21/20/21/21, 21/21/21/21, 21/20/23/23, 21/21/23/23, 21/20/22/22, 21/21/22/22, 21/20/23/22, 21/21/23/22, 21/20/22/23, 21/21/22/23 | I24: 20 | L24: [20/10/10/10 20/10/11/11]
C27: ※1 配列に格納された空間IDの順番は不定

Sheet 【別紙4】最適化前の精度パターン
A1: ■ 最適化前の精度 試験データパターン
B2: 最適化前の拡張空間ID内における精度に関する試験用データ
B4: 〇拡張空間ID試験データ
C5: 変換元として入力する"拡張空間ID"、"変換後の水平/垂直方向精度"及び、精度変換時に取得される期待値を以下に記載する。
C6: 試験実施時は以下に記載する入力値をAPIの引数に入力し、取得された値が期待値と同じであることを確認する。
C8: No | D8: 精度パターン | E8: 変換前拡張空間ID | H8: 変換後水平方向精度 | K8: 変換後垂直方向精度 | N8: 期待値※1
C9: 1 | D9: 最適化前水平方向精度：0 最適化後水平方向精度：1 | E9: 0/0/0/1/0, 0/0/0/1/1 | H9: 1 | K9: 0 | N9: [0/0/0/1/0 0/0/0/1/1]
C10: 2 | D10: 最適化前水平方向精度：35 最適化後水平方向精度：34 | E10: 35/1/0/35/1, 35/0/1/35/0, 35/0/1/35/1, 35/1/1/35/0, 35/1/1/35/1, 35/0/0/35/0, 35/0/0/35/1, 35/1/0/35/0 | H10: 34 | K10: 35 | N10: [34/0/0/35/0 34/0/0/35/1]
C11: 3 | D11: 最適化前垂直方向精度：0 最適化後垂直方向精度：1 | E11: 1/0/0/0/0, 1/1/0/0/0, 1/0/1/0/0, 1/1/1/0/0 | H11: 0 | K11: 1 | N11: [1/0/0/0/0 1/1/0/0/0 1/0/1/0/0 1/1/1/0/0]
C12: 4 | D12: 最適化前垂直方向精度：35 最適化後垂直方向精度：34 | E12: 35/1/0/35/1, 35/0/1/35/0, 35/0/1/35/1, 35/1/1/35/0, 35/1/1/35/1, 35/0/0/35/0, 35/0/0/35/1, 35/1/0/35/0 | H12: 35 | K12: 34 | N12: [35/0/0/34/0 35/1/0/34/0 35/0/1/34/0 35/1/1/34/0]
B16: 〇空間ID試験データ
C17: 変換元として入力する"空間ID"、"変換後の水平/垂直方向精度"及び、精度変換時に取得される期待値を以下に記載する。
C18: 試験実施時は以下に記載する入力値をAPIの引数に入力し、取得された値が期待値と同じであることを確認する。
C20: No | D20: 精度パターン | E20: 変換前空間ID | H20: 変換後精度 | K20: 期待値※1
C21: 1 | D21: 最適化前精度：0 最適化後精度：1 | E21: 0/0/0/0 | H21: 1 | K21: [0/0/0/0]
C22: 2 | D22: 最適化前精度：35 最適化後精度：34 | E22: 35/1/1/0, 35/0/0/1, 35/1/0/1, 35/0/1/1, 35/1/1/1, 35/0/0/0, 35/1/0/0, 35/0/1/0 | H22: 34 | K22: [34/0/0/0]
C25: ※1 配列に格納された空間IDの順番は不定

Sheet 【別紙5】最適化後の精度パターン
A1: ■ 最適化後の精度 試験データパターン
B2: 最適化後の拡張空間ID内における精度に関する試験用データ
B4: 〇拡張空間ID試験データ
C5: 変換元として入力する"拡張空間ID"、"変換後の水平/垂直方向精度"及び、精度変換時に取得される期待値を以下に記載する。
C6: 試験実施時は以下に記載する入力値をAPIの引数に入力し、取得された値が期待値と同じであることを確認する。
C8: No | D8: 精度パターン | E8: 変換前拡張空間ID | H8: 変換後水平方向精度 | K8: 変換後垂直方向精度 | N8: 期待値※1
C9: 1 | D9: 最適化後水平方向精度：0 | E9: 1/0/0/1/0, 1/1/0/1/0, 1/0/1/1/0, 1/1/1/1/0 | H9: 0 | K9: 1 | N9: [0/0/0/1/0]
C10: 2 | D10: 最適化後水平方向精度：35 | E10: 34/0/0/34/0, 34/1/1/34/0 | H10: 35 | K10: 34 | N10: [34/0/0/34/0 34/1/1/34/0]
C11: 3 | D11: 最適化後垂直方向精度：0 | E11: 1/0/0/1/0, 1/0/0/1/1 | H11: 1 | K11: 0 | N11: [1/0/0/0/0]
C12: 4 | D12: 最適化後垂直方向精度：35 | E12: 34/0/0/34/0, 34/0/0/34/1 | H12: 34 | K12: 35 | N12: [34/0/0/34/0 34/0/0/34/1]
B16: 〇空間ID試験データ
C17: 変換元として入力する"空間ID"、"変換後の水平/垂直方向精度"及び、精度変換時に取得される期待値を以下に記載する。
C18: 試験実施時は以下に記載する入力値をAPIの引数に入力し、取得された値が期待値と同じであることを確認する。
C20: No | D20: 精度パターン | E20: 変換前空間ID | H20: 変換後精度 | K20: 期待値※1
C21: 1 | D21: 最適化後精度：0 | E21: 1/1/1/0, 1/0/0/1, 1/1/0/1, 1/0/1/1, 1/1/1/1, 1/0/0/0, 1/1/0/0, 1/0/1/0 | H21: 0 | K21: [0/0/0/0]
C22: 2 | D22: 最適化後精度：35 | E22: 34/0/0/0, 34/1/1/1 | H22: 35 | K22: [34/0/0/0 34/1/1/1]
C25: ※1 配列に格納された空間IDの順番は不定
