Workbook
Name Level2ManDays: 【別紙1】1ボクセルに収まる線分マトリクス!Level2ManDays
Name Level2ManDays: 【別紙2】線分マトリクスパターン!Level2ManDays
Name Level2ManDays: 【別紙3】XYZ方向に長い線分の確認!Level2ManDays
Name Level2ManDays: 【別紙4】精度入力パターン!Level2ManDays
Name Level2ManDays: 変更履歴!Level2ManDays
Name Level2ManDays: [0]!Level2ManDays

Sheet 表紙
AB1: 線分
B7: ="空間ID開発(GO言語版) "&AB1 -> 空間ID開発(GO言語版) 線分
B17: 結合試験項目書
B20: =CONCATENATE(TEXT(MAX(変更履歴!C3:C7),"0.00"), "版") -> 1.01版
B23: 44936

Sheet 変更履歴
B2: 日時 | C2: 版 | D2: 変更箇所 | E2: 作業者 | F2: 変更内容
B3: 44895 | C3: 1 | D3: 全ページ | E3: α | F3: 新規改定
B4: 44936 | C4: 1.01 | D4: 1.結合試験 | E4: α | F4: 線分APIの仕様変更の内容を項目に反映。 - 中点取得の再帰処理関連の試験項目を修正/追加。

Sheet 集計
A1: 集計
B2: 試験シート | C2: 全項目数 | D2: 実施済み | E2: 未実施
B3: 1.結合試験 | C3: =VLOOKUP(B3,$B$8:$D$11,3,FALSE) -> 88 | D3: {=COUNTIF(INDIRECT(B3&"!$K$3:$K$1024"),"OK")-SUMPRODUCT((OFFSET(INDIRECT(B3&"!$K$3:$K$1024"),,)="OK")*(OFFSET(INDIRECT(B3&"!$M$3:$M$1024"),,)<>""))} -> 88 | E3: =C3-D3 -> 0
B4: 計 | C4: =SUM(C3:C3) -> 88 | D4: =SUM(D3:D3) -> 88 | E4: =SUM(E3:E3) -> 0
B6: 試験項目数内訳
B8: 1.結合試験 | C8: 全項目数 | D8: =SUM(D9:D11) -> 88
C9: 正常 | D9: {=COUNTIF(INDIRECT(B8&"!$E$3:$E$1024"),C9)-SUMPRODUCT((OFFSET(INDIRECT(B8&"!$E$3:$E$1024"),,)=C9)*(OFFSET(INDIRECT(B8&"!$M$3:$M$1024"),,)<>""))} -> 80
C10: 準正常 | D10: {=COUNTIF(INDIRECT(B8&"!$E$3:$E$1024"),C10)-SUMPRODUCT((OFFSET(INDIRECT(B8&"!$E$3:$E$1024"),,)=C10)*(OFFSET(INDIRECT(B8&"!$M$3:$M$1024"),,)<>""))} -> 8
C11: 異常 | D11: {=COUNTIF(INDIRECT(B8&"!$E$3:$E$1024"),C11)-SUMPRODUCT((OFFSET(INDIRECT(B8&"!$E$3:$E$1024"),,)=C11)*(OFFSET(INDIRECT(B8&"!$M$3:$M$1024"),,)<>""))} -> 0

Sheet 1.結合試験
A1: =MID(CELL("filename",$A$1),FIND("]",CELL("filename",$A$1))+3,31) -> 結合試験 | K1: OK, NG | R1: シート番号 | S1: =VALUE(MID(CELL("filename",$A$1),FIND("]",CELL("filename",$A$1))+1,2)) -> 1
A2: No | B2: 大項目 | C2: 中項目 | D2: 小項目 | E2: 試験種別 | F2: 優先度 | G2: 確認手順 | H2: 確認内容 | I2: 試験日 | J2: 試験者 | K2: 試験結果 | L2: 備考 | M2: 重複項目 | R2: 大番号 | S2: 中番号 | T2: 小番号
A3: =IF(B3<>"",表紙!$AB$1&"-"&"結合-"&TEXT($S$1,"00")&"-"&TEXT(R3,"00")&"-"&TEXT(S3,"00")&"-"&TEXT(T3,"０00"),"") -> 線分-結合-01-01-01-001 | B3: パラメータ入力チェック | C3: 精度閾値を超過した値を入力する | D3: 水平精度：36 | E3: 準正常 | G3: 1. 引数に以下を指定して、shape.GetSpatialIdsOnLineを呼び出す。 始点: 正常な任意の値 終点: 正常な任意の値 水平精度: 36 垂直精度: 正常な任意の値 | H3: ・以下のspatialIdErrorが返却されること - エラーコード：InputValueError - エラーメッセージ：入力チェックエラー | I3: 44907 | J3: 宮原 | K3: OK | R3: =IF(ROW()<>3,IF(B2<>B3,#REF!+1,#REF!),1) -> 1 | S3: =IF(B2=B3,IF(C2<>C3,#REF!+1,#REF!),1) -> 1 | T3: =IF(B2<>B3,1,IF(C2=C3,#REF!+1,1)) -> 1
A4: =IF(B4<>"",表紙!$AB$1&"-"&"結合-"&TEXT($S$1,"00")&"-"&TEXT(R4,"00")&"-"&TEXT(S4,"00")&"-"&TEXT(T4,"０00"),"") -> 線分-結合-01-01-01-002 | B4: パラメータ入力チェック | C4: 精度閾値を超過した値を入力する | D4: 水平精度：-1 | E4: 準正常 | G4: 1. 引数に以下を指定して、shape.GetSpatialIdsOnLineを呼び出す。 始点: 正常な任意の値 終点: 正常な任意の値 水平精度: -1 垂直精度: 正常な任意の値 | H4: ・以下のspatialIdErrorが返却されること - エラーコード：InputValueError - エラーメッセージ：入力チェックエラー | I4: 44907 | J4: 宮原 | K4: OK | R4: =IF(ROW()<>3,IF(B3<>B4,R3+1,R3),1) -> 1 | S4: =IF(B3=B4,IF(C3<>C4,S3+1,S3),1) -> 1 | T4: =IF(B3<>B4,1,IF(C3=C4,T3+1,1)) -> 2
A5: =IF(B5<>"",表紙!$AB$1&"-"&"結合-"&TEXT($S$1,"00")&"-"&TEXT(R5,"00")&"-"&TEXT(S5,"00")&"-"&TEXT(T5,"０00"),"") -> 線分-結合-01-01-01-003 | B5: パラメータ入力チェック | C5: 精度閾値を超過した値を入力する | D5: 垂直精度：36 | E5: 準正常 | G5: 1. 引数に以下を指定して、shape.GetSpatialIdsOnLineを呼び出す。 始点: 正常な任意の値 終点: 正常な任意の値 水平精度: 正常な任意の値 垂直精度: 36 | H5: ・以下のspatialIdErrorが返却されること - エラーコード：InputValueError - エラーメッセージ：入力チェックエラー | I5: 44907 | J5: 宮原 | K5: OK | R5: =IF(ROW()<>3,IF(B4<>B5,R4+1,R4),1) -> 1 | S5: =IF(B4=B5,IF(C4<>C5,S4+1,S4),1) -> 1 | T5: =IF(B4<>B5,1,IF(C4=C5,T4+1,1)) -> 3
A6: =IF(B6<>"",表紙!$AB$1&"-"&"結合-"&TEXT($S$1,"00")&"-"&TEXT(R6,"00")&"-"&TEXT(S6,"00")&"-"&TEXT(T6,"０00"),"") -> 線分-結合-01-01-01-004 | B6: パラメータ入力チェック | C6: 精度閾値を超過した値を入力する | D6: 垂直精度：-1 | E6: 準正常 | G6: 1. 引数に以下を指定して、shape.GetSpatialIdsOnLineを呼び出す。 始点: 正常な任意の値 終点: 正常な任意の値 水平精度: 正常な任意の値 垂直精度: -1 | H6: ・以下のspatialIdErrorが返却されること - エラーコード：InputValueError - エラーメッセージ：入力チェックエラー | I6: 44907 | J6: 宮原 | K6: OK | R6: =IF(ROW()<>3,IF(B5<>B6,R5+1,R5),1) -> 1 | S6: =IF(B5=B6,IF(C5<>C6,S5+1,S5),1) -> 1 | T6: =IF(B5<>B6,1,IF(C5=C6,T5+1,1)) -> 4
A7: =IF(B7<>"",表紙!$AB$1&"-"&"結合-"&TEXT($S$1,"00")&"-"&TEXT(R7,"00")&"-"&TEXT(S7,"00")&"-"&TEXT(T7,"０00"),"") -> 線分-結合-01-01-01-005 | B7: パラメータ入力チェック | C7: 精度閾値を超過した値を入力する | D7: 水平・垂直精度：36 | E7: 準正常 | G7: 1. 引数に以下を指定して、shape.GetSpatialIdsOnLineを呼び出す。 始点: 正常な任意の値 終点: 正常な任意の値 水平精度: 36 垂直精度: 36 | H7: ・以下のspatialIdErrorが返却されること - エラーコード：InputValueError - エラーメッセージ：入力チェックエラー | I7: 44907 | J7: 宮原 | K7: OK | R7: =IF(ROW()<>3,IF(B6<>B7,R6+1,R6),1) -> 1 | S7: =IF(B6=B7,IF(C6<>C7,S6+1,S6),1) -> 1 | T7: =IF(B6<>B7,1,IF(C6=C7,T6+1,1)) -> 5
A8: =IF(B8<>"",表紙!$AB$1&"-"&"結合-"&TEXT($S$1,"00")&"-"&TEXT(R8,"00")&"-"&TEXT(S8,"00")&"-"&TEXT(T8,"０00"),"") -> 線分-結合-01-01-01-006 | B8: パラメータ入力チェック | C8: 精度閾値を超過した値を入力する | D8: 水平・垂直精度：-1 | E8: 準正常 | G8: 1. 引数に以下を指定して、shape.GetSpatialIdsOnLineを呼び出す。 始点: 正常な任意の値 終点: 正常な任意の値 水平精度: -1 垂直精度: -1 | H8: ・以下のspatialIdErrorが返却されること - エラーコード：InputValueError - エラーメッセージ：入力チェックエラー | I8: 44907 | J8: 宮原 | K8: OK | R8: =IF(ROW()<>3,IF(B7<>B8,R7+1,R7),1) -> 1 | S8: =IF(B7=B8,IF(C7<>C8,S7+1,S7),1) -> 1 | T8: =IF(B7<>B8,1,IF(C7=C8,T7+1,1)) -> 6
A9: =IF(B9<>"",表紙!$AB$1&"-"&"結合-"&TEXT($S$1,"00")&"-"&TEXT(R9,"00")&"-"&TEXT(S9,"00")&"-"&TEXT(T9,"０00"),"") -> 線分-結合-01-01-02-001 | B9: パラメータ入力チェック | C9: 座標にnilを入力する | D9: 始点 | E9: 準正常 | G9: 1. 引数に以下を指定して、shape.GetSpatialIdsOnLineを呼び出す。 始点: nil 終点: 正常な任意の値 水平精度: 正常な任意の値 垂直精度: 正常な任意の値 | H9: ・以下のspatialIdErrorが返却されること - エラーコード：InputValueError - エラーメッセージ：入力チェックエラー | I9: 44907 | J9: 宮原 | K9: OK | R9: =IF(ROW()<>3,IF(B8<>B9,R8+1,R8),1) -> 1 | S9: =IF(B8=B9,IF(C8<>C9,S8+1,S8),1) -> 2 | T9: =IF(B8<>B9,1,IF(C8=C9,T8+1,1)) -> 1
A10: =IF(B10<>"",表紙!$AB$1&"-"&"結合-"&TEXT($S$1,"00")&"-"&TEXT(R10,"00")&"-"&TEXT(S10,"00")&"-"&TEXT(T10,"０00"),"") -> 線分-結合-01-01-02-002 | B10: パラメータ入力チェック | C10: 座標にnilを入力する | D10: 終点 | E10: 準正常 | G10: 1. 引数に以下を指定して、shape.GetSpatialIdsOnLineを呼び出す。 始点: 正常な任意の値 終点: nil 水平精度: 正常な任意の値 垂直精度: 正常な任意の値 | H10: ・以下のspatialIdErrorが返却されること - エラーコード：InputValueError - エラーメッセージ：入力チェックエラー | I10: 44907 | J10: 宮原 | K10: OK | R10: =IF(ROW()<>3,IF(B9<>B10,R9+1,R9),1) -> 1 | S10: =IF(B9=B10,IF(C9<>C10,S9+1,S9),1) -> 2 | T10: =IF(B9<>B10,1,IF(C9=C10,T9+1,1)) -> 2
A11: =IF(B11<>"",表紙!$AB$1&"-"&"結合-"&TEXT($S$1,"00")&"-"&TEXT(R11,"00")&"-"&TEXT(S11,"00")&"-"&TEXT(T11,"０00"),"") -> 線分-結合-01-02-01-001 | B11: 始点終点のパターン網羅 | C11: 始点終点が同じ座標 | D11: - | E11: 正常 | G11: 1. 引数に以下を指定して、shape.GetSpatialIdsOnLineを呼び出す。 始点: 正常な任意の値 終点: 始点と同じ値 水平精度: 正常な任意の値 垂直精度: 正常な任意の値 | H11: ・1個の空間IDが取得できること ・エラーインスタンスが返却されていないこと | I11: 44907 | J11: 宮原 | K11: OK | R11: =IF(ROW()<>3,IF(B10<>B11,R10+1,R10),1) -> 2 | S11: =IF(B10=B11,IF(C10<>C11,S10+1,S10),1) -> 1 | T11: =IF(B10<>B11,1,IF(C10=C11,T10+1,1)) -> 1
A12: =IF(B12<>"",表紙!$AB$1&"-"&"結合-"&TEXT($S$1,"00")&"-"&TEXT(R12,"00")&"-"&TEXT(S12,"00")&"-"&TEXT(T12,"０00"),"") -> 線分-結合-01-02-02-001 | B12: 始点終点のパターン網羅 | C12: 1ボクセルに収まる線分 | D12: 始点: (0,0,0) 終点: (1,0,0) | E12: 正常 | G12: 1. 引数に以下を指定して、shape.GetSpatialIdsOnLineを呼び出す。 "【別紙2】線分マトリクスパターン"シートのNo.1の「始点取得」「終点取得」 | H12: ・入力したパラメータに対応した期待値が取得できること ・エラーインスタンスが返却されていないこと | I12: 44908 | J12: 宮原 | K12: OK | R12: =IF(ROW()<>3,IF(B11<>B12,R11+1,R11),1) -> 2 | S12: =IF(B11=B12,IF(C11<>C12,S11+1,S11),1) -> 2 | T12: =IF(B11<>B12,1,IF(C11=C12,T11+1,1)) -> 1
A13: =IF(B13<>"",表紙!$AB$1&"-"&"結合-"&TEXT($S$1,"00")&"-"&TEXT(R13,"00")&"-"&TEXT(S13,"00")&"-"&TEXT(T13,"０00"),"") -> 線分-結合-01-02-02-002 | B13: 始点終点のパターン網羅 | C13: 1ボクセルに収まる線分 | D13: 始点: (0,0,0) 終点: (0,1,0) | E13: 正常 | G13: 1. 引数に以下を指定して、shape.GetSpatialIdsOnLineを呼び出す。 "【別紙2】線分マトリクスパターン"シートのNo.2の「始点取得」「終点取得」 | H13: ・入力したパラメータに対応した期待値が取得できること ・エラーインスタンスが返却されていないこと | I13: 44908 | J13: 宮原 | K13: OK | R13: =IF(ROW()<>3,IF(B12<>B13,R12+1,R12),1) -> 2 | S13: =IF(B12=B13,IF(C12<>C13,S12+1,S12),1) -> 2 | T13: =IF(B12<>B13,1,IF(C12=C13,T12+1,1)) -> 2
A14: =IF(B14<>"",表紙!$AB$1&"-"&"結合-"&TEXT($S$1,"00")&"-"&TEXT(R14,"00")&"-"&TEXT(S14,"00")&"-"&TEXT(T14,"０00"),"") -> 線分-結合-01-02-02-003 | B14: 始点終点のパターン網羅 | C14: 1ボクセルに収まる線分 | D14: 始点: (0,0,0) 終点: (0,0,1) | E14: 正常 | G14: 1. 引数に以下を指定して、shape.GetSpatialIdsOnLineを呼び出す。 "【別紙2】線分マトリクスパターン"シートのNo.3の「始点取得」「終点取得」 | H14: ・入力したパラメータに対応した期待値が取得できること ・エラーインスタンスが返却されていないこと | I14: 44908 | J14: 宮原 | K14: OK | R14: =IF(ROW()<>3,IF(B13<>B14,R13+1,R13),1) -> 2 | S14: =IF(B13=B14,IF(C13<>C14,S13+1,S13),1) -> 2 | T14: =IF(B13<>B14,1,IF(C13=C14,T13+1,1)) -> 3
A15: =IF(B15<>"",表紙!$AB$1&"-"&"結合-"&TEXT($S$1,"00")&"-"&TEXT(R15,"00")&"-"&TEXT(S15,"00")&"-"&TEXT(T15,"０00"),"") -> 線分-結合-01-02-02-004 | B15: 始点終点のパターン網羅 | C15: 1ボクセルに収まる線分 | D15: 始点: (0,0,0) 終点: (1,1,0) | E15: 正常 | G15: 1. 引数に以下を指定して、shape.GetSpatialIdsOnLineを呼び出す。 "【別紙2】線分マトリクスパターン"シートのNo.4の「始点取得」「終点取得」 | H15: ・入力したパラメータに対応した期待値が取得できること ・エラーインスタンスが返却されていないこと | I15: 44908 | J15: 宮原 | K15: OK | R15: =IF(ROW()<>3,IF(B14<>B15,R14+1,R14),1) -> 2 | S15: =IF(B14=B15,IF(C14<>C15,S14+1,S14),1) -> 2 | T15: =IF(B14<>B15,1,IF(C14=C15,T14+1,1)) -> 4
... A77: =IF(B77<>"",表紙!$AB$1&"-"&"結合-"&TEXT($S$1,"00")&"-"&TEXT(R77,"00")&"-"&TEXT(S77,"00")&"-"&TEXT(T77,"０00"),"") -> 線分-結合-01-02-11-001 | B77: 始点終点のパターン網羅 | C77: 精度を変えても空間IDが取得できる | D77: - | E77: 正常 | G77: 1. 引数に以下を指定して、shape.GetSpatialIdsOnLineを呼び出す。 "【別紙4】精度入力パターン"シートの全パターンの「始点」「終点」「精度」 | H77: ・入力したパラメータに対応した期待値が取得できること ・エラーインスタンスが返却されていないこと | I77: 44907 | J77: 宮原 | K77: OK | R77: =IF(ROW()<>3,IF(B76<>B77,R76+1,R76),1) -> 2 | S77: =IF(B76=B77,IF(C76<>C77,S76+1,S76),1) -> 11 | T77: =IF(B76<>B77,1,IF(C76=C77,T76+1,1)) -> 1
A78: =IF(B78<>"",表紙!$AB$1&"-"&"結合-"&TEXT($S$1,"00")&"-"&TEXT(R78,"00")&"-"&TEXT(S78,"00")&"-"&TEXT(T78,"０00"),"") -> 線分-結合-01-02-12-001 | B78: 始点終点のパターン網羅 | C78: Python版の「指定範囲の空間ID変換 (線分)」と同一の結果が取得できる | D78: - | E78: 正常 | M78: =$A$72 -> 線分-結合-01-02-07-001 | R78: =IF(ROW()<>3,IF(B77<>B78,R77+1,R77),1) -> 2 | S78: =IF(B77=B78,IF(C77<>C78,S77+1,S77),1) -> 12 | T78: =IF(B77<>B78,1,IF(C77=C78,T77+1,1)) -> 1
A79: =IF(B79<>"",表紙!$AB$1&"-"&"結合-"&TEXT($S$1,"00")&"-"&TEXT(R79,"00")&"-"&TEXT(S79,"00")&"-"&TEXT(T79,"０00"),"") -> 線分-結合-01-03-01-001 | B79: 中点取得の再起処理終了パターンの網羅 | C79: 分割された線分の端点2つの拡張空間IDが同じ | D79: - | E79: 正常 | G79: 1. 引数に以下を指定して、shape.GetSpatialIdsOnLineを呼び出す。 始点: object.NewPoint(-179.82421875, 85.0359182614, 16384.0) 終点: object.NewPoint(-179.12109375, 84.9438129428, 147456.0) 水平精度: 10 垂直精度: 10 | H79: ・始点終点間の空間IDが全て取得できていること [10/0/0/10/0 10/0/0/10/1 10/0/1/10/1 10/1/1/10/1 10/1/1/10/2 10/1/2/10/2 10/1/2/10/3 10/2/2/10/3 10/2/3/10/3 10/2/3/10/4] ・エラーインスタンスが返却されていないこと ・空間IDデバッグログに以下のメッセージが出力されていること。 "中点が始点・終点の周囲にあるため終了" ・空間IDデバッグログに以下のメッセージが出力されていないこと。 "ベクトルの成分が閾値未満のため終了" | I79: 44907 | J79: 宮原 | K79: OK | R79: =IF(ROW()<>3,IF(B78<>B79,R78+1,R78),1) -> 3 | S79: =IF(B78=B79,IF(C78<>C79,S78+1,S78),1) -> 1 | T79: =IF(B78<>B79,1,IF(C78=C79,T78+1,1)) -> 1
A80: =IF(B80<>"",表紙!$AB$1&"-"&"結合-"&TEXT($S$1,"00")&"-"&TEXT(R80,"00")&"-"&TEXT(S80,"00")&"-"&TEXT(T80,"０00"),"") -> 線分-結合-01-03-02-001 | B80: 中点取得の再起処理終了パターンの網羅 | C80: 分割された線分の端点2つの拡張空間IDが隣接する（前後左右上下の6方向） | D80: 経度方向に平行：デフォルト閾値 | E80: 正常 | G80: 1. 引数に以下を指定して、shape.GetSpatialIdsOnLineを呼び出す。 始点：object.NewPoint(-179.99999983236194, 85.0511287653, 0.001953125) 終点：object.NewPoint(-179.99999782070518, 85.0511287653, 0.001953125) 水平精度: 30 垂直精度: 33 | H80: ・始点終点間の空間IDが全て取得できていること [30/0/0/33/0 30/1/0/33/0 30/2/0/33/0 30/3/0/33/0 30/4/0/33/0 30/5/0/33/0 30/6/0/33/0] ・エラーインスタンスが返却されていないこと ・空間IDデバッグログに以下のメッセージが出力されていること。 "中点が始点・終点の周囲にあるため終了" ・空間IDデバッグログに以下のメッセージが出力されていないこと。 "ベクトルの成分が閾値未満のため終了" | I80: 44936 | J80: 宮原 | K80: OK | R80: =IF(ROW()<>3,IF(B79<>B80,R79+1,R79),1) -> 3 | S80: =IF(B79=B80,IF(C79<>C80,S79+1,S79),1) -> 2 | T80: =IF(B79<>B80,1,IF(C79=C80,T79+1,1)) -> 1
A81: =IF(B81<>"",表紙!$AB$1&"-"&"結合-"&TEXT($S$1,"00")&"-"&TEXT(R81,"00")&"-"&TEXT(S81,"00")&"-"&TEXT(T81,"０00"),"") -> 線分-結合-01-03-02-002 | B81: 中点取得の再起処理終了パターンの網羅 | C81: 分割された線分の端点2つの拡張空間IDが隣接する（前後左右上下の6方向） | D81: 経度方向に平行：高精度閾値 | E81: 正常 | G81: 1. 引数に以下を指定して、shape.GetSpatialIdsOnLineを呼び出す。 始点：object.NewPoint(-179.99999991618097, 85.0511287725, 0.0009765625) 終点：object.NewPoint(-179.9999989103526, 85.0511287725, 0.0009765625) 水平精度: 31 垂直精度: 34 | H81: ・始点終点間の空間IDが全て取得できていること [31/0/0/34/0 31/1/0/34/0 31/2/0/34/0 31/3/0/34/0 31/4/0/34/0 31/5/0/34/0 31/6/0/34/0] ・エラーインスタンスが返却されていないこと ・空間IDデバッグログに以下のメッセージが出力されていること。 "中点が始点・終点の周囲にあるため終了" ・空間IDデバッグログに以下のメッセージが出力されていないこと。 "ベクトルの成分が閾値未満のため終了" | I81: 44936 | J81: 宮原 | K81: OK | R81: =IF(ROW()<>3,IF(B80<>B81,R80+1,R80),1) -> 3 | S81: =IF(B80=B81,IF(C80<>C81,S80+1,S80),1) -> 2 | T81: =IF(B80<>B81,1,IF(C80=C81,T80+1,1)) -> 2
A82: =IF(B82<>"",表紙!$AB$1&"-"&"結合-"&TEXT($S$1,"00")&"-"&TEXT(R82,"00")&"-"&TEXT(S82,"00")&"-"&TEXT(T82,"０00"),"") -> 線分-結合-01-03-02-003 | B82: 中点取得の再起処理終了パターンの網羅 | C82: 分割された線分の端点2つの拡張空間IDが隣接する（前後左右上下の6方向） | D82: 緯度方向に平行：デフォルト閾値 | E82: 正常 | G82: 1. 引数に以下を指定して、shape.GetSpatialIdsOnLineを呼び出す。 始点：object.NewPoint(-179.99999983236194, 85.0511287653, 0.001953125) 終点：object.NewPoint(-179.99999983236194, 85.0511285917, 0.001953125) 水平精度: 30 垂直精度: 33 | H82: ・始点終点間の空間IDが全て取得できていること [30/0/0/33/0 30/0/1/33/0 30/0/2/33/0 30/0/3/33/0 30/0/4/33/0 30/0/5/33/0 30/0/6/33/0] ・エラーインスタンスが返却されていないこと ・空間IDデバッグログに以下のメッセージが出力されていること。 "中点が始点・終点の周囲にあるため終了" ・空間IDデバッグログに以下のメッセージが出力されていないこと。 "ベクトルの成分が閾値未満のため終了" | I82: 44936 | J82: 宮原 | K82: OK | R82: =IF(ROW()<>3,IF(B81<>B82,R81+1,R81),1) -> 3 | S82: =IF(B81=B82,IF(C81<>C82,S81+1,S81),1) -> 2 | T82: =IF(B81<>B82,1,IF(C81=C82,T81+1,1)) -> 3
A83: =IF(B83<>"",表紙!$AB$1&"-"&"結合-"&TEXT($S$1,"00")&"-"&TEXT(R83,"00")&"-"&TEXT(S83,"00")&"-"&TEXT(T83,"０00"),"") -> 線分-結合-01-03-02-004 | B83: 中点取得の再起処理終了パターンの網羅 | C83: 分割された線分の端点2つの拡張空間IDが隣接する（前後左右上下の6方向） | D83: 緯度方向に平行：高精度閾値 | E83: 正常 | G83: 1. 引数に以下を指定して、shape.GetSpatialIdsOnLineを呼び出す。 始点：object.NewPoint(-179.99999991618097, 85.0511287725, 0.0009765625) 終点：object.NewPoint(-179.99999991618097, 85.0511286857, 0.0009765625) 水平精度: 31 垂直精度: 34 | H83: ・始点終点間の空間IDが全て取得できていること [31/0/0/34/0 31/0/1/34/0 31/0/2/34/0 31/0/3/34/0 31/0/4/34/0 31/0/5/34/0 31/0/6/34/0] ・エラーインスタンスが返却されていないこと ・空間IDデバッグログに以下のメッセージが出力されていること。 "中点が始点・終点の周囲にあるため終了" ・空間IDデバッグログに以下のメッセージが出力されていないこと。 "ベクトルの成分が閾値未満のため終了" | I83: 44936 | J83: 宮原 | K83: OK | R83: =IF(ROW()<>3,IF(B82<>B83,R82+1,R82),1) -> 3 | S83: =IF(B82=B83,IF(C82<>C83,S82+1,S82),1) -> 2 | T83: =IF(B82<>B83,1,IF(C82=C83,T82+1,1)) -> 4
A84: =IF(B84<>"",表紙!$AB$1&"-"&"結合-"&TEXT($S$1,"00")&"-"&TEXT(R84,"00")&"-"&TEXT(S84,"00")&"-"&TEXT(T84,"０00"),"") -> 線分-結合-01-03-02-005 | B84: 中点取得の再起処理終了パターンの網羅 | C84: 分割された線分の端点2つの拡張空間IDが隣接する（前後左右上下の6方向） | D84: 高さ方向に平行：デフォルト閾値 | E84: 正常 | G84: 1. 引数に以下を指定して、shape.GetSpatialIdsOnLineを呼び出す。 始点：object.NewPoint(-179.99999983236194, 85.0511287653, 0.001953125) 終点：object.NewPoint(-179.99999983236194, 85.0511287653, 0.025390625) 水平精度: 30 垂直精度: 33 | H84: ・始点終点間の空間IDが全て取得できていること [30/0/0/33/0 30/0/0/33/1 30/0/0/33/2 30/0/0/33/3 30/0/0/33/4 30/0/0/33/5 30/0/0/33/6] ・エラーインスタンスが返却されていないこと ・空間IDデバッグログに以下のメッセージが出力されていること。 "中点が始点・終点の周囲にあるため終了" ・空間IDデバッグログに以下のメッセージが出力されていないこと。 "ベクトルの成分が閾値未満のため終了" | I84: 44936 | J84: 宮原 | K84: OK | R84: =IF(ROW()<>3,IF(B83<>B84,R83+1,R83),1) -> 3 | S84: =IF(B83=B84,IF(C83<>C84,S83+1,S83),1) -> 2 | T84: =IF(B83<>B84,1,IF(C83=C84,T83+1,1)) -> 5
A85: =IF(B85<>"",表紙!$AB$1&"-"&"結合-"&TEXT($S$1,"00")&"-"&TEXT(R85,"00")&"-"&TEXT(S85,"00")&"-"&TEXT(T85,"０00"),"") -> 線分-結合-01-03-02-006 | B85: 中点取得の再起処理終了パターンの網羅 | C85: 分割された線分の端点2つの拡張空間IDが隣接する（前後左右上下の6方向） | D85: 高さ方向に平行：高精度閾値 | E85: 正常 | G85: 1. 引数に以下を指定して、shape.GetSpatialIdsOnLineを呼び出す。 始点：object.NewPoint(-179.99999991618097, 85.0511287725, 0.0009765625) 終点：object.NewPoint(-179.99999991618097, 85.0511287725, 0.0126953125) 水平精度: 31 垂直精度: 34 | H85: ・始点終点間の空間IDが全て取得できていること [31/0/0/34/0 31/0/0/34/1 31/0/0/34/2 31/0/0/34/3 31/0/0/34/4 31/0/0/34/5 31/0/0/34/6] ・エラーインスタンスが返却されていないこと ・空間IDデバッグログに以下のメッセージが出力されていること。 "中点が始点・終点の周囲にあるため終了" ・空間IDデバッグログに以下のメッセージが出力されていないこと。 "ベクトルの成分が閾値未満のため終了" | I85: 44936 | J85: 宮原 | K85: OK | R85: =IF(ROW()<>3,IF(B84<>B85,R84+1,R84),1) -> 3 | S85: =IF(B84=B85,IF(C84<>C85,S84+1,S84),1) -> 2 | T85: =IF(B84<>B85,1,IF(C84=C85,T84+1,1)) -> 6
A86: =IF(B86<>"",表紙!$AB$1&"-"&"結合-"&TEXT($S$1,"00")&"-"&TEXT(R86,"00")&"-"&TEXT(S86,"00")&"-"&TEXT(T86,"０00"),"") -> 線分-結合-01-03-03-001 | B86: 中点取得の再起処理終了パターンの網羅 | C86: 中点取得の閾値がデフォルトの場合、線分中点と始点終点の距離のすべての成分が閾値未満となる線分の確認 | D86: 経度が境界値以上から未満になるパターン | E86: 正常 | G86: 1. 引数に以下を指定して、shape.GetSpatialIdsOnLineを呼び出す。 始点: object.NewPoint(-179.99999983236194, 85.0511287653, 0.001953125) 終点: object.NewPoint(-179.99999782070518, 85.0511285917, 0.001953125) 水平精度: 30 垂直精度: 33 | H86: ・始点終点間の空間IDが全て取得できていること [30/0/0/33/0 30/1/1/33/0 30/2/2/33/0 30/3/3/33/0 30/4/4/33/0 30/5/5/33/0 30/6/6/33/0] ・エラーインスタンスが返却されていないこと ・空間IDデバッグログに以下のメッセージが出力されていること。 "ベクトルの成分が閾値未満のため終了" ・空間IDデバッグログに以下の閾値が表示されていること。 "ベクトル閾値:X=2e-08, Y=2e-08, Z=0.003" | I86: 44936 | J86: 宮原 | K86: OK | L86: 本項目で取得される空間IDは、Python版で同じ値を入力した場合と差異がある。 線分の空間ID取得のロジックがGo版とPython版とで異なるため、差異が出ている可能性がある。 Python版は経度、緯度、高さ境界面と線分が接触している箇所の空間IDを取得するロジックだが、 Go版は線分の始点、終点間の中点を再帰的に取得し、その中点の空間IDを取得するロジックとなっている。 | R86: =IF(ROW()<>3,IF(B85<>B86,R85+1,R85),1) -> 3 | S86: =IF(B85=B86,IF(C85<>C86,S85+1,S85),1) -> 3 | T86: =IF(B85<>B86,1,IF(C85=C86,T85+1,1)) -> 1
A87: =IF(B87<>"",表紙!$AB$1&"-"&"結合-"&TEXT($S$1,"00")&"-"&TEXT(R87,"00")&"-"&TEXT(S87,"00")&"-"&TEXT(T87,"０00"),"") -> 線分-結合-01-03-03-002 | B87: 中点取得の再起処理終了パターンの網羅 | C87: 中点取得の閾値がデフォルトの場合、線分中点と始点終点の距離のすべての成分が閾値未満となる線分の確認 | D87: 緯度が境界値以上から未満になるパターン | E87: 正常 | G87: 1. 引数に以下を指定して、shape.GetSpatialIdsOnLineを呼び出す。 始点: object.NewPoint(-179.99999983236194, 85.0511287653, 0.001953125) 終点: object.NewPoint(-179.99999983236194, 85.0511285917, 0.025390625) 水平精度: 30 垂直精度: 33 | H87: ・始点終点間の空間IDが全て取得できていること [30/0/0/33/0 30/0/1/33/1 30/0/2/33/2 30/0/3/33/3 30/0/4/33/4 30/0/5/33/5 30/0/6/33/6] ・エラーインスタンスが返却されていないこと ・空間IDデバッグログに以下のメッセージが出力されていること。 "ベクトルの成分が閾値未満のため終了" ・空間IDデバッグログに以下の閾値が表示されていること。 "ベクトル閾値:X=2e-08, Y=2e-08, Z=0.003" | I87: 44936 | J87: 宮原 | K87: OK | L87: 同上 | R87: =IF(ROW()<>3,IF(B86<>B87,R86+1,R86),1) -> 3 | S87: =IF(B86=B87,IF(C86<>C87,S86+1,S86),1) -> 3 | T87: =IF(B86<>B87,1,IF(C86=C87,T86+1,1)) -> 2
A88: =IF(B88<>"",表紙!$AB$1&"-"&"結合-"&TEXT($S$1,"00")&"-"&TEXT(R88,"00")&"-"&TEXT(S88,"00")&"-"&TEXT(T88,"０00"),"") -> 線分-結合-01-03-03-003 | B88: 中点取得の再起処理終了パターンの網羅 | C88: 中点取得の閾値がデフォルトの場合、線分中点と始点終点の距離のすべての成分が閾値未満となる線分の確認 | D88: 高さが境界値以上から未満になるパターン | E88: 正常 | L88: 同上 | M88: =$A$87 -> 線分-結合-01-03-03-002 | R88: =IF(ROW()<>3,IF(B87<>B88,R87+1,R87),1) -> 3 | S88: =IF(B87=B88,IF(C87<>C88,S87+1,S87),1) -> 3 | T88: =IF(B87<>B88,1,IF(C87=C88,T87+1,1)) -> 3
A89: =IF(B89<>"",表紙!$AB$1&"-"&"結合-"&TEXT($S$1,"00")&"-"&TEXT(R89,"00")&"-"&TEXT(S89,"00")&"-"&TEXT(T89,"０00"),"") -> 線分-結合-01-03-03-004 | B89: 中点取得の再起処理終了パターンの網羅 | C89: 中点取得の閾値がデフォルトの場合、線分中点と始点終点の距離のすべての成分が閾値未満となる線分の確認 | D89: 経度・緯度・高さが以上から未満になるパターン | E89: 正常 | G89: 1. 引数に以下を指定して、shape.GetSpatialIdsOnLineを呼び出す。 始点: object.NewPoint(-179.99999983236194, 85.0511287653, 0.001953125) 終点: object.NewPoint(-179.99999782070518, 85.0511285917, 0.025390625) 水平精度: 30 垂直精度: 33 | H89: ・始点終点間の空間IDが全て取得できていること [30/0/0/33/0 30/1/1/33/1 30/2/2/33/2 30/3/3/33/3 30/4/4/33/4 30/5/5/33/5 30/6/6/33/6] ・エラーインスタンスが返却されていないこと ・空間IDデバッグログに以下のメッセージが出力されていること。 "ベクトルの成分が閾値未満のため終了" ・空間IDデバッグログに以下の閾値が表示されていること。 "ベクトル閾値:X=2e-08, Y=2e-08, Z=0.003" | I89: 44936 | J89: 宮原 | K89: OK | L89: 同上 | R89: =IF(ROW()<>3,IF(B88<>B89,R88+1,R88),1) -> 3 | S89: =IF(B88=B89,IF(C88<>C89,S88+1,S88),1) -> 3 | T89: =IF(B88<>B89,1,IF(C88=C89,T88+1,1)) -> 4
A90: =IF(B90<>"",表紙!$AB$1&"-"&"結合-"&TEXT($S$1,"00")&"-"&TEXT(R90,"00")&"-"&TEXT(S90,"00")&"-"&TEXT(T90,"０00"),"") -> 線分-結合-01-03-04-001 | B90: 中点取得の再起処理終了パターンの網羅 | C90: 中点取得の閾値が高精度用の場合、線分中点と始点終点の距離のすべての成分が閾値未満となる線分の確認 | D90: 経度が境界値以上から未満になるパターン | E90: 正常 | G90: 1. 引数に以下を指定して、shape.GetSpatialIdsOnLineを呼び出す。 始点: object.NewPoint(-179.9999999947613, 85.0511287793, 0.00048828125) 終点: object.NewPoint(-179.99999993189704, 85.0511287738, 0.00048828125) 水平精度: 35 垂直精度: 35 | H90: ・始点終点間の空間IDが全て取得できていること [35/0/0/35/0 35/0/1/35/0 35/1/1/35/0 35/2/2/35/0 35/2/3/35/0 35/3/3/35/0 35/4/4/35/0 35/5/5/35/0 35/5/6/35/0 35/6/6/35/0] ・エラーインスタンスが返却されていないこと ・空間IDデバッグログに以下のメッセージが出力されていること。 "ベクトルの成分が閾値未満のため終了" ・空間IDデバッグログに以下の閾値が表示されていること。 "ベクトル閾値:X=5e-09, Y=5e-10, Z=0.0005" | I90: 44937 | J90: 宮原 | K90: OK | L90: 同上 | R90: =IF(ROW()<>3,IF(B89<>B90,R89+1,R89),1) -> 3 | S90: =IF(B89=B90,IF(C89<>C90,S89+1,S89),1) -> 4 | T90: =IF(B89<>B90,1,IF(C89=C90,T89+1,1)) -> 1
A91: =IF(B91<>"",表紙!$AB$1&"-"&"結合-"&TEXT($S$1,"00")&"-"&TEXT(R91,"00")&"-"&TEXT(S91,"00")&"-"&TEXT(T91,"０00"),"") -> 線分-結合-01-03-04-002 | B91: 中点取得の再起処理終了パターンの網羅 | C91: 中点取得の閾値が高精度用の場合、線分中点と始点終点の距離のすべての成分が閾値未満となる線分の確認 | D91: 緯度が境界値以上から未満になるパターン | E91: 正常 | G91: 1. 引数に以下を指定して、shape.GetSpatialIdsOnLineを呼び出す。 始点: object.NewPoint(-179.9999999947613, 85.0511287793, 0.00048828125) 終点: object.NewPoint(-179.9999999947613, 85.0511287738, 0.00634765625) 水平精度: 35 垂直精度: 35 | H91: ・始点終点間の空間IDが全て取得できていること [35/0/0/35/0 35/0/1/35/0 35/0/1/35/1 35/0/2/35/2 35/0/3/35/2 35/0/3/35/3 35/0/4/35/4 35/0/5/35/5 35/0/6/35/5 35/0/6/35/6] ・エラーインスタンスが返却されていないこと ・空間IDデバッグログに以下のメッセージが出力されていること。 "ベクトルの成分が閾値未満のため終了" ・空間IDデバッグログに以下の閾値が表示されていること。 "ベクトル閾値:X=5e-09, Y=5e-10, Z=0.0005" | I91: 44937 | J91: 宮原 | K91: OK | L91: 同上 | R91: =IF(ROW()<>3,IF(B90<>B91,R90+1,R90),1) -> 3 | S91: =IF(B90=B91,IF(C90<>C91,S90+1,S90),1) -> 4 | T91: =IF(B90<>B91,1,IF(C90=C91,T90+1,1)) -> 2
A92: =IF(B92<>"",表紙!$AB$1&"-"&"結合-"&TEXT($S$1,"00")&"-"&TEXT(R92,"00")&"-"&TEXT(S92,"00")&"-"&TEXT(T92,"０00"),"") -> 線分-結合-01-03-04-003 | B92: 中点取得の再起処理終了パターンの網羅 | C92: 中点取得の閾値が高精度用の場合、線分中点と始点終点の距離のすべての成分が閾値未満となる線分の確認 | D92: 高さが境界値以上から未満になるパターン | E92: 正常 | L92: 同上 | M92: =$A$91 -> 線分-結合-01-03-04-002 | R92: =IF(ROW()<>3,IF(B91<>B92,R91+1,R91),1) -> 3 | S92: =IF(B91=B92,IF(C91<>C92,S91+1,S91),1) -> 4 | T92: =IF(B91<>B92,1,IF(C91=C92,T91+1,1)) -> 3
A93: =IF(B93<>"",表紙!$AB$1&"-"&"結合-"&TEXT($S$1,"00")&"-"&TEXT(R93,"00")&"-"&TEXT(S93,"00")&"-"&TEXT(T93,"０00"),"") -> 線分-結合-01-03-04-004 | B93: 中点取得の再起処理終了パターンの網羅 | C93: 中点取得の閾値が高精度用の場合、線分中点と始点終点の距離のすべての成分が閾値未満となる線分の確認 | D93: 経度・緯度・高さが以上から未満になるパターン | E93: 正常 | G93: 1. 引数に以下を指定して、shape.GetSpatialIdsOnLineを呼び出す。 始点: object.NewPoint(-179.9999999947613, 85.0511287793, 0.00048828125) 終点: object.NewPoint(-179.99999993189704, 85.0511287738, 0.00634765625) 水平精度: 35 垂直精度: 35 | H93: ・始点終点間の空間IDが全て取得できていること [35/0/0/35/0 35/0/1/35/0 35/1/1/35/1 35/2/2/35/2 35/2/3/35/2 35/3/3/35/3 35/4/4/35/4 35/5/5/35/5 35/5/6/35/5 35/6/6/35/6] ・エラーインスタンスが返却されていないこと ・空間IDデバッグログに以下のメッセージが出力されていること。 "ベクトルの成分が閾値未満のため終了" ・空間IDデバッグログに以下の閾値が表示されていること。 "ベクトル閾値:X=5e-09, Y=5e-10, Z=0.0005" | I93: 44937 | J93: 宮原 | K93: OK | L93: 同上 | R93: =IF(ROW()<>3,IF(B92<>B93,R92+1,R92),1) -> 3 | S93: =IF(B92=B93,IF(C92<>C93,S92+1,S92),1) -> 4 | T93: =IF(B92<>B93,1,IF(C92=C93,T92+1,1)) -> 4
A94: =IF(B94<>"",表紙!$AB$1&"-"&"結合-"&TEXT($S$1,"00")&"-"&TEXT(R94,"00")&"-"&TEXT(S94,"00")&"-"&TEXT(T94,"０00"),"") | R94: =IF(ROW()<>3,IF(B93<>B94,R93+1,R93),1) -> 4 | S94: =IF(B93=B94,IF(C93<>C94,S93+1,S93),1) -> 1 | T94: =IF(B93<>B94,1,IF(C93=C94,T93+1,1)) -> 1
A95: =IF(B95<>"",表紙!$AB$1&"-"&"結合-"&TEXT($S$1,"00")&"-"&TEXT(R95,"00")&"-"&TEXT(S95,"00")&"-"&TEXT(T95,"０00"),"") | R95: =IF(ROW()<>3,IF(B94<>B95,R94+1,R94),1) -> 4 | S95: =IF(B94=B95,IF(C94<>C95,S94+1,S94),1) -> 1 | T95: =IF(B94<>B95,1,IF(C94=C95,T94+1,1)) -> 2
A96: =IF(B96<>"",表紙!$AB$1&"-"&"結合-"&TEXT($S$1,"00")&"-"&TEXT(R96,"00")&"-"&TEXT(S96,"00")&"-"&TEXT(T96,"０00"),"") | R96: =IF(ROW()<>3,IF(B95<>B96,R95+1,R95),1) -> 4 | S96: =IF(B95=B96,IF(C95<>C96,S95+1,S95),1) -> 1 | T96: =IF(B95<>B96,1,IF(C95=C96,T95+1,1)) -> 3
A97: =IF(B97<>"",表紙!$AB$1&"-"&"結合-"&TEXT($S$1,"00")&"-"&TEXT(R97,"00")&"-"&TEXT(S97,"00")&"-"&TEXT(T97,"０00"),"") | R97: =IF(ROW()<>3,IF(B96<>B97,R96+1,R96),1) -> 4 | S97: =IF(B96=B97,IF(C96<>C97,S96+1,S96),1) -> 1 | T97: =IF(B96<>B97,1,IF(C96=C97,T96+1,1)) -> 4
A98: =IF(B98<>"",表紙!$AB$1&"-"&"結合-"&TEXT($S$1,"00")&"-"&TEXT(R98,"00")&"-"&TEXT(S98,"00")&"-"&TEXT(T98,"０00"),"") | R98: =IF(ROW()<>3,IF(B97<>B98,R97+1,R97),1) -> 4 | S98: =IF(B97=B98,IF(C97<>C98,S97+1,S97),1) -> 1 | T98: =IF(B97<>B98,1,IF(C97=C98,T97+1,1)) -> 5
A99: =IF(B99<>"",表紙!$AB$1&"-"&"結合-"&TEXT($S$1,"00")&"-"&TEXT(R99,"00")&"-"&TEXT(S99,"00")&"-"&TEXT(T99,"０00"),"") | R99: =IF(ROW()<>3,IF(B98<>B99,R98+1,R98),1) -> 4 | S99: =IF(B98=B99,IF(C98<>C99,S98+1,S98),1) -> 1 | T99: =IF(B98<>B99,1,IF(C98=C99,T98+1,1)) -> 6
A100: =IF(B100<>"",表紙!$AB$1&"-"&"結合-"&TEXT($S$1,"00")&"-"&TEXT(R100,"00")&"-"&TEXT(S100,"00")&"-"&TEXT(T100,"０00"),"") | R100: =IF(ROW()<>3,IF(B99<>B100,R99+1,R99),1) -> 4 | S100: =IF(B99=B100,IF(C99<>C100,S99+1,S99),1) -> 1 | T100: =IF(B99<>B100,1,IF(C99=C100,T99+1,1)) -> 7
A101: =IF(B101<>"",表紙!$AB$1&"-"&"結合-"&TEXT($S$1,"00")&"-"&TEXT(R101,"00")&"-"&TEXT(S101,"00")&"-"&TEXT(T101,"０00"),"") | R101: =IF(ROW()<>3,IF(B100<>B101,R100+1,R100),1) -> 4 | S101: =IF(B100=B101,IF(C100<>C101,S100+1,S100),1) -> 1 | T101: =IF(B100<>B101,1,IF(C100=C101,T100+1,1)) -> 8
...

Sheet 【別紙1】1ボクセルに収まる線分マトリクス
A1: ■ 1ボクセルに収まる線分のマトリクス確認
B3: ○網羅パターン
C4: 行（始点）、列（終点）として判定を行う（以下は大きさ1のボクセルとして記載する）
D5: 終点
D6: (0,0,0) | E6: (1,0,0) | F6: (0,1,0) | G6: (0,0,1) | H6: (1,1,0) | I6: (0,1,1) | J6: (1,0,1) | K6: (1,1,1)
B7: 始点 | C7: (0,0,0) | D7: - | E7: ="始点: "&$C7&" 終点: "&E$6 -> 始点: (0,0,0) 終点: (1,0,0) | F7: ="始点: "&$C7&" 終点: "&F$6 -> 始点: (0,0,0) 終点: (0,1,0) | G7: ="始点: "&$C7&" 終点: "&G$6 -> 始点: (0,0,0) 終点: (0,0,1) | H7: ="始点: "&$C7&" 終点: "&H$6 -> 始点: (0,0,0) 終点: (1,1,0) | I7: ="始点: "&$C7&" 終点: "&I$6 -> 始点: (0,0,0) 終点: (0,1,1) | J7: ="始点: "&$C7&" 終点: "&J$6 -> 始点: (0,0,0) 終点: (1,0,1) | K7: ="始点: "&$C7&" 終点: "&K$6 -> 始点: (0,0,0) 終点: (1,1,1)
C8: (1,0,0) | D8: ="始点: "&$C8&" 終点: "&D$6 -> 始点: (1,0,0) 終点: (0,0,0) | E8: - | F8: ="始点: "&$C8&" 終点: "&F$6 -> 始点: (1,0,0) 終点: (0,1,0) | G8: ="始点: "&$C8&" 終点: "&G$6 -> 始点: (1,0,0) 終点: (0,0,1) | H8: ="始点: "&$C8&" 終点: "&H$6 -> 始点: (1,0,0) 終点: (1,1,0) | I8: ="始点: "&$C8&" 終点: "&I$6 -> 始点: (1,0,0) 終点: (0,1,1) | J8: ="始点: "&$C8&" 終点: "&J$6 -> 始点: (1,0,0) 終点: (1,0,1) | K8: ="始点: "&$C8&" 終点: "&K$6 -> 始点: (1,0,0) 終点: (1,1,1)
C9: (0,1,0) | D9: ="始点: "&$C9&" 終点: "&D$6 -> 始点: (0,1,0) 終点: (0,0,0) | E9: ="始点: "&$C9&" 終点: "&E$6 -> 始点: (0,1,0) 終点: (1,0,0) | F9: - | G9: ="始点: "&$C9&" 終点: "&G$6 -> 始点: (0,1,0) 終点: (0,0,1) | H9: ="始点: "&$C9&" 終点: "&H$6 -> 始点: (0,1,0) 終点: (1,1,0) | I9: ="始点: "&$C9&" 終点: "&I$6 -> 始点: (0,1,0) 終点: (0,1,1) | J9: ="始点: "&$C9&" 終点: "&J$6 -> 始点: (0,1,0) 終点: (1,0,1) | K9: ="始点: "&$C9&" 終点: "&K$6 -> 始点: (0,1,0) 終点: (1,1,1)
C10: (0,0,1) | D10: ="始点: "&$C10&" 終点: "&D$6 -> 始点: (0,0,1) 終点: (0,0,0) | E10: ="始点: "&$C10&" 終点: "&E$6 -> 始点: (0,0,1) 終点: (1,0,0) | F10: ="始点: "&$C10&" 終点: "&F$6 -> 始点: (0,0,1) 終点: (0,1,0) | G10: - | H10: ="始点: "&$C10&" 終点: "&H$6 -> 始点: (0,0,1) 終点: (1,1,0) | I10: ="始点: "&$C10&" 終点: "&I$6 -> 始点: (0,0,1) 終点: (0,1,1) | J10: ="始点: "&$C10&" 終点: "&J$6 -> 始点: (0,0,1) 終点: (1,0,1) | K10: ="始点: "&$C10&" 終点: "&K$6 -> 始点: (0,0,1) 終点: (1,1,1)
C11: (1,1,0) | D11: ="始点: "&$C11&" 終点: "&D$6 -> 始点: (1,1,0) 終点: (0,0,0) | E11: ="始点: "&$C11&" 終点: "&E$6 -> 始点: (1,1,0) 終点: (1,0,0) | F11: ="始点: "&$C11&" 終点: "&F$6 -> 始点: (1,1,0) 終点: (0,1,0) | G11: ="始点: "&$C11&" 終点: "&G$6 -> 始点: (1,1,0) 終点: (0,0,1) | H11: - | I11: ="始点: "&$C11&" 終点: "&I$6 -> 始点: (1,1,0) 終点: (0,1,1) | J11: ="始点: "&$C11&" 終点: "&J$6 -> 始点: (1,1,0) 終点: (1,0,1) | K11: ="始点: "&$C11&" 終点: "&K$6 -> 始点: (1,1,0) 終点: (1,1,1)
C12: (0,1,1) | D12: ="始点: "&$C12&" 終点: "&D$6 -> 始点: (0,1,1) 終点: (0,0,0) | E12: ="始点: "&$C12&" 終点: "&E$6 -> 始点: (0,1,1) 終点: (1,0,0) | F12: ="始点: "&$C12&" 終点: "&F$6 -> 始点: (0,1,1) 終点: (0,1,0) | G12: ="始点: "&$C12&" 終点: "&G$6 -> 始点: (0,1,1) 終点: (0,0,1) | H12: ="始点: "&$C12&" 終点: "&H$6 -> 始点: (0,1,1) 終点: (1,1,0) | I12: - | J12: ="始点: "&$C12&" 終点: "&J$6 -> 始点: (0,1,1) 終点: (1,0,1) | K12: ="始点: "&$C12&" 終点: "&K$6 -> 始点: (0,1,1) 終点: (1,1,1)
C13: (1,0,1) | D13: ="始点: "&$C13&" 終点: "&D$6 -> 始点: (1,0,1) 終点: (0,0,0) | E13: ="始点: "&$C13&" 終点: "&E$6 -> 始点: (1,0,1) 終点: (1,0,0) | F13: ="始点: "&$C13&" 終点: "&F$6 -> 始点: (1,0,1) 終点: (0,1,0) | G13: ="始点: "&$C13&" 終点: "&G$6 -> 始点: (1,0,1) 終点: (0,0,1) | H13: ="始点: "&$C13&" 終点: "&H$6 -> 始点: (1,0,1) 終点: (1,1,0) | I13: ="始点: "&$C13&" 終点: "&I$6 -> 始点: (1,0,1) 終点: (0,1,1) | J13: - | K13: ="始点: "&$C13&" 終点: "&K$6 -> 始点: (1,0,1) 終点: (1,1,1)
C14: (1,1,1) | D14: ="始点: "&$C14&" 終点: "&D$6 -> 始点: (1,1,1) 終点: (0,0,0) | E14: ="始点: "&$C14&" 終点: "&E$6 -> 始点: (1,1,1) 終点: (1,0,0) | F14: ="始点: "&$C14&" 終点: "&F$6 -> 始点: (1,1,1) 終点: (0,1,0) | G14: ="始点: "&$C14&" 終点: "&G$6 -> 始点: (1,1,1) 終点: (0,0,1) | H14: ="始点: "&$C14&" 終点: "&H$6 -> 始点: (1,1,1) 終点: (1,1,0) | I14: ="始点: "&$C14&" 終点: "&I$6 -> 始点: (1,1,1) 終点: (0,1,1) | J14: ="始点: "&$C14&" 終点: "&J$6 -> 始点: (1,1,1) 終点: (1,0,1) | K14: -
B16: ○確認方法
C17: 1) 任意の空間IDから頂点座標を取得し、網羅パターンの組み合わせで始点、終点を選択する。
C18: 点座標 | D18: 頂点取得時の対応
C19: (0,0,0) | D19: GetPointOnExtendedSpatialId("任意の空間ID", enum.Vertex)[0]
C20: (1,0,0) | D20: GetPointOnExtendedSpatialId("任意の空間ID", enum.Vertex)[1]
C21: (0,1,0) | D21: GetPointOnExtendedSpatialId("任意の空間ID", enum.Vertex)[3]
C22: (0,0,1) | D22: GetPointOnExtendedSpatialId("任意の空間ID", enum.Vertex)[4]
C23: (1,1,0) | D23: GetPointOnExtendedSpatialId("任意の空間ID", enum.Vertex)[2]
C24: (0,1,1) | D24: GetPointOnExtendedSpatialId("任意の空間ID", enum.Vertex)[7]
C25: (1,0,1) | D25: GetPointOnExtendedSpatialId("任意の空間ID", enum.Vertex)[5]
C26: (1,1,1) | D26: GetPointOnExtendedSpatialId("任意の空間ID", enum.Vertex)[6]
C28: 2) 線分のAPIから以下の空間IDが返却されることを確認する。
C29: ・始点から取得できる空間IDが返却されていること(※1)
C30: ・終点から取得できる空間IDが返却されていること(※1)
C31: ・始点、終点間の辺が所属する空間IDが返却されていること(※2)
C32: ※1 点がボクセル頂点上の場合
C33: - X成分の場合、X座標が正方向の空間IDが取得できること
C34: "10/10/10/10/10"の(0, Y, Z)頂点の場合："10/10/10/10/10"
C35: "10/10/10/10/10"の(1, Y, Z)頂点の場合："10/11/10/10/10"
C36: - Y成分の場合、Y座標が負方向の空間IDが取得できること
C37: "10/10/10/10/10"の(X, 0, Z)頂点の場合："10/10/11/10/10"
C38: "10/10/10/10/10"の(X, 1, Z)頂点の場合："10/10/10/10/10"
C39: - Z成分の場合、Z座標が正方向の空間IDが取得できること
... C51: -XY成分は、「※1」と同様
B54: 〇試験用データパターン
C55: "【別紙2】線分マトリクスパターン"シートに記載

Sheet 【別紙2】線分マトリクスパターン
A1: ■ 1ボクセルに収まる線分のマトリクス 試験データパターン
C2: 始点・終点として入力する座標は点群API（shape.GetPointOnExtendedSpatialId）を利用して取得する。
C3: テスト用の始点、終点座標取得時、座標群は以下の形式で変数に格納する。
C5: 座標群（引数に指定する空間IDは 10/10/10/10/10 固定とする）
C6: points, _ := GetPointOnExtendedSpatialId("10/10/10/10/10", enum.Vertex)
C8: 線分API（shape.GetSpatialIdsOnLine）呼び出し時に指定する水平、垂直方向精度は以下とする。
C9: 水平、垂直方向精度
C10: 10
C12: 始点、終点として使用する座標は、上記で取得した座標群（配列）から取得する。
C13: 試験項目の各パターンで取得する始点終点について以下に記載する。
C15: No | D15: 始点, 終点 パターン | F15: 始点取得 | K15: 終点取得 | Q15: 期待値※1
C16: 1 | D16: 始点: (0,0,0) 終点: (1,0,0) | F16: points[0] | K16: points[1] | Q16: ['10/11/10/10/10', '10/10/10/10/10']
C17: 2 | D17: 始点: (0,0,0) 終点: (0,1,0) | F17: points[0] | K17: points[3] | Q17: ['10/10/10/10/10', '10/10/11/10/10']
C18: 3 | D18: 始点: (0,0,0) 終点: (0,0,1) | F18: points[0] | K18: points[4] | Q18: ['10/10/10/10/11', '10/10/10/10/10']
C19: 4 | D19: 始点: (0,0,0) 終点: (1,1,0) | F19: points[0] | K19: points[2] | Q19: ['10/11/11/10/10', '10/10/10/10/10']
C20: 5 | D20: 始点: (0,0,0) 終点: (0,1,1) | F20: points[0] | K20: points[7] | Q20: ['10/10/11/10/11', '10/10/10/10/10']
C21: 6 | D21: 始点: (0,0,0) 終点: (1,0,1) | F21: points[0] | K21: points[5] | Q21: ['10/11/10/10/11', '10/10/10/10/10']
C22: 7 | D22: 始点: (0,0,0) 終点: (1,1,1) | F22: points[0] | K22: points[6] | Q22: ['10/11/11/10/11', '10/10/10/10/10']
C23: 8 | D23: 始点: (1,0,0) 終点: (0,1,0) | F23: points[1] | K23: points[3] | Q23: ['10/10/11/10/10', '10/11/10/10/10', '10/10/10/10/10']
C24: 9 | D24: 始点: (1,0,0) 終点: (0,0,1) | F24: points[1] | K24: points[4] | Q24: ['10/11/10/10/10', '10/10/10/10/11', '10/10/10/10/10']
C25: 10 | D25: 始点: (1,0,0) 終点: (1,1,0) | F25: points[1] | K25: points[2] | Q25: ['10/11/11/10/10', '10/11/10/10/10']
C26: 11 | D26: 始点: (1,0,0) 終点: (0,1,1) | F26: points[1] | K26: points[7] | Q26: ['10/11/10/10/10', '10/10/11/10/11', '10/10/10/10/10']
C27: 12 | D27: 始点: (1,0,0) 終点: (1,0,1) | F27: points[1] | K27: points[5] | Q27: ['10/11/10/10/11', '10/11/10/10/10']
... C71: 56 | D71: 始点: (1,1,1) 終点: (1,0,1) | F71: points[6] | K71: points[5] | Q71: ['10/11/10/10/11', '10/11/11/10/11']
C73: ※1 配列に格納された空間IDの順番は不定

Sheet 【別紙3】XYZ方向に長い線分の確認
A1: ■ XYZ方向に長い線分の確認
B3: ○ | C3: 入力値
C4: 始点：空間ID「10/10/10/10/10」の中心点とする。
C5: 終点：空間ID「10/13/15/10/18」の中心点から以下分だけずらした座標とする。
D6: 経度: -0.00001
D7: 緯度: +0.00001
D8: 高さ: -0.00001
C9: 精度：「水平」「垂直」ともに "10"
C11: 始点・終点について、点群APIを使用して取得する際は以下のように取得。
D12: 始点： GetPointOnExtendedSpatialId("10/10/10/10/10", enum.Center)[0]
D14: 終点： p = GetPointOnExtendedSpatialId("10/13/15/10/18", enum.Center)[0]
D15: object.NewPoint(p.Lon() - 0.00001, p.Lat() + 0.00001, p.Alt() -0.00001)
B17: ○ | C17: 各平面で取得されるID成分の期待値
C18: 取得される空間IDの期待値は以下
D19: '10/10/10/10/10'
D20: '10/10/10/10/11'
D21: '10/10/11/10/11'
D22: '10/11/11/10/11'
D23: '10/11/11/10/12'
D24: '10/11/12/10/12'
D25: '10/11/12/10/13'
D26: '10/11/12/10/14'
D27: '10/11/13/10/14'
D28: '10/12/13/10/14'
D29: '10/12/13/10/15'
D30: '10/12/13/10/16'
... D35: '10/13/15/10/18'
C37: ▼図による簡易確認
C38: ・XY平面
C39: Y
R40: X | S40: Y
R41: 10 | S41: 10
C42: 15 | R42: 10 | S42: 11
R43: 11 | S43: 11
C44: 14 | R44: 11 | S44: 12
R45: 11 | S45: 13
C46: 13 | R46: 12 | S46: 13
R47: 12 | S47: 14
C48: 12 | R48: 13 | S48: 14
R49: 13 | S49: 15
...

Sheet 【別紙4】精度入力パターン
A1: ■ 1ボクセルに収まる線分のマトリクス 試験データパターン
C2: 指定可能な全ての精度で空間IDが取得できることを確認する。
C3: 入力するデータおよび期待値を以下に記載する。
C5: No | D5: 始点 | I5: 終点 | N5: 水平/垂直精度 | O5: 期待値※1
C6: 1 | D6: object.NewPoint(0.0, 0.0, 0.0) | I6: object.NewPoint(179.0, 80.0, 100.0) | N6: 0 | O6: ['0/0/0/0/0']
C7: 2 | D7: object.NewPoint(0.0, 0.0, 0.0) | I7: object.NewPoint(179.0, 80.0, 100.0) | N7: 1 | O7: ['1/1/1/1/0', '1/1/0/1/0']
C8: 3 | D8: object.NewPoint(-135.0, 75.7821946114, 4194304.0) | I8: object.NewPoint(45.0, 75.7821946114, 4194304.0) | N8: 2 | O8: ['2/2/0/2/0', '2/0/0/2/0', '2/1/0/2/0']
C9: 4 | D9: object.NewPoint(-157.5, 82.1112317102, 2097152.0) | I9: object.NewPoint(-67.5, 82.1112317102, 2097152.0) | N9: 3 | O9: ['3/1/0/3/0', '3/2/0/3/0', '3/0/0/3/0']
C10: 5 | D10: object.NewPoint(-168.75, 83.863706879, 1048576.0) | I10: object.NewPoint(-123.75, 83.863706879, 1048576.0) | N10: 4 | O10: ['4/1/0/4/0', '4/2/0/4/0', '4/0/0/4/0']
C11: 6 | D11: object.NewPoint(-174.375, 84.5151941393, 524288.0) | I11: object.NewPoint(-151.875, 84.5151941393, 524288.0) | N11: 5 | O11: ['5/0/0/5/0', '5/2/0/5/0', '5/1/0/5/0']
C12: 7 | D12: object.NewPoint(-177.1875, 84.7962449264, 262144.0) | I12: object.NewPoint(-165.9375, 84.7962449264, 262144.0) | N12: 6 | O12: ['6/1/0/6/0', '6/2/0/6/0', '6/0/0/6/0']
C13: 8 | D13: object.NewPoint(-178.59375, 84.926801252, 131072.0) | I13: object.NewPoint(-172.96875, 84.926801252, 131072.0) | N13: 7 | O13: ['7/1/0/7/0', '7/2/0/7/0', '7/0/0/7/0']
C14: 9 | D14: object.NewPoint(-179.296875, 84.9897248546, 65536.0) | I14: object.NewPoint(-176.484375, 84.9897248546, 65536.0) | N14: 8 | O14: ['8/0/0/8/0', '8/1/0/8/0', '8/2/0/8/0']
C15: 10 | D15: object.NewPoint(-179.6484375, 85.02061448, 32768.0) | I15: object.NewPoint(-178.2421875, 85.02061448, 32768.0) | N15: 9 | O15: ['9/2/0/9/0', '9/1/0/9/0', '9/0/0/9/0']
C16: 11 | D16: object.NewPoint(-179.82421875, 85.0359182614, 16384.0) | I16: object.NewPoint(-179.12109375, 85.0359182614, 16384.0) | N16: 10 | O16: ['10/2/0/10/0', '10/1/0/10/0', '10/0/0/10/0']
C17: 12 | D17: object.NewPoint(-179.912109375, 85.0435351431, 8192.0) | I17: object.NewPoint(-179.560546875, 85.0435351431, 8192.0) | N17: 11 | O17: ['11/2/0/11/0', '11/1/0/11/0', '11/0/0/11/0']
... C41: 36 | D41: object.NewPoint(-179.9999999947613, 85.0511287793, 0.00048828125) | I41: object.NewPoint(-179.99999997380655, 85.0511287793, 0.00048828125) | N41: 35 | O41: ['35/0/0/35/0', '35/1/0/35/0', '35/2/0/35/0']
C43: ※1 配列に格納された空間IDの順番は不定
