Workbook
Name Level2ManDays: 変更履歴!Level2ManDays
Name Level2ManDays: [0]!Level2ManDays

Sheet 表紙
AB1: 点群
B7: ="空間ID開発(GO言語版) "&AB1 -> 空間ID開発(GO言語版) 点群
B17: 結合試験項目書
B20: =CONCATENATE(TEXT(MAX(変更履歴!C3:C7),"0.00"), "版") -> 1.00版
B23: 44883

Sheet 変更履歴
B2: 日時 | C2: 版 | D2: 変更箇所 | E2: 作業者 | F2: 変更内容
B3: 44883 | C3: 1 | D3: 全ページ | E3: α | F3: 新規改定

Sheet 集計
A1: 集計
B2: 試験シート | C2: 全項目数 | D2: 実施済み | E2: 未実施
B3: 1.結合試験 | C3: =VLOOKUP(B3,$B$8:$D$11,3,FALSE) -> 83 | D3: {=COUNTIF(INDIRECT(B3&"!$K$3:$K$1024"),"OK")-SUMPRODUCT((OFFSET(INDIRECT(B3&"!$K$3:$K$1024"),,)="OK")*(OFFSET(INDIRECT(B3&"!$M$3:$M$1024"),,)<>""))} -> 83 | E3: =C3-D3 -> 0
B4: 計 | C4: =SUM(C3:C3) -> 83 | D4: =SUM(D3:D3) -> 83 | E4: =SUM(E3:E3) -> 0
B6: 試験項目数内訳
B8: 1.結合試験 | C8: 全項目数 | D8: =SUM(D9:D11) -> 83
C9: 正常 | D9: {=COUNTIF(INDIRECT(B8&"!$E$3:$E$1024"),C9)-SUMPRODUCT((OFFSET(INDIRECT(B8&"!$E$3:$E$1024"),,)=C9)*(OFFSET(INDIRECT(B8&"!$M$3:$M$1024"),,)<>""))} -> 40
C10: 準正常 | D10: {=COUNTIF(INDIRECT(B8&"!$E$3:$E$1024"),C10)-SUMPRODUCT((OFFSET(INDIRECT(B8&"!$E$3:$E$1024"),,)=C10)*(OFFSET(INDIRECT(B8&"!$M$3:$M$1024"),,)<>""))} -> 43
C11: 異常 | D11: {=COUNTIF(INDIRECT(B8&"!$E$3:$E$1024"),C11)-SUMPRODUCT((OFFSET(INDIRECT(B8&"!$E$3:$E$1024"),,)=C11)*(OFFSET(INDIRECT(B8&"!$M$3:$M$1024"),,)<>""))} -> 0

Sheet 1.結合試験
A1: =MID(CELL("filename",$A$1),FIND("]",CELL("filename",$A$1))+3,31) -> 結合試験 | K1: OK, NG | R1: シート番号 | S1: =VALUE(MID(CELL("filename",$A$1),FIND("]",CELL("filename",$A$1))+1,2)) -> 1
A2: No | B2: 大項目 | C2: 中項目 | D2: 小項目 | E2: 試験種別 | F2: 優先度 | G2: 確認手順 | H2: 確認内容 | I2: 試験日 | J2: 試験者 | K2: 試験結果 | L2: 備考 | M2: 重複項目 | R2: 大番号 | S2: 中番号 | T2: 小番号
A3: =IF(B3<>"",表紙!$AB$1&"-"&"結合-"&TEXT($S$1,"00")&"-"&TEXT(R3,"00")&"-"&TEXT(S3,"00")&"-"&TEXT(T3,"０00"),"") -> 点群-結合-01-01-01-001 | B3: 指定範囲の拡張空間ID変換 (点群) | C3: 範囲外の経度緯度を入力する | D3: 経度：180.1 | E3: 準正常 | G3: 1. 引数に以下を指定して、object.NewPointを呼び出す。 lon(経度): 180.1 lat(緯度): 正常な任意の値 alt(高さ): 正常な任意の値 | H3: ・以下のspatialIdErrorが返却されること - エラーコード：InputValueError - エラーメッセージ：入力チェックエラー | I3: 44889 | J3: 宮原 | K3: OK | R3: =IF(ROW()<>3,IF(B2<>B3,#REF!+1,#REF!),1) -> 1 | S3: =IF(B2=B3,IF(C2<>C3,#REF!+1,#REF!),1) -> 1 | T3: =IF(B2<>B3,1,IF(C2=C3,#REF!+1,1)) -> 1
A4: =IF(B4<>"",表紙!$AB$1&"-"&"結合-"&TEXT($S$1,"00")&"-"&TEXT(R4,"00")&"-"&TEXT(S4,"00")&"-"&TEXT(T4,"０00"),"") -> 点群-結合-01-01-01-002 | B4: 指定範囲の拡張空間ID変換 (点群) | C4: 範囲外の経度緯度を入力する | D4: 経度：-180.1 | E4: 準正常 | G4: 1. 引数に以下を指定して、object.NewPointを呼び出す。 lon(経度): -180.1 lat(緯度): 正常な任意の値 alt(高さ): 正常な任意の値 | H4: ・以下のspatialIdErrorが返却されること - エラーコード：InputValueError - エラーメッセージ：入力チェックエラー | I4: 44889 | J4: 宮原 | K4: OK | R4: =IF(ROW()<>3,IF(B3<>B4,R3+1,R3),1) -> 1 | S4: =IF(B3=B4,IF(C3<>C4,S3+1,S3),1) -> 1 | T4: =IF(B3<>B4,1,IF(C3=C4,T3+1,1)) -> 2
A5: =IF(B5<>"",表紙!$AB$1&"-"&"結合-"&TEXT($S$1,"00")&"-"&TEXT(R5,"00")&"-"&TEXT(S5,"00")&"-"&TEXT(T5,"０00"),"") -> 点群-結合-01-01-01-003 | B5: 指定範囲の拡張空間ID変換 (点群) | C5: 範囲外の経度緯度を入力する | D5: 緯度：85.0511287799 | E5: 準正常 | G5: 1. 引数に以下を指定して、object.NewPointを呼び出す。 lon(経度): 正常な任意の値 lat(緯度): 85.0511287799 alt(高さ): 正常な任意の値 | H5: ・以下のspatialIdErrorが返却されること - エラーコード：InputValueError - エラーメッセージ：入力チェックエラー | I5: 44889 | J5: 宮原 | K5: OK | R5: =IF(ROW()<>3,IF(B4<>B5,R4+1,R4),1) -> 1 | S5: =IF(B4=B5,IF(C4<>C5,S4+1,S4),1) -> 1 | T5: =IF(B4<>B5,1,IF(C4=C5,T4+1,1)) -> 3
A6: =IF(B6<>"",表紙!$AB$1&"-"&"結合-"&TEXT($S$1,"00")&"-"&TEXT(R6,"00")&"-"&TEXT(S6,"00")&"-"&TEXT(T6,"０00"),"") -> 点群-結合-01-01-01-004 | B6: 指定範囲の拡張空間ID変換 (点群) | C6: 範囲外の経度緯度を入力する | D6: 緯度：-85.0511287799 | E6: 準正常 | G6: 1. 引数に以下を指定して、object.NewPointを呼び出す。 lon(経度): 正常な任意の値 lat(緯度): -85.0511287799 alt(高さ): 正常な任意の値 | H6: ・以下のspatialIdErrorが返却されること - エラーコード：InputValueError - エラーメッセージ：入力チェックエラー | I6: 44889 | J6: 宮原 | K6: OK | R6: =IF(ROW()<>3,IF(B5<>B6,R5+1,R5),1) -> 1 | S6: =IF(B5=B6,IF(C5<>C6,S5+1,S5),1) -> 1 | T6: =IF(B5<>B6,1,IF(C5=C6,T5+1,1)) -> 4
A7: =IF(B7<>"",表紙!$AB$1&"-"&"結合-"&TEXT($S$1,"00")&"-"&TEXT(R7,"00")&"-"&TEXT(S7,"00")&"-"&TEXT(T7,"０00"),"") -> 点群-結合-01-01-01-005 | B7: 指定範囲の拡張空間ID変換 (点群) | C7: 範囲外の経度緯度を入力する | D7: 緯度：85.05112877991 | E7: 準正常 | G7: 1. 引数に以下を指定して、object.NewPointを呼び出す。 lon(経度): 正常な任意の値 lat(緯度): 85.05112877991 alt(高さ): 正常な任意の値 | H7: ・以下のspatialIdErrorが返却されること - エラーコード：InputValueError - エラーメッセージ：入力チェックエラー | I7: 44889 | J7: 宮原 | K7: OK | R7: =IF(ROW()<>3,IF(B6<>B7,R6+1,R6),1) -> 1 | S7: =IF(B6=B7,IF(C6<>C7,S6+1,S6),1) -> 1 | T7: =IF(B6<>B7,1,IF(C6=C7,T6+1,1)) -> 5
A8: =IF(B8<>"",表紙!$AB$1&"-"&"結合-"&TEXT($S$1,"00")&"-"&TEXT(R8,"00")&"-"&TEXT(S8,"00")&"-"&TEXT(T8,"０00"),"") -> 点群-結合-01-01-01-006 | B8: 指定範囲の拡張空間ID変換 (点群) | C8: 範囲外の経度緯度を入力する | D8: 緯度：-85.05112877991 | E8: 準正常 | G8: 1. 引数に以下を指定して、object.NewPointを呼び出す。 lon(経度): 正常な任意の値 lat(緯度): -85.05112877991 alt(高さ): 正常な任意の値 | H8: ・以下のspatialIdErrorが返却されること - エラーコード：InputValueError - エラーメッセージ：入力チェックエラー | I8: 44889 | J8: 宮原 | K8: OK | R8: =IF(ROW()<>3,IF(B7<>B8,R7+1,R7),1) -> 1 | S8: =IF(B7=B8,IF(C7<>C8,S7+1,S7),1) -> 1 | T8: =IF(B7<>B8,1,IF(C7=C8,T7+1,1)) -> 6
A9: =IF(B9<>"",表紙!$AB$1&"-"&"結合-"&TEXT($S$1,"00")&"-"&TEXT(R9,"00")&"-"&TEXT(S9,"00")&"-"&TEXT(T9,"０00"),"") -> 点群-結合-01-01-02-001 | B9: 指定範囲の拡張空間ID変換 (点群) | C9: 精度閾値を超過した値を入力する | D9: 水平精度：36 | E9: 準正常 | G9: 1. 引数に以下を指定して、shape.GetExtendedSpatialIdsOnPointsを呼び出す。 地理座標リスト: 正常な任意の値 水平精度: 36 垂直精度: 正常な任意の値 | H9: ・以下のspatialIdErrorが返却されること - エラーコード：InputValueError - エラーメッセージ：入力チェックエラー | I9: 44889 | J9: 宮原 | K9: OK | R9: =IF(ROW()<>3,IF(B8<>B9,R8+1,R8),1) -> 1 | S9: =IF(B8=B9,IF(C8<>C9,S8+1,S8),1) -> 2 | T9: =IF(B8<>B9,1,IF(C8=C9,T8+1,1)) -> 1
A10: =IF(B10<>"",表紙!$AB$1&"-"&"結合-"&TEXT($S$1,"00")&"-"&TEXT(R10,"00")&"-"&TEXT(S10,"00")&"-"&TEXT(T10,"０00"),"") -> 点群-結合-01-01-02-002 | B10: 指定範囲の拡張空間ID変換 (点群) | C10: 精度閾値を超過した値を入力する | D10: 水平精度：-1 | E10: 準正常 | G10: 1. 引数に以下を指定して、shape.GetExtendedSpatialIdsOnPointsを呼び出す。 地理座標リスト: 正常な任意の値 水平精度: -1 垂直精度: 正常な任意の値 | H10: ・以下のspatialIdErrorが返却されること - エラーコード：InputValueError - エラーメッセージ：入力チェックエラー | I10: 44889 | J10: 宮原 | K10: OK | R10: =IF(ROW()<>3,IF(B9<>B10,R9+1,R9),1) -> 1 | S10: =IF(B9=B10,IF(C9<>C10,S9+1,S9),1) -> 2 | T10: =IF(B9<>B10,1,IF(C9=C10,T9+1,1)) -> 2
A11: =IF(B11<>"",表紙!$AB$1&"-"&"結合-"&TEXT($S$1,"00")&"-"&TEXT(R11,"00")&"-"&TEXT(S11,"00")&"-"&TEXT(T11,"０00"),"") -> 点群-結合-01-01-02-003 | B11: 指定範囲の拡張空間ID変換 (点群) | C11: 精度閾値を超過した値を入力する | D11: 垂直精度：36 | E11: 準正常 | G11: 1. 引数に以下を指定して、shape.GetExtendedSpatialIdsOnPointsを呼び出す。 地理座標リスト: 正常な任意の値 水平精度: 正常な任意の値 垂直精度: 36 | H11: ・以下のspatialIdErrorが返却されること - エラーコード：InputValueError - エラーメッセージ：入力チェックエラー | I11: 44889 | J11: 宮原 | K11: OK | R11: =IF(ROW()<>3,IF(B10<>B11,R10+1,R10),1) -> 1 | S11: =IF(B10=B11,IF(C10<>C11,S10+1,S10),1) -> 2 | T11: =IF(B10<>B11,1,IF(C10=C11,T10+1,1)) -> 3
A12: =IF(B12<>"",表紙!$AB$1&"-"&"結合-"&TEXT($S$1,"00")&"-"&TEXT(R12,"00")&"-"&TEXT(S12,"00")&"-"&TEXT(T12,"０00"),"") -> 点群-結合-01-01-02-004 | B12: 指定範囲の拡張空間ID変換 (点群) | C12: 精度閾値を超過した値を入力する | D12: 垂直精度：-1 | E12: 準正常 | G12: 1. 引数に以下を指定して、shape.GetExtendedSpatialIdsOnPointsを呼び出す。 地理座標リスト: 正常な任意の値 水平精度: 正常な任意の値 垂直精度: -1 | H12: ・以下のspatialIdErrorが返却されること - エラーコード：InputValueError - エラーメッセージ：入力チェックエラー | I12: 44889 | J12: 宮原 | K12: OK | R12: =IF(ROW()<>3,IF(B11<>B12,R11+1,R11),1) -> 1 | S12: =IF(B11=B12,IF(C11<>C12,S11+1,S11),1) -> 2 | T12: =IF(B11<>B12,1,IF(C11=C12,T11+1,1)) -> 4
A13: =IF(B13<>"",表紙!$AB$1&"-"&"結合-"&TEXT($S$1,"00")&"-"&TEXT(R13,"00")&"-"&TEXT(S13,"00")&"-"&TEXT(T13,"０00"),"") -> 点群-結合-01-01-02-005 | B13: 指定範囲の拡張空間ID変換 (点群) | C13: 精度閾値を超過した値を入力する | D13: 水平・垂直精度：36 | E13: 準正常 | G13: 1. 引数に以下を指定して、shape.GetExtendedSpatialIdsOnPointsを呼び出す。 地理座標リスト: 正常な任意の値 水平精度: 36 垂直精度: 36 | H13: ・以下のspatialIdErrorが返却されること - エラーコード：InputValueError - エラーメッセージ：入力チェックエラー | I13: 44889 | J13: 宮原 | K13: OK | R13: =IF(ROW()<>3,IF(B12<>B13,R12+1,R12),1) -> 1 | S13: =IF(B12=B13,IF(C12<>C13,S12+1,S12),1) -> 2 | T13: =IF(B12<>B13,1,IF(C12=C13,T12+1,1)) -> 5
A14: =IF(B14<>"",表紙!$AB$1&"-"&"結合-"&TEXT($S$1,"00")&"-"&TEXT(R14,"00")&"-"&TEXT(S14,"00")&"-"&TEXT(T14,"０00"),"") -> 点群-結合-01-01-02-006 | B14: 指定範囲の拡張空間ID変換 (点群) | C14: 精度閾値を超過した値を入力する | D14: 水平・垂直精度：-1 | E14: 準正常 | G14: 1. 引数に以下を指定して、shape.GetExtendedSpatialIdsOnPointsを呼び出す。 地理座標リスト: 正常な任意の値 水平精度: -1 垂直精度: -1 | H14: ・以下のspatialIdErrorが返却されること - エラーコード：InputValueError - エラーメッセージ：入力チェックエラー | I14: 44889 | J14: 宮原 | K14: OK | R14: =IF(ROW()<>3,IF(B13<>B14,R13+1,R13),1) -> 1 | S14: =IF(B13=B14,IF(C13<>C14,S13+1,S13),1) -> 2 | T14: =IF(B13<>B14,1,IF(C13=C14,T13+1,1)) -> 6
A15: =IF(B15<>"",表紙!$AB$1&"-"&"結合-"&TEXT($S$1,"00")&"-"&TEXT(R15,"00")&"-"&TEXT(S15,"00")&"-"&TEXT(T15,"０00"),"") -> 点群-結合-01-01-03-001 | B15: 指定範囲の拡張空間ID変換 (点群) | C15: 座標にnilを入力する | D15: - | E15: 準正常 | G15: 1. 引数に以下を指定して、shape.GetExtendedSpatialIdsOnPointsを呼び出す。 地理座標リスト: nil 水平精度: 正常な任意の値 垂直精度: 正常な任意の値 | H15: ・以下のspatialIdErrorが返却されること - エラーコード：InputValueError - エラーメッセージ：入力チェックエラー | I15: 44890 | J15: 宮原 | K15: OK | R15: =IF(ROW()<>3,IF(B14<>B15,R14+1,R14),1) -> 1 | S15: =IF(B14=B15,IF(C14<>C15,S14+1,S14),1) -> 3 | T15: =IF(B14<>B15,1,IF(C14=C15,T14+1,1)) -> 1
... A22: =IF(B22<>"",表紙!$AB$1&"-"&"結合-"&TEXT($S$1,"00")&"-"&TEXT(R22,"00")&"-"&TEXT(S22,"00")&"-"&TEXT(T22,"０00"),"") -> 点群-結合-01-01-05-001 | B22: 指定範囲の拡張空間ID変換 (点群) | C22: 精度を変えても拡張空間IDが取得できる | D22: 水平精度：0 ～ 35 | E22: 正常 | G22: 1. 引数に以下を指定して、shape.GetExtendedSpatialIdsOnPointsを呼び出す。 "【別紙2】精度入力パターン"シート"◆指定範囲の拡張空間ID変換 (点群)"の「座標」、「精度」 ※0～35 全ての精度の結果を確認すること。 | H22: ・入力した座標パターンに対応した期待値が取得できること ・エラーインスタンスが返却されていないこと | I22: 44889 | J22: 宮原 | K22: OK | R22: =IF(ROW()<>3,IF(B21<>B22,R21+1,R21),1) -> 1 | S22: =IF(B21=B22,IF(C21<>C22,S21+1,S21),1) -> 5 | T22: =IF(B21<>B22,1,IF(C21=C22,T21+1,1)) -> 1
A23: =IF(B23<>"",表紙!$AB$1&"-"&"結合-"&TEXT($S$1,"00")&"-"&TEXT(R23,"00")&"-"&TEXT(S23,"00")&"-"&TEXT(T23,"０00"),"") -> 点群-結合-01-01-05-002 | B23: 指定範囲の拡張空間ID変換 (点群) | C23: 精度を変えても拡張空間IDが取得できる | D23: 垂直精度：0 ～ 35 | E23: 正常 | M23: =$A$22 -> 点群-結合-01-01-05-001 | R23: =IF(ROW()<>3,IF(B22<>B23,R22+1,R22),1) -> 1 | S23: =IF(B22=B23,IF(C22<>C23,S22+1,S22),1) -> 5 | T23: =IF(B22<>B23,1,IF(C22=C23,T22+1,1)) -> 2
A24: =IF(B24<>"",表紙!$AB$1&"-"&"結合-"&TEXT($S$1,"00")&"-"&TEXT(R24,"00")&"-"&TEXT(S24,"00")&"-"&TEXT(T24,"０00"),"") -> 点群-結合-01-01-06-001 | B24: 指定範囲の拡張空間ID変換 (点群) | C24: 「拡張空間IDから座標への変換」で取得した中心座標を入力する | D24: - | E24: 正常 | G24: 1. 引数に以下を指定して、shape.GetPointOnExtendedSpatialIdを呼び出す。 空間ID：正常な任意の値 オプション：common.enum.Center 2. 引数に以下を指定して、shape.GetExtendedSpatialIdsOnPointsを呼び出す。 地理座標リスト: 手順1で取得した地理座標 水平精度: 手順1で入力した空間IDの水平精度 垂直精度: 手順1で入力した空間IDの垂直精度 | H24: ・手順2実行で取得される空間IDが、手順1で入力したIDと同じであること ・エラーインスタンスが返却されていないこと | I24: 44889 | J24: 宮原 | K24: OK | R24: =IF(ROW()<>3,IF(B23<>B24,R23+1,R23),1) -> 1 | S24: =IF(B23=B24,IF(C23<>C24,S23+1,S23),1) -> 6 | T24: =IF(B23<>B24,1,IF(C23=C24,T23+1,1)) -> 1
A25: =IF(B25<>"",表紙!$AB$1&"-"&"結合-"&TEXT($S$1,"00")&"-"&TEXT(R25,"00")&"-"&TEXT(S25,"00")&"-"&TEXT(T25,"０00"),"") -> 点群-結合-01-01-07-001 | B25: 指定範囲の拡張空間ID変換 (点群) | C25: 「拡張空間IDから座標への変換」で取得した頂点座標を入力する | D25: - | E25: 正常 | G25: 1. 引数に以下を指定して、shape.GetPointOnExtendedSpatialIdを呼び出す。 空間ID：正常な任意の値 オプション：common.enum.Vertex 2. 引数に以下を指定して、shape.GetExtendedSpatialIdsOnPointsを呼び出す。 地理座標リスト: 手順1で取得した地理座標8つ 水平精度: 手順1で入力した空間IDの水平精度 垂直精度: 手順1で入力した空間IDの垂直精度 | H25: ・"【別紙3】相互変換"シート"◆指定範囲の拡張空間ID変換 (点群)"に記載されている、頂点座標のと変換後の空間IDの対応表と同様の結果が取得できること ・エラーインスタンスが返却されていないこと。 | I25: 44889 | J25: 宮原 | K25: OK | R25: =IF(ROW()<>3,IF(B24<>B25,R24+1,R24),1) -> 1 | S25: =IF(B24=B25,IF(C24<>C25,S24+1,S24),1) -> 7 | T25: =IF(B24<>B25,1,IF(C24=C25,T24+1,1)) -> 1
A26: =IF(B26<>"",表紙!$AB$1&"-"&"結合-"&TEXT($S$1,"00")&"-"&TEXT(R26,"00")&"-"&TEXT(S26,"00")&"-"&TEXT(T26,"０00"),"") -> 点群-結合-01-01-08-001 | B26: 指定範囲の拡張空間ID変換 (点群) | C26: 経度、緯度に境界値を入力する | D26: 経度：180.0 | E26: 正常 | G26: 1. 引数に以下を指定して、shape.GetExtendedSpatialIdsOnPointsを呼び出す。 "【別紙1】座標入力パターン"シートのNo.2-1の「座標」「精度」 | H26: ・入力した座標パターンに対応した期待値が取得できること ・エラーインスタンスが返却されていないこと | I26: 44889 | J26: 宮原 | K26: OK | R26: =IF(ROW()<>3,IF(B25<>B26,R25+1,R25),1) -> 1 | S26: =IF(B25=B26,IF(C25<>C26,S25+1,S25),1) -> 8 | T26: =IF(B25<>B26,1,IF(C25=C26,T25+1,1)) -> 1
A27: =IF(B27<>"",表紙!$AB$1&"-"&"結合-"&TEXT($S$1,"00")&"-"&TEXT(R27,"00")&"-"&TEXT(S27,"00")&"-"&TEXT(T27,"０00"),"") -> 点群-結合-01-01-08-002 | B27: 指定範囲の拡張空間ID変換 (点群) | C27: 経度、緯度に境界値を入力する | D27: 経度：-180.0 | E27: 正常 | G27: 1. 引数に以下を指定して、shape.GetExtendedSpatialIdsOnPointsを呼び出す。 "【別紙1】座標入力パターン"シートのNo.2-2の「座標」「精度」 | H27: ・入力した座標パターンに対応した期待値が取得できること ・エラーインスタンスが返却されていないこと | I27: 44889 | J27: 宮原 | K27: OK | R27: =IF(ROW()<>3,IF(B26<>B27,R26+1,R26),1) -> 1 | S27: =IF(B26=B27,IF(C26<>C27,S26+1,S26),1) -> 8 | T27: =IF(B26<>B27,1,IF(C26=C27,T26+1,1)) -> 2
A28: =IF(B28<>"",表紙!$AB$1&"-"&"結合-"&TEXT($S$1,"00")&"-"&TEXT(R28,"00")&"-"&TEXT(S28,"00")&"-"&TEXT(T28,"０00"),"") -> 点群-結合-01-01-08-003 | B28: 指定範囲の拡張空間ID変換 (点群) | C28: 経度、緯度に境界値を入力する | D28: 緯度：85.0511287798 | E28: 正常 | G28: 1. 引数に以下を指定して、shape.GetExtendedSpatialIdsOnPointsを呼び出す。 "【別紙1】座標入力パターン"シートのNo.2-3の「座標」「精度」 | H28: ・入力した座標パターンに対応した期待値が取得できること ・エラーインスタンスが返却されていないこと | I28: 44889 | J28: 宮原 | K28: OK | R28: =IF(ROW()<>3,IF(B27<>B28,R27+1,R27),1) -> 1 | S28: =IF(B27=B28,IF(C27<>C28,S27+1,S27),1) -> 8 | T28: =IF(B27<>B28,1,IF(C27=C28,T27+1,1)) -> 3
A29: =IF(B29<>"",表紙!$AB$1&"-"&"結合-"&TEXT($S$1,"00")&"-"&TEXT(R29,"00")&"-"&TEXT(S29,"00")&"-"&TEXT(T29,"０00"),"") -> 点群-結合-01-01-08-004 | B29: 指定範囲の拡張空間ID変換 (点群) | C29: 経度、緯度に境界値を入力する | D29: 緯度：-85.0511287798 | E29: 正常 | G29: 1. 引数に以下を指定して、shape.GetExtendedSpatialIdsOnPointsを呼び出す。 "【別紙1】座標入力パターン"シートのNo.2-4の「座標」「精度」 | H29: ・入力した座標パターンに対応した期待値が取得できること ・エラーインスタンスが返却されていないこと | I29: 44889 | J29: 宮原 | K29: OK | R29: =IF(ROW()<>3,IF(B28<>B29,R28+1,R28),1) -> 1 | S29: =IF(B28=B29,IF(C28<>C29,S28+1,S28),1) -> 8 | T29: =IF(B28<>B29,1,IF(C28=C29,T28+1,1)) -> 4
A30: =IF(B30<>"",表紙!$AB$1&"-"&"結合-"&TEXT($S$1,"00")&"-"&TEXT(R30,"00")&"-"&TEXT(S30,"00")&"-"&TEXT(T30,"０00"),"") -> 点群-結合-01-01-08-005 | B30: 指定範囲の拡張空間ID変換 (点群) | C30: 経度、緯度に境界値を入力する | D30: 緯度、経度境界値 | E30: 正常 | G30: 1. 引数に以下を指定して、shape.GetExtendedSpatialIdsOnPointsを呼び出す。 "【別紙1】座標入力パターン"シートのNo.2-5, No.2-6の「座標」「精度」 | H30: ・入力した座標パターンに対応した期待値が取得できること ・エラーインスタンスが返却されていないこと | I30: 44889 | J30: 宮原 | K30: OK | R30: =IF(ROW()<>3,IF(B29<>B30,R29+1,R29),1) -> 1 | S30: =IF(B29=B30,IF(C29<>C30,S29+1,S29),1) -> 8 | T30: =IF(B29<>B30,1,IF(C29=C30,T29+1,1)) -> 5
A31: =IF(B31<>"",表紙!$AB$1&"-"&"結合-"&TEXT($S$1,"00")&"-"&TEXT(R31,"00")&"-"&TEXT(S31,"00")&"-"&TEXT(T31,"０00"),"") -> 点群-結合-01-01-09-001 | B31: 指定範囲の拡張空間ID変換 (点群) | C31: 経度、緯度、高さに0を入力する | D31: 経度：0 | E31: 正常 | M31: =$A$21 -> 点群-結合-01-01-04-006 | R31: =IF(ROW()<>3,IF(B30<>B31,R30+1,R30),1) -> 1 | S31: =IF(B30=B31,IF(C30<>C31,S30+1,S30),1) -> 9 | T31: =IF(B30<>B31,1,IF(C30=C31,T30+1,1)) -> 1
A32: =IF(B32<>"",表紙!$AB$1&"-"&"結合-"&TEXT($S$1,"00")&"-"&TEXT(R32,"00")&"-"&TEXT(S32,"00")&"-"&TEXT(T32,"０00"),"") -> 点群-結合-01-01-09-002 | B32: 指定範囲の拡張空間ID変換 (点群) | C32: 経度、緯度、高さに0を入力する | D32: 緯度：0 | E32: 正常 | M32: =$A$21 -> 点群-結合-01-01-04-006 | R32: =IF(ROW()<>3,IF(B31<>B32,R31+1,R31),1) -> 1 | S32: =IF(B31=B32,IF(C31<>C32,S31+1,S31),1) -> 9 | T32: =IF(B31<>B32,1,IF(C31=C32,T31+1,1)) -> 2
A33: =IF(B33<>"",表紙!$AB$1&"-"&"結合-"&TEXT($S$1,"00")&"-"&TEXT(R33,"00")&"-"&TEXT(S33,"00")&"-"&TEXT(T33,"０00"),"") -> 点群-結合-01-01-09-003 | B33: 指定範囲の拡張空間ID変換 (点群) | C33: 経度、緯度、高さに0を入力する | D33: 高さ：0 | E33: 正常 | G33: 1. 引数に以下を指定して、shape.GetExtendedSpatialIdsOnPointsを呼び出す。 "【別紙1】座標入力パターン"シートのNo.3-3の「座標」「精度」 | H33: ・入力した座標パターンに対応した期待値が取得できること ・エラーインスタンスが返却されていないこと | I33: 44889 | J33: 宮原 | K33: OK | R33: =IF(ROW()<>3,IF(B32<>B33,R32+1,R32),1) -> 1 | S33: =IF(B32=B33,IF(C32<>C33,S32+1,S32),1) -> 9 | T33: =IF(B32<>B33,1,IF(C32=C33,T32+1,1)) -> 3
A34: =IF(B34<>"",表紙!$AB$1&"-"&"結合-"&TEXT($S$1,"00")&"-"&TEXT(R34,"00")&"-"&TEXT(S34,"00")&"-"&TEXT(T34,"０00"),"") -> 点群-結合-01-01-09-004 | B34: 指定範囲の拡張空間ID変換 (点群) | C34: 経度、緯度、高さに0を入力する | D34: 経度、緯度、高さ：0 | E34: 正常 | G34: 1. 引数に以下を指定して、shape.GetExtendedSpatialIdsOnPointsを呼び出す。 "【別紙1】座標入力パターン"シートのNo.3-4の「座標」「精度」 | H34: ・入力した座標パターンに対応した期待値が取得できること ・エラーインスタンスが返却されていないこと | I34: 44889 | J34: 宮原 | K34: OK | R34: =IF(ROW()<>3,IF(B33<>B34,R33+1,R33),1) -> 1 | S34: =IF(B33=B34,IF(C33<>C34,S33+1,S33),1) -> 9 | T34: =IF(B33<>B34,1,IF(C33=C34,T33+1,1)) -> 4
A35: =IF(B35<>"",表紙!$AB$1&"-"&"結合-"&TEXT($S$1,"00")&"-"&TEXT(R35,"00")&"-"&TEXT(S35,"00")&"-"&TEXT(T35,"０00"),"") -> 点群-結合-01-01-10-001 | B35: 指定範囲の拡張空間ID変換 (点群) | C35: 緯度に小数点の桁数11桁以上の値を入力する | D35: 正の値 | E35: 正常 | G35: 1. 引数に以下を指定して、shape.GetExtendedSpatialIdsOnPointsを呼び出す。 "【別紙1】座標入力パターン"シートのNo.4-1の「座標」「精度」 | H35: ・入力した座標パターンに対応した期待値が取得できること ・エラーインスタンスが返却されていないこと | I35: 44889 | J35: 宮原 | K35: OK | R35: =IF(ROW()<>3,IF(B34<>B35,R34+1,R34),1) -> 1 | S35: =IF(B34=B35,IF(C34<>C35,S34+1,S34),1) -> 10 | T35: =IF(B34<>B35,1,IF(C34=C35,T34+1,1)) -> 1
A36: =IF(B36<>"",表紙!$AB$1&"-"&"結合-"&TEXT($S$1,"00")&"-"&TEXT(R36,"00")&"-"&TEXT(S36,"00")&"-"&TEXT(T36,"０00"),"") -> 点群-結合-01-01-10-002 | B36: 指定範囲の拡張空間ID変換 (点群) | C36: 緯度に小数点の桁数11桁以上の値を入力する | D36: 負の値 | E36: 正常 | G36: 1. 引数に以下を指定して、shape.GetExtendedSpatialIdsOnPointsを呼び出す。 "【別紙1】座標入力パターン"シートのNo.4-2の「座標」「精度」 | H36: ・入力した座標パターンに対応した期待値が取得できること ・エラーインスタンスが返却されていないこと | I36: 44889 | J36: 宮原 | K36: OK | R36: =IF(ROW()<>3,IF(B35<>B36,R35+1,R35),1) -> 1 | S36: =IF(B35=B36,IF(C35<>C36,S35+1,S35),1) -> 10 | T36: =IF(B35<>B36,1,IF(C35=C36,T35+1,1)) -> 2
A37: =IF(B37<>"",表紙!$AB$1&"-"&"結合-"&TEXT($S$1,"00")&"-"&TEXT(R37,"00")&"-"&TEXT(S37,"00")&"-"&TEXT(T37,"０00"),"") -> 点群-結合-01-01-11-001 | B37: 指定範囲の拡張空間ID変換 (点群) | C37: 緯度に小数点の桁数10桁の値を入力する | D37: 正の値 | E37: 正常 | M37: =$A$28 -> 点群-結合-01-01-08-003 | R37: =IF(ROW()<>3,IF(B36<>B37,R36+1,R36),1) -> 1 | S37: =IF(B36=B37,IF(C36<>C37,S36+1,S36),1) -> 11 | T37: =IF(B36<>B37,1,IF(C36=C37,T36+1,1)) -> 1
A38: =IF(B38<>"",表紙!$AB$1&"-"&"結合-"&TEXT($S$1,"00")&"-"&TEXT(R38,"00")&"-"&TEXT(S38,"00")&"-"&TEXT(T38,"０00"),"") -> 点群-結合-01-01-11-002 | B38: 指定範囲の拡張空間ID変換 (点群) | C38: 緯度に小数点の桁数10桁の値を入力する | D38: 負の値 | E38: 正常 | M38: =$A$29 -> 点群-結合-01-01-08-004 | R38: =IF(ROW()<>3,IF(B37<>B38,R37+1,R37),1) -> 1 | S38: =IF(B37=B38,IF(C37<>C38,S37+1,S37),1) -> 11 | T38: =IF(B37<>B38,1,IF(C37=C38,T37+1,1)) -> 2
A39: =IF(B39<>"",表紙!$AB$1&"-"&"結合-"&TEXT($S$1,"00")&"-"&TEXT(R39,"00")&"-"&TEXT(S39,"00")&"-"&TEXT(T39,"０00"),"") -> 点群-結合-01-01-12-001 | B39: 指定範囲の拡張空間ID変換 (点群) | C39: 高さに負の値を入力する | D39: - | E39: 正常 | G39: 1. 引数に以下を指定して、shape.GetExtendedSpatialIdsOnPointsを呼び出す。 "【別紙1】座標入力パターン"シートのNo.5-1の「座標」「精度」 | H39: ・入力した座標パターンに対応した期待値が取得できること ・エラーインスタンスが返却されていないこと | I39: 44889 | J39: 宮原 | K39: OK | R39: =IF(ROW()<>3,IF(B38<>B39,R38+1,R38),1) -> 1 | S39: =IF(B38=B39,IF(C38<>C39,S38+1,S38),1) -> 12 | T39: =IF(B38<>B39,1,IF(C38=C39,T38+1,1)) -> 1
A40: =IF(B40<>"",表紙!$AB$1&"-"&"結合-"&TEXT($S$1,"00")&"-"&TEXT(R40,"00")&"-"&TEXT(S40,"00")&"-"&TEXT(T40,"０00"),"") -> 点群-結合-01-01-13-001 | B40: 指定範囲の拡張空間ID変換 (点群) | C40: 同じ拡張空間IDに変換される座標を複数入力 | D40: - | E40: 正常 | G40: 1. 引数に以下を指定して、shape.GetExtendedSpatialIdsOnPointsを呼び出す。 "【別紙1】座標入力パターン"シートのNo.6-1の「座標」「精度」 | H40: ・入力した座標パターンに対応した期待値が取得できること ・エラーインスタンスが返却されていないこと | I40: 44889 | J40: 宮原 | K40: OK | R40: =IF(ROW()<>3,IF(B39<>B40,R39+1,R39),1) -> 1 | S40: =IF(B39=B40,IF(C39<>C40,S39+1,S39),1) -> 13 | T40: =IF(B39<>B40,1,IF(C39=C40,T39+1,1)) -> 1
A41: =IF(B41<>"",表紙!$AB$1&"-"&"結合-"&TEXT($S$1,"00")&"-"&TEXT(R41,"00")&"-"&TEXT(S41,"00")&"-"&TEXT(T41,"０00"),"") -> 点群-結合-01-01-14-001 | B41: 指定範囲の拡張空間ID変換 (点群) | C41: Python版の「指定範囲の空間ID変換 (点群)」と同一の結果が取得できる | D41: - | E41: 正常 | M41: =$A$16 -> 点群-結合-01-01-04-001 | R41: =IF(ROW()<>3,IF(B40<>B41,R40+1,R40),1) -> 1 | S41: =IF(B40=B41,IF(C40<>C41,S40+1,S40),1) -> 14 | T41: =IF(B40<>B41,1,IF(C40=C41,T40+1,1)) -> 1
A42: =IF(B42<>"",表紙!$AB$1&"-"&"結合-"&TEXT($S$1,"00")&"-"&TEXT(R42,"00")&"-"&TEXT(S42,"00")&"-"&TEXT(T42,"０00"),"") -> 点群-結合-01-02-01-001 | B42: 拡張空間IDから座標への変換 | C42: 不正なoptionが入力される | D42: - | E42: 準正常 | G42: 1. 引数に以下を指定して、shape.GetPointOnExtendedSpatialIdを呼び出す。 空間ID：正常な任意の値 option： 10 | H42: ・以下のspatialIdErrorが返却されること - エラーコード：OptionFailedError - エラーメッセージ：オプション値の指定エラー | I42: 44889 | J42: 宮原 | K42: OK | R42: =IF(ROW()<>3,IF(B41<>B42,R41+1,R41),1) -> 2 | S42: =IF(B41=B42,IF(C41<>C42,S41+1,S41),1) -> 1 | T42: =IF(B41<>B42,1,IF(C41=C42,T41+1,1)) -> 1
A43: =IF(B43<>"",表紙!$AB$1&"-"&"結合-"&TEXT($S$1,"00")&"-"&TEXT(R43,"00")&"-"&TEXT(S43,"00")&"-"&TEXT(T43,"０00"),"") -> 点群-結合-01-02-02-001 | B43: 拡張空間IDから座標への変換 | C43: 空の文字列が入力される | D43: - | E43: 準正常 | G43: 1. 引数に以下を指定して、shape.GetPointOnExtendedSpatialIdを呼び出す。 空間ID：空文字 option： common.enum.Center | H43: ・以下のspatialIdErrorが返却されること - エラーコード：InputValueError - エラーメッセージ：入力チェックエラー | I43: 44889 | J43: 宮原 | K43: OK | R43: =IF(ROW()<>3,IF(B42<>B43,R42+1,R42),1) -> 2 | S43: =IF(B42=B43,IF(C42<>C43,S42+1,S42),1) -> 2 | T43: =IF(B42<>B43,1,IF(C42=C43,T42+1,1)) -> 1
A44: =IF(B44<>"",表紙!$AB$1&"-"&"結合-"&TEXT($S$1,"00")&"-"&TEXT(R44,"00")&"-"&TEXT(S44,"00")&"-"&TEXT(T44,"０00"),"") -> 点群-結合-01-02-03-001 | B44: 拡張空間IDから座標への変換 | C44: 拡張空間IDフォーマット不正の拡張空間IDが入力される | D44: 区切り文字不足： 3個以下 | E44: 準正常 | G44: 1. 引数に以下を指定して、shape.GetPointOnExtendedSpatialIdを呼び出す。 空間ID：10/10/10/10 option： common.enum.Center | H44: ・以下のspatialIdErrorが返却されること - エラーコード：InputValueError - エラーメッセージ：入力チェックエラー | I44: 44889 | J44: 宮原 | K44: OK | R44: =IF(ROW()<>3,IF(B43<>B44,R43+1,R43),1) -> 2 | S44: =IF(B43=B44,IF(C43<>C44,S43+1,S43),1) -> 3 | T44: =IF(B43<>B44,1,IF(C43=C44,T43+1,1)) -> 1
A45: =IF(B45<>"",表紙!$AB$1&"-"&"結合-"&TEXT($S$1,"00")&"-"&TEXT(R45,"00")&"-"&TEXT(S45,"00")&"-"&TEXT(T45,"０00"),"") -> 点群-結合-01-02-03-002 | B45: 拡張空間IDから座標への変換 | C45: 拡張空間IDフォーマット不正の拡張空間IDが入力される | D45: 区切り文字過多： 5個以上 | E45: 準正常 | G45: 1. 引数に以下を指定して、shape.GetPointOnExtendedSpatialIdを呼び出す。 空間ID：10/10/10/10/10/10 option： common.enum.Vertex | H45: ・以下のspatialIdErrorが返却されること - エラーコード：InputValueError - エラーメッセージ：入力チェックエラー | I45: 44889 | J45: 宮原 | K45: OK | R45: =IF(ROW()<>3,IF(B44<>B45,R44+1,R44),1) -> 2 | S45: =IF(B44=B45,IF(C44<>C45,S44+1,S44),1) -> 3 | T45: =IF(B44<>B45,1,IF(C44=C45,T44+1,1)) -> 2
A46: =IF(B46<>"",表紙!$AB$1&"-"&"結合-"&TEXT($S$1,"00")&"-"&TEXT(R46,"00")&"-"&TEXT(S46,"00")&"-"&TEXT(T46,"０00"),"") -> 点群-結合-01-02-03-003 | B46: 拡張空間IDから座標への変換 | C46: 拡張空間IDフォーマット不正の拡張空間IDが入力される | D46: 利用不可の文字を含む | E46: 準正常 | G46: 1. 引数に以下を指定して、shape.GetPointOnExtendedSpatialIdを呼び出す。 空間ID：10|10|10|10|10 option： common.enum.Center | H46: ・以下のspatialIdErrorが返却されること - エラーコード：InputValueError - エラーメッセージ：入力チェックエラー | I46: 44889 | J46: 宮原 | K46: OK | R46: =IF(ROW()<>3,IF(B45<>B46,R45+1,R45),1) -> 2 | S46: =IF(B45=B46,IF(C45<>C46,S45+1,S45),1) -> 3 | T46: =IF(B45<>B46,1,IF(C45=C46,T45+1,1)) -> 3
...

Sheet 【別紙1】座標入力パターン
B2: 「指定範囲の拡張空間ID変換 (点群)」 の試験項目にて、点群の空間ID変換を行う際に入力するパラメータと、変換後の空間ID期待値を以下に記載する。
B3: ※期待値についてはPython版の点群APIにて同様の座標、精度を入力して取得した値を記載している。
C5: No | D5: 入力パターン種別 | E5: 座標パターン | F5: 入力座標（経度, 緯度, 高さ） | G5: 入力精度(水平, 垂直) | H5: 期待値
C6: 1-1 | D6: 座標閾値内 | E6: 任意の座標 | F6: (139.753098, 35.685371, 0.0) | G6: (18, 25) | H6: 18/232837/103222/25/0
C7: 1-2 | E7: 北半球西側 | F7: (-21.942400, 64.147209, 100.0) | G7: (9, 25) | H7: 9/224/136/25/100
C8: 1-3 | E8: 南半球 | F8: (-58.373490, -34.608510, -1300.0) | G8: (14, 25) | H8: 14/5535/9872/25/-1300
C9: 1-4 | E9: 地図上の左上 | F9: (-180.0, 85.05112877, -1300.0) | G9: (24, 25) | H9: 24/0/0/25/-1300
C10: 1-5 | E10: 地図上の右下 | F10: (179.99999999, -85.05112877, -1300.0) | G10: (10, 25) | H10: 10/1023/1023/25/-1300
C11: 1-6 | E11: 原点 | F11: (0.0, 0.0, -1300.0) | G11: (9, 25) | H11: 9/256/256/25/-1300
C12: 2-1 | D12: 経度緯度の境界値 | E12: 経度境界値 | F12: (180.0, -35.685371, 1.0) | G12: (10, 35) | H12: 10/0/620/35/1024
C13: 2-2 | F13: (-180.0, 35.685371, -1300.0) | G13: (24, 25) | H13: 24/0/6606261/25/-1300
C14: 2-3 | E14: 緯度境界値 | F14: (139.753098, 85.0511287798, 500.0) | G14: (26, 10) | H14: 26/59606297/0/10/0
C15: 2-4 | F15: (139.753098, -85.0511287798, 500.0) | G15: (26, 10) | H15: 26/59606297/67108863/10/0
C16: 2-5 | E16: 経度緯度境界値 | F16: (180.0, -85.0511287798, 1.0) | G16: (10, 35) | H16: 10/0/1023/35/1024
C17: 2-6 | F17: (-180.0, 85.0511287798, -1300.0) | G17: (24, 25) | H17: 24/0/0/25/-1300
C18: 3-1 | D18: 経度、緯度、高さ 0 | E18: 経度0 | F18: (0.0, 0.0, -1300.0) | G18: (9, 25) | H18: 9/256/256/25/-1300
C19: 3-2 | E19: 緯度0 | F19: (0.0, 0.0, -1300.0) | G19: (9, 25) | H19: 9/256/256/25/-1300
C20: 3-3 | E20: 高さ0 | F20: (139.753098, 35.685371, 0.0) | G20: (26, 26) | H20: 26/59606297/26425045/26/0
C21: 3-4 | E21: 経度, 緯度, 高さ | F21: (0.0, 0.0, 0.0) | G21: (26, 26) | H21: 26/33554432/33554432/26/0
C22: 4-1 | D22: 緯度桁数上限 | E22: 11桁以上 | F22: (-21.942400, 64.14720900001, 100.0) | G22: (9, 25) | H22: 9/224/136/25/100
C23: 4-2 | F23: (-58.373490, -34.60851000001, -1300.0) | G23: (14, 25) | H23: 14/5535/9872/25/-1300
C24: 4-3 | E24: 10桁 | F24: (139.753098, 85.0511287798, 500.0) | G24: (26, 10) | H24: 26/59606297/0/10/0
C25: 4-4 | F25: (139.753098, -85.0511287798, 500.0) | G25: (26, 10) | H25: 26/59606297/67108863/10/0
C26: 5-1 | D26: 高さが負の値 | E26: - | F26: (179.99999999, -85.05112877, -1300.0) | G26: (10, 25) | H26: 10/1023/1023/25/-1300
C27: 6-1 | D27: 変換後空間ID重複する複数の座標 | E27: - | F27: (139.753098, 35.615309, 0.0) (139.753098, 35.615310, 0.0) (139.753098, 35.615311, 0.0) (139.753098, 35.615312, 0.0) (139.753098, 35.615313, 0.0) (139.753098, 35.615314, 0.0) (139.753098, 35.615315, 0.0) (139.753098, 35.615316, 0.0) | G27: (26, 26) | H27: 26/59606297/26441118/26/0 26/59606297/26441118/26/0 26/59606297/26441118/26/0 26/59606297/26441117/26/0 26/59606297/26441117/26/0 26/59606297/26441117/26/0 26/59606297/26441117/26/0 26/59606297/26441116/26/0

Sheet 【別紙2】精度入力パターン
B2: ◆指定範囲の拡張空間ID変換 (点群)
B3: 「指定範囲の拡張空間ID変換 (点群)」 の試験項目にて、点群の空間ID変換を行う際に入力するパラメータと、変換後の空間ID期待値を以下に記載する。
B4: ※期待値についてはPython版の点群APIにて同様の座標、精度を入力して取得した値を記載している。
B6: 入力座標については以下の値で固定とする。
C8: 入力座標（経度, 緯度, 高さ）
C9: (139.753098, 35.685371, 1000.0)
C11: 入力パターン種別 | D11: 入力水平/垂直精度 | E11: 期待値
C12: 精度閾値内 | D12: 0 | E12: 0/0/0/0/0
D13: 1 | E13: 1/1/0/1/0
D14: 2 | E14: 2/3/1/2/0
D15: 3 | E15: 3/7/3/3/0
D16: 4 | E16: 4/14/6/4/0
D17: 5 | E17: 5/28/12/5/0
D18: 6 | E18: 6/56/25/6/0
D19: 7 | E19: 7/113/50/7/0
D20: 8 | E20: 8/227/100/8/0
D21: 9 | E21: 9/454/201/9/0
D22: 10 | E22: 10/909/403/10/0
D23: 11 | E23: 11/1819/806/11/0
D24: 12 | E24: 12/3638/1612/12/0
... D47: 35 | E47: 35/30518424415/13529623431/35/1024000
B52: ◆拡張空間IDから座標への変換
B53: 「空間IDから座標への変換」 の試験項目にて、空間IDの座標変換を行う際に入力するパラメータと、変換後の期待値を以下に記載する。
B54: ※期待値についてはPython版の点群APIにて同様の空間ID、オプションを入力して取得した値を記載している。
B56: 入力オプションについては以下の値で固定とする。
C58: オプション
C59: common.enum.Center
C61: 入力パターン種別 | D61: 入力空間ID | E61: 期待値（経度, 緯度, 高さ）
C62: 精度閾値内 | D62: 0/0/0/0/0 | E62: (0.0, 0.0, 16777216.0)
D63: 1/0/0/1/0 | E63: (-90.0, 42.5255643899, 8388608.0)
D64: 2/0/0/2/0 | E64: (-135.0, 75.7821946114, 4194304.0)
D65: 3/0/0/3/0 | E65: (-157.5, 82.1112317102, 2097152.0)
D66: 4/0/0/4/0 | E66: (-168.75, 83.863706879, 1048576.0)
D67: 5/0/0/5/0 | E67: (-174.375, 84.5151941393, 524288.0)
D68: 6/0/0/6/0 | E68: (-177.1875, 84.7962449264, 262144.0)
D69: 7/0/0/7/0 | E69: (-178.59375, 84.926801252, 131072.0)
D70: 8/0/0/8/0 | E70: (-179.296875, 84.9897248546, 65536.0)
D71: 9/0/0/9/0 | E71: (-179.6484375, 85.02061448, 32768.0)
D72: 10/0/0/10/0 | E72: (-179.82421875, 85.0359182614, 16384.0)
D73: 11/0/0/11/0 | E73: (-179.912109375, 85.0435351431, 8192.0)
...

Sheet 【別紙3】相互変換
B2: ◆指定範囲の拡張空間ID変換 (点群)
B3: 「指定範囲の拡張空間ID変換 (点群)」 の試験項目にて、以下のパターンの試験の確認内容について記載する。
C4: ・「拡張空間IDから座標への変換」で取得した頂点座標を入力
B6: 試験用の頂点座標群取得は、以下の形式で関数を呼び出して結果を変数に格納する。※1
C7: 座標群取得
C8: points, _ := GetPointOnExtendedSpatialId("空間ID", common.enum.Vertex)
B10: 座標への変換で取得した8つの頂点座標を空間IDに変換した場合、変換後の空間IDは以下のようになる。
B11: 試験時は、取得した頂点座標を空間IDに変換した際、以下の対応表と同様の結果となることを確認すること。
C13: 頂点座標 | D13: 空間ID変換時の期待値
C14: points[0] | D14: 入力時の空間IDと同じID
C15: points[1] | D15: 経度インデックス+1
C16: points[2] | D16: 経度インデックス, 緯度インデックス+1
C17: points[3] | D17: 緯度インデックス+1
C18: points[4] | D18: 高さインデックス+1
C19: points[5] | D19: 経度インデックス, 高さインデックス+1
C20: points[6] | D20: 全てのインデックスが+1
C21: points[7] | D21: 緯度インデックス, 高さインデックス+1
B25: 〇実行例
C26: 座標群取得（試験対象の空間IDを "10/5/5/10/10" とする場合）
C27: points, _ := GetPointOnExtendedSpatialId("10/5/5/10/10", common.enum.Vertex)
C29: 頂点座標 | D29: 空間ID変換時の期待値
C30: points[0] | D30: 10/5/5/10/10
C31: points[1] | D31: 10/6/5/10/10
C32: points[2] | D32: 10/6/6/10/10
C33: points[3] | D33: 10/5/6/10/10
C34: points[4] | D34: 10/5/5/10/11
C35: points[5] | D35: 10/6/5/10/11
C36: points[6] | D36: 10/6/6/10/11
C37: points[7] | D37: 10/5/6/10/11
B41: ◆指定範囲の空間ID変換 (点群)
B42: 「指定範囲の空間ID変換 (点群)」 の試験項目にて、以下のパターンの試験の確認内容について記載する。
C43: ・「空間IDから座標への変換」で取得した頂点座標を入力
B45: 試験用の頂点座標群取得は、以下の形式で関数を呼び出して結果を変数に格納する。※1
C46: 座標群取得
C47: points, _ := GetPointOnSpatialId("空間ID", common.enum.Vertex)
B49: 取得した8つの頂点座標を空間IDに変換した際のインデックスの値については、
B50: 拡張空間IDの場合と同様の対応になる。
B52: 〇実行例
C53: 座標群取得 （試験対象の空間IDを "10/10/5/5" とする場合）
C54: points, _ := GetPointOnSpatialId("空間ID", common.enum.Vertex)
...

Sheet 【別紙4】空間ID入力パターン
B2: 「拡張空間IDから座標への変換」 の試験項目にて、空間IDの座標変換を行う際に入力するパラメータと、変換後の座標の期待値を以下に記載する。
B3: ※期待値についてはPython版の点群APIにて同様の空間ID、オプションを入力して取得した値を記載している。
C5: No | D5: 入力パターン種別 | E5: 空間IDパターン | F5: 入力空間ID | G5: 入力オプション | H5: 期待値（経度, 緯度, 高さ）
C6: 1-1 | D6: 座標に正しく変換される | E6: 任意の空間ID | F6: 18/232837/103222/18/32 | G6: common.enum.Center | H6: (139.75364685058594, 35.6857446882, 4160)
C7: 1-2 | E7: 北半球西側 | F7: 9/224/136/26/852 | G7: common.enum.Vertex | H7: (-22.5, 64.1681068979, 426) (-21.796875, 64.1681068979, 426) (-21.796875, 63.8600358953, 426) (-22.5, 63.8600358953, 426) (-22.5, 64.1681068979, 426.5) (-21.796875, 64.1681068979, 426.5) (-21.796875, 63.8600358953, 426.5) (-22.5, 63.8600358953, 426.5)
C8: 1-3 | E8: 南半球 | F8: 14/5535/9872/1/1 | G8: common.enum.Center | H8: (-58.370361328125, -34.6060840997, 25165824)
C9: 1-4 | E9: 地図上の左上を含む | F9: 24/0/0/26/852 | G9: common.enum.Vertex | H9: (-180, 85.0511287798, 426) (-179.99997854232788, 85.0511287798, 426) (-179.99997854232788, 85.0511269287, 426) (-180, 85.0511269287, 426) (-180, 85.0511287798, 426.5) (-179.99997854232788, 85.0511287798, 426.5) (-179.99997854232788, 85.0511269287, 426.5) (-180, 85.0511269287, 426.5)
C10: 1-5 | E10: 地図上の右下を含む | F10: 10/1023/1023/1/1 | G10: common.enum.Vertex | H10: (179.6484375, -85.0207077431, 16777216) (180, -85.0207077431, 16777216) (180, -85.0511287798, 16777216) (179.6484375, -85.0511287798, 16777216) (179.6484375, -85.0207077431, 33554432) (180, -85.0207077431, 33554432) (180, -85.0511287798, 33554432) (179.6484375, -85.0511287798, 33554432)
C11: 1-6 | E11: 原点を含む | F11: 9/256/256/26/852 | G11: common.enum.Vertex | H11: (0, 0, 426) (0.703125, 0, 426) (0.703125, -0.7031073524, 426) (0, -0.7031073524, 426) (0, 0, 426.5) (0.703125, 0, 426.5) (0.703125, -0.7031073524, 426.5) (0, -0.7031073524, 426.5)
C12: 2-1 | D12: 高さインデックスに負の値が設定された空間IDが正しく変換される | E12: - | F12: 10/5/5/10/-5 | G12: common.enum.Center | H12: (-178.06640625, 84.8814644094, -147456)
C13: 3-1 | D13: 空間IDのインデックス値が[2^精度]の境界値を入力 | E13: 経度インデックス | F13: 10/1023/1023/1/1 | G13: common.enum.Vertex | H13: (179.6484375, -85.0207077431, 16777216) (180, -85.0207077431, 16777216) (180, -85.0511287798, 16777216) (179.6484375, -85.0511287798, 16777216) (179.6484375, -85.0207077431, 33554432) (180, -85.0207077431, 33554432) (180, -85.0511287798, 33554432) (179.6484375, -85.0511287798, 33554432)
C14: 3-2 | E14: 緯度インデックス | F14: 10/1023/1023/1/1 | G14: common.enum.Vertex | H14: (179.6484375, -85.0207077431, 16777216) (180, -85.0207077431, 16777216) (180, -85.0511287798, 16777216) (179.6484375, -85.0511287798, 16777216) (179.6484375, -85.0207077431, 33554432) (180, -85.0207077431, 33554432) (180, -85.0511287798, 33554432) (179.6484375, -85.0511287798, 33554432)
C15: 4-1 | D15: 空間IDのインデックス値が[2^精度]を超えていても正しく変換される | E15: 経度インデックス | F15: 10/2048/2048/26/852 | G15: common.enum.Vertex | H15: (-180, -85.0207077431, 426) (-179.6484375, -85.0207077431, 426) (-179.6484375, -85.0511287798, 426) (-180, -85.0511287798, 426) (-180, -85.0207077431, 426.5) (-179.6484375, -85.0207077431, 426.5) (-179.6484375, -85.0511287798, 426.5) (-180, -85.0511287798, 426.5))
C16: 4-2 | E16: 緯度インデックス | F16: 10/2048/2048/26/852 | G16: common.enum.Vertex | H16: (-180, -85.0207077431, 426) (-179.6484375, -85.0207077431, 426) (-179.6484375, -85.0511287798, 426) (-180, -85.0511287798, 426) (-180, -85.0207077431, 426.5) (-179.6484375, -85.0207077431, 426.5) (-179.6484375, -85.0511287798, 426.5) (-180, -85.0511287798, 426.5))
C17: 5-1 | D17: 頂点の座標(計８個)が返却される | E17: - | F17: 18/232837/103222/18/32 | G17: common.enum.Center | H17: (139.75364685058594, 35.6857446882, 4160)
C18: 6-1 | D18: 中心点の座標(計1個)が返却される | E18: - | F18: 9/224/136/26/852 | G18: common.enum.Vertex | H18: (-22.5, 64.1681068979, 426) (-21.796875, 64.1681068979, 426) (-21.796875, 63.8600358953, 426) (-22.5, 63.8600358953, 426) (-22.5, 64.1681068979, 426.5) (-21.796875, 64.1681068979, 426.5) (-21.796875, 63.8600358953, 426.5) (-22.5, 63.8600358953, 426.5)
