Workbook
Name Level2ManDays: 【別紙1】変換前後の精度差パターン!Level2ManDays
Name Level2ManDays: 【別紙2】変換前の空間IDパターン!Level2ManDays
Name Level2ManDays: 【別紙3】変換後拡張空間IDの重複パターン!Level2ManDays
Name Level2ManDays: 【別紙4】変換後の角に接するパターン!Level2ManDays
Name Level2ManDays: 【別紙5】変換前拡張空間IDの複数入力パターン!Level2ManDays
Name Level2ManDays: 変更履歴!Level2ManDays
Name Level2ManDays: [0]!Level2ManDays

Sheet 表紙
AB1: 精度変換
B7: ="空間ID開発(GO言語版) "&AB1 -> 空間ID開発(GO言語版) 精度変換
B17: 結合試験項目書
B20: =CONCATENATE(TEXT(MAX(変更履歴!C3:C7),"0.00"), "版") -> 1.00版
B23: 44585

Sheet 変更履歴
B2: 日時 | C2: 版 | D2: 変更箇所 | E2: 作業者 | F2: 変更内容
B3: 44585 | C3: 1 | D3: 全ページ | E3: α | F3: 新規改定

Sheet 集計
A1: 集計
B2: 試験シート | C2: 全項目数 | D2: 実施済み | E2: 未実施
B3: 1.結合試験 | C3: =VLOOKUP(B3,$B$8:$D$11,3,FALSE) -> 93 | D3: {=COUNTIF(INDIRECT(B3&"!$K$3:$K$1024"),"OK")-SUMPRODUCT((OFFSET(INDIRECT(B3&"!$K$3:$K$1024"),,)="OK")*(OFFSET(INDIRECT(B3&"!$M$3:$M$1024"),,)<>""))} -> 93 | E3: =C3-D3 -> 0
B4: 計 | C4: =SUM(C3:C3) -> 93 | D4: =SUM(D3:D3) -> 93 | E4: =SUM(E3:E3) -> 0
B6: 試験項目数内訳
B8: 1.結合試験 | C8: 全項目数 | D8: =SUM(D9:D11) -> 93
C9: 正常 | D9: {=COUNTIF(INDIRECT(B8&"!$E$3:$E$1024"),C9)-SUMPRODUCT((OFFSET(INDIRECT(B8&"!$E$3:$E$1024"),,)=C9)*(OFFSET(INDIRECT(B8&"!$M$3:$M$1024"),,)<>""))} -> 70
C10: 準正常 | D10: {=COUNTIF(INDIRECT(B8&"!$E$3:$E$1024"),C10)-SUMPRODUCT((OFFSET(INDIRECT(B8&"!$E$3:$E$1024"),,)=C10)*(OFFSET(INDIRECT(B8&"!$M$3:$M$1024"),,)<>""))} -> 23
C11: 異常 | D11: {=COUNTIF(INDIRECT(B8&"!$E$3:$E$1024"),C11)-SUMPRODUCT((OFFSET(INDIRECT(B8&"!$E$3:$E$1024"),,)=C11)*(OFFSET(INDIRECT(B8&"!$M$3:$M$1024"),,)<>""))} -> 0

Sheet 1.結合試験
A1: =MID(CELL("filename",$A$1),FIND("]",CELL("filename",$A$1))+3,31) -> 結合試験 | K1: OK, NG | R1: シート番号 | S1: =VALUE(MID(CELL("filename",$A$1),FIND("]",CELL("filename",$A$1))+1,2)) -> 1
A2: No | B2: 大項目 | C2: 中項目 | D2: 小項目 | E2: 試験種別 | F2: 優先度 | G2: 確認手順 | H2: 確認内容 | I2: 試験日 | J2: 試験者 | K2: 試験結果 | L2: 備考 | M2: 重複項目 | R2: 大番号 | S2: 中番号 | T2: 小番号
A3: =IF(B3<>"",表紙!$AB$1&"-"&"結合-"&TEXT($S$1,"00")&"-"&TEXT(R3,"00")&"-"&TEXT(S3,"00")&"-"&TEXT(T3,"０00"),"") -> 精度変換-結合-01-01-01-001 | B3: パラメータ入力チェック(拡張空間ID) | C3: 精度閾値を超過した値を入力する | D3: 水平方向精度：36 | E3: 準正常 | G3: 1. 引数に以下を指定して、integrate.ChangeExtendedSpatialIdsZoomを呼び出す。 拡張空間ID：10/10/10/10/10 水平方向精度： 36 垂直方向精度： 11 | H3: ・以下のspatialIdErrorが返却されること - エラーコード：InputValueError - エラーメッセージ：入力チェックエラー | I3: 44950 | J3: 宮原 | K3: OK | R3: =IF(ROW()<>3,IF(B2<>B3,#REF!+1,#REF!),1) -> 1 | S3: =IF(B2=B3,IF(C2<>C3,#REF!+1,#REF!),1) -> 1 | T3: =IF(B2<>B3,1,IF(C2=C3,#REF!+1,1)) -> 1
A4: =IF(B4<>"",表紙!$AB$1&"-"&"結合-"&TEXT($S$1,"00")&"-"&TEXT(R4,"00")&"-"&TEXT(S4,"00")&"-"&TEXT(T4,"０00"),"") -> 精度変換-結合-01-01-01-002 | B4: パラメータ入力チェック(拡張空間ID) | C4: 精度閾値を超過した値を入力する | D4: 水平方向精度：-1 | E4: 準正常 | G4: 1. 引数に以下を指定して、integrate.ChangeExtendedSpatialIdsZoomを呼び出す。 拡張空間ID：10/10/10/10/10 水平方向精度： -1 垂直方向精度： 11 | H4: ・以下のspatialIdErrorが返却されること - エラーコード：InputValueError - エラーメッセージ：入力チェックエラー | I4: 44950 | J4: 宮原 | K4: OK | R4: =IF(ROW()<>3,IF(B3<>B4,R3+1,R3),1) -> 1 | S4: =IF(B3=B4,IF(C3<>C4,S3+1,S3),1) -> 1 | T4: =IF(B3<>B4,1,IF(C3=C4,T3+1,1)) -> 2
A5: =IF(B5<>"",表紙!$AB$1&"-"&"結合-"&TEXT($S$1,"00")&"-"&TEXT(R5,"00")&"-"&TEXT(S5,"00")&"-"&TEXT(T5,"０00"),"") -> 精度変換-結合-01-01-01-003 | B5: パラメータ入力チェック(拡張空間ID) | C5: 精度閾値を超過した値を入力する | D5: 垂直方向精度：36 | E5: 準正常 | G5: 1. 引数に以下を指定して、integrate.ChangeExtendedSpatialIdsZoomを呼び出す。 拡張空間ID：10/10/10/10/10 水平方向精度： 11 垂直方向精度： 36 | H5: ・以下のspatialIdErrorが返却されること - エラーコード：InputValueError - エラーメッセージ：入力チェックエラー | I5: 44950 | J5: 宮原 | K5: OK | R5: =IF(ROW()<>3,IF(B4<>B5,R4+1,R4),1) -> 1 | S5: =IF(B4=B5,IF(C4<>C5,S4+1,S4),1) -> 1 | T5: =IF(B4<>B5,1,IF(C4=C5,T4+1,1)) -> 3
A6: =IF(B6<>"",表紙!$AB$1&"-"&"結合-"&TEXT($S$1,"00")&"-"&TEXT(R6,"00")&"-"&TEXT(S6,"00")&"-"&TEXT(T6,"０00"),"") -> 精度変換-結合-01-01-01-004 | B6: パラメータ入力チェック(拡張空間ID) | C6: 精度閾値を超過した値を入力する | D6: 垂直方向精度：-1 | E6: 準正常 | G6: 1. 引数に以下を指定して、integrate.ChangeExtendedSpatialIdsZoomを呼び出す。 拡張空間ID：10/10/10/10/10 水平方向精度： 11 垂直方向精度： -1 | H6: ・以下のspatialIdErrorが返却されること - エラーコード：InputValueError - エラーメッセージ：入力チェックエラー | I6: 44950 | J6: 宮原 | K6: OK | R6: =IF(ROW()<>3,IF(B5<>B6,R5+1,R5),1) -> 1 | S6: =IF(B5=B6,IF(C5<>C6,S5+1,S5),1) -> 1 | T6: =IF(B5<>B6,1,IF(C5=C6,T5+1,1)) -> 4
A7: =IF(B7<>"",表紙!$AB$1&"-"&"結合-"&TEXT($S$1,"00")&"-"&TEXT(R7,"00")&"-"&TEXT(S7,"00")&"-"&TEXT(T7,"０00"),"") -> 精度変換-結合-01-01-01-005 | B7: パラメータ入力チェック(拡張空間ID) | C7: 精度閾値を超過した値を入力する | D7: 水平・垂直方向精度：36 | E7: 準正常 | G7: 1. 引数に以下を指定して、integrate.ChangeExtendedSpatialIdsZoomを呼び出す。 拡張空間ID：10/10/10/10/10 水平方向精度： 36 垂直方向精度： 36 | H7: ・以下のspatialIdErrorが返却されること - エラーコード：InputValueError - エラーメッセージ：入力チェックエラー | I7: 44950 | J7: 宮原 | K7: OK | R7: =IF(ROW()<>3,IF(B6<>B7,R6+1,R6),1) -> 1 | S7: =IF(B6=B7,IF(C6<>C7,S6+1,S6),1) -> 1 | T7: =IF(B6<>B7,1,IF(C6=C7,T6+1,1)) -> 5
A8: =IF(B8<>"",表紙!$AB$1&"-"&"結合-"&TEXT($S$1,"00")&"-"&TEXT(R8,"00")&"-"&TEXT(S8,"00")&"-"&TEXT(T8,"０00"),"") -> 精度変換-結合-01-01-01-006 | B8: パラメータ入力チェック(拡張空間ID) | C8: 精度閾値を超過した値を入力する | D8: 水平・垂直方向精度：-1 | E8: 準正常 | G8: 1. 引数に以下を指定して、integrate.ChangeExtendedSpatialIdsZoomを呼び出す。 拡張空間ID：10/10/10/10/10 水平方向精度： -1 垂直方向精度： -1 | H8: ・以下のspatialIdErrorが返却されること - エラーコード：InputValueError - エラーメッセージ：入力チェックエラー | I8: 44950 | J8: 宮原 | K8: OK | R8: =IF(ROW()<>3,IF(B7<>B8,R7+1,R7),1) -> 1 | S8: =IF(B7=B8,IF(C7<>C8,S7+1,S7),1) -> 1 | T8: =IF(B7<>B8,1,IF(C7=C8,T7+1,1)) -> 6
A9: =IF(B9<>"",表紙!$AB$1&"-"&"結合-"&TEXT($S$1,"00")&"-"&TEXT(R9,"00")&"-"&TEXT(S9,"00")&"-"&TEXT(T9,"０00"),"") -> 精度変換-結合-01-01-02-001 | B9: パラメータ入力チェック(拡張空間ID) | C9: 拡張空間IDフォーマット不正の拡張空間IDが入力される | D9: 区切り文字不足： 3個以下 | E9: 準正常 | G9: 1. 引数に以下を指定して、integrate.ChangeExtendedSpatialIdsZoomを呼び出す。 拡張空間ID：10/10/10/10 水平方向精度： 11 垂直方向精度： 11 | H9: ・以下のspatialIdErrorが返却されること - エラーコード：InputValueError - エラーメッセージ：入力チェックエラー | I9: 44950 | J9: 宮原 | K9: OK | R9: =IF(ROW()<>3,IF(B8<>B9,R8+1,R8),1) -> 1 | S9: =IF(B8=B9,IF(C8<>C9,S8+1,S8),1) -> 2 | T9: =IF(B8<>B9,1,IF(C8=C9,T8+1,1)) -> 1
A10: =IF(B10<>"",表紙!$AB$1&"-"&"結合-"&TEXT($S$1,"00")&"-"&TEXT(R10,"00")&"-"&TEXT(S10,"00")&"-"&TEXT(T10,"０00"),"") -> 精度変換-結合-01-01-02-002 | B10: パラメータ入力チェック(拡張空間ID) | C10: 拡張空間IDフォーマット不正の拡張空間IDが入力される | D10: 区切り文字過多： 5個以上 | E10: 準正常 | G10: 1. 引数に以下を指定して、integrate.ChangeExtendedSpatialIdsZoomを呼び出す。 拡張空間ID：10/10/10/10/10/10 水平方向精度： 11 垂直方向精度： 11 | H10: ・以下のspatialIdErrorが返却されること - エラーコード：InputValueError - エラーメッセージ：入力チェックエラー | I10: 44950 | J10: 宮原 | K10: OK | R10: =IF(ROW()<>3,IF(B9<>B10,R9+1,R9),1) -> 1 | S10: =IF(B9=B10,IF(C9<>C10,S9+1,S9),1) -> 2 | T10: =IF(B9<>B10,1,IF(C9=C10,T9+1,1)) -> 2
A11: =IF(B11<>"",表紙!$AB$1&"-"&"結合-"&TEXT($S$1,"00")&"-"&TEXT(R11,"00")&"-"&TEXT(S11,"00")&"-"&TEXT(T11,"０00"),"") -> 精度変換-結合-01-01-02-003 | B11: パラメータ入力チェック(拡張空間ID) | C11: 拡張空間IDフォーマット不正の拡張空間IDが入力される | D11: 利用不可の文字を含む | E11: 準正常 | G11: 1. 引数に以下を指定して、integrate.ChangeExtendedSpatialIdsZoomを呼び出す。 拡張空間ID：10|10|10|10|10 水平方向精度： 11 垂直方向精度： 11 | H11: ・以下のspatialIdErrorが返却されること - エラーコード：InputValueError - エラーメッセージ：入力チェックエラー | I11: 44950 | J11: 宮原 | K11: OK | R11: =IF(ROW()<>3,IF(B10<>B11,R10+1,R10),1) -> 1 | S11: =IF(B10=B11,IF(C10<>C11,S10+1,S10),1) -> 2 | T11: =IF(B10<>B11,1,IF(C10=C11,T10+1,1)) -> 3
A12: =IF(B12<>"",表紙!$AB$1&"-"&"結合-"&TEXT($S$1,"00")&"-"&TEXT(R12,"00")&"-"&TEXT(S12,"00")&"-"&TEXT(T12,"０00"),"") -> 精度変換-結合-01-01-02-004 | B12: パラメータ入力チェック(拡張空間ID) | C12: 拡張空間IDフォーマット不正の拡張空間IDが入力される | D12: 水平精度インデクス値無し | E12: 準正常 | G12: 1. 引数に以下を指定して、integrate.ChangeExtendedSpatialIdsZoomを呼び出す。 拡張空間ID：/10/10/10/10 水平方向精度： 11 垂直方向精度： 11 | H12: ・以下のspatialIdErrorが返却されること - エラーコード：InputValueError - エラーメッセージ：入力チェックエラー | I12: 44950 | J12: 宮原 | K12: OK | R12: =IF(ROW()<>3,IF(B11<>B12,R11+1,R11),1) -> 1 | S12: =IF(B11=B12,IF(C11<>C12,S11+1,S11),1) -> 2 | T12: =IF(B11<>B12,1,IF(C11=C12,T11+1,1)) -> 4
A13: =IF(B13<>"",表紙!$AB$1&"-"&"結合-"&TEXT($S$1,"00")&"-"&TEXT(R13,"00")&"-"&TEXT(S13,"00")&"-"&TEXT(T13,"０00"),"") -> 精度変換-結合-01-01-02-005 | B13: パラメータ入力チェック(拡張空間ID) | C13: 拡張空間IDフォーマット不正の拡張空間IDが入力される | D13: 垂直精度インデクス値無し | E13: 準正常 | G13: 1. 引数に以下を指定して、integrate.ChangeExtendedSpatialIdsZoomを呼び出す。 拡張空間ID：10/10/10//10 水平方向精度： 11 垂直方向精度： 11 | H13: ・以下のspatialIdErrorが返却されること - エラーコード：InputValueError - エラーメッセージ：入力チェックエラー | I13: 44950 | J13: 宮原 | K13: OK | R13: =IF(ROW()<>3,IF(B12<>B13,R12+1,R12),1) -> 1 | S13: =IF(B12=B13,IF(C12<>C13,S12+1,S12),1) -> 2 | T13: =IF(B12<>B13,1,IF(C12=C13,T12+1,1)) -> 5
A14: =IF(B14<>"",表紙!$AB$1&"-"&"結合-"&TEXT($S$1,"00")&"-"&TEXT(R14,"00")&"-"&TEXT(S14,"00")&"-"&TEXT(T14,"０00"),"") -> 精度変換-結合-01-01-02-006 | B14: パラメータ入力チェック(拡張空間ID) | C14: 拡張空間IDフォーマット不正の拡張空間IDが入力される | D14: 経度インデクス値無し | E14: 準正常 | G14: 1. 引数に以下を指定して、integrate.ChangeExtendedSpatialIdsZoomを呼び出す。 拡張空間ID：10//10/10/10 水平方向精度： 11 垂直方向精度： 11 | H14: ・以下のspatialIdErrorが返却されること - エラーコード：InputValueError - エラーメッセージ：入力チェックエラー | I14: 44950 | J14: 宮原 | K14: OK | R14: =IF(ROW()<>3,IF(B13<>B14,R13+1,R13),1) -> 1 | S14: =IF(B13=B14,IF(C13<>C14,S13+1,S13),1) -> 2 | T14: =IF(B13<>B14,1,IF(C13=C14,T13+1,1)) -> 6
A15: =IF(B15<>"",表紙!$AB$1&"-"&"結合-"&TEXT($S$1,"00")&"-"&TEXT(R15,"00")&"-"&TEXT(S15,"00")&"-"&TEXT(T15,"０00"),"") -> 精度変換-結合-01-01-02-007 | B15: パラメータ入力チェック(拡張空間ID) | C15: 拡張空間IDフォーマット不正の拡張空間IDが入力される | D15: 緯度インデクス値無し | E15: 準正常 | G15: 1. 引数に以下を指定して、integrate.ChangeExtendedSpatialIdsZoomを呼び出す。 拡張空間ID：10/10//10/10 水平方向精度： 11 垂直方向精度： 11 | H15: ・以下のspatialIdErrorが返却されること - エラーコード：InputValueError - エラーメッセージ：入力チェックエラー | I15: 44950 | J15: 宮原 | K15: OK | R15: =IF(ROW()<>3,IF(B14<>B15,R14+1,R14),1) -> 1 | S15: =IF(B14=B15,IF(C14<>C15,S14+1,S14),1) -> 2 | T15: =IF(B14<>B15,1,IF(C14=C15,T14+1,1)) -> 7
... A27: =IF(B27<>"",表紙!$AB$1&"-"&"結合-"&TEXT($S$1,"00")&"-"&TEXT(R27,"00")&"-"&TEXT(S27,"00")&"-"&TEXT(T27,"０00"),"") -> 精度変換-結合-01-02-01-011 | B27: 精度変換の試験パターンの網羅(拡張空間ID) | C27: 変換前後の水平/垂直方向精度差のパターン | D27: 水平方向精度: 2以上減少 垂直方向精度: 2以上減少 | E27: 正常 | G27: 1. 引数に以下を指定して、integrate.ChangeExtendedSpatialIdsZoomを呼び出す。 "【別紙1】変換前後の精度差パターン"シート"拡張空間ID試験データ"のNo.11の「変換前拡張空間ID」「変換後水平方向精度」「変換後水平方向精度」 | H27: ・入力した座標パターンに対応した期待値が取得できること ・変換後の拡張空間ID数が期待値通りになっていること ・エラーインスタンスが返却されていないこと | I27: 44951 | J27: 宮原 | K27: OK | R27: =IF(ROW()<>3,IF(B26<>B27,R26+1,R26),1) -> 2 | S27: =IF(B26=B27,IF(C26<>C27,S26+1,S26),1) -> 1 | T27: =IF(B26<>B27,1,IF(C26=C27,T26+1,1)) -> 11
A28: =IF(B28<>"",表紙!$AB$1&"-"&"結合-"&TEXT($S$1,"00")&"-"&TEXT(R28,"00")&"-"&TEXT(S28,"00")&"-"&TEXT(T28,"０00"),"") -> 精度変換-結合-01-02-02-001 | B28: 精度変換の試験パターンの網羅(拡張空間ID) | C28: 変換前拡張空間IDを1つ入力 | M28: =$A$17 -> 精度変換-結合-01-02-01-001 | R28: =IF(ROW()<>3,IF(B25<>B28,R25+1,R25),1) -> 2 | S28: =IF(B25=B28,IF(C25<>C28,S25+1,S25),1) -> 2 | T28: =IF(B25<>B28,1,IF(C25=C28,T25+1,1)) -> 1
A29: =IF(B29<>"",表紙!$AB$1&"-"&"結合-"&TEXT($S$1,"00")&"-"&TEXT(R29,"00")&"-"&TEXT(S29,"00")&"-"&TEXT(T29,"０00"),"") -> 精度変換-結合-01-02-03-001 | B29: 精度変換の試験パターンの網羅(拡張空間ID) | C29: 変換前拡張空間IDを複数入力 | D29: 入力数：2 | E29: 正常 | G29: 1. 引数に以下を指定して、integrate.ChangeExtendedSpatialIdsZoomを呼び出す。 "【別紙5】変換前拡張空間IDの複数入力パターン"シート"拡張空間ID試験データ"のNo.1の「変換前拡張空間ID」「変換後水平方向精度」「変換後水平方向精度」 | H29: ・入力した座標パターンに対応した期待値が取得できること ・エラーインスタンスが返却されていないこと | I29: 44951 | J29: 宮原 | K29: OK | R29: =IF(ROW()<>3,IF(B28<>B29,R28+1,R28),1) -> 2 | S29: =IF(B28=B29,IF(C28<>C29,S28+1,S28),1) -> 3 | T29: =IF(B28<>B29,1,IF(C28=C29,T28+1,1)) -> 1
A30: =IF(B30<>"",表紙!$AB$1&"-"&"結合-"&TEXT($S$1,"00")&"-"&TEXT(R30,"00")&"-"&TEXT(S30,"00")&"-"&TEXT(T30,"０00"),"") -> 精度変換-結合-01-02-03-002 | B30: 精度変換の試験パターンの網羅(拡張空間ID) | C30: 変換前拡張空間IDを複数入力 | D30: 入力数：10 | E30: 正常 | G30: 1. 引数に以下を指定して、integrate.ChangeExtendedSpatialIdsZoomを呼び出す。 "【別紙5】変換前拡張空間IDの複数入力パターン"シート"拡張空間ID試験データ"のNo.2の「変換前拡張空間ID」「変換後水平方向精度」「変換後水平方向精度」 | H30: ・入力した座標パターンに対応した期待値が取得できること ・エラーインスタンスが返却されていないこと | I30: 44951 | J30: 宮原 | K30: OK | R30: =IF(ROW()<>3,IF(B29<>B30,R29+1,R29),1) -> 2 | S30: =IF(B29=B30,IF(C29<>C30,S29+1,S29),1) -> 3 | T30: =IF(B29<>B30,1,IF(C29=C30,T29+1,1)) -> 2
A31: =IF(B31<>"",表紙!$AB$1&"-"&"結合-"&TEXT($S$1,"00")&"-"&TEXT(R31,"00")&"-"&TEXT(S31,"00")&"-"&TEXT(T31,"０00"),"") -> 精度変換-結合-01-02-04-001 | B31: 精度変換の試験パターンの網羅(拡張空間ID) | C31: 変換前拡張空間IDの精度を変えても精度変換結果が取得できる | D31: 変換前水平方向精度：0 変換後水平方向精度：1 | E31: 正常 | G31: 1. 引数に以下を指定して、integrate.ChangeExtendedSpatialIdsZoomを呼び出す。 拡張空間ID：0/0/0/2/0 水平方向精度： 1 垂直方向精度： 2 | H31: ・以下の拡張空間IDが取得できること [1/0/0/2/0, 1/1/0/2/0, 1/0/1/2/0, 1/1/1/2/0] ・エラーインスタンスが返却されていないこと | I31: 44951 | J31: 宮原 | K31: OK | R31: =IF(ROW()<>3,IF(B30<>B31,R30+1,R30),1) -> 2 | S31: =IF(B30=B31,IF(C30<>C31,S30+1,S30),1) -> 4 | T31: =IF(B30<>B31,1,IF(C30=C31,T30+1,1)) -> 1
A32: =IF(B32<>"",表紙!$AB$1&"-"&"結合-"&TEXT($S$1,"00")&"-"&TEXT(R32,"00")&"-"&TEXT(S32,"00")&"-"&TEXT(T32,"０00"),"") -> 精度変換-結合-01-02-04-002 | B32: 精度変換の試験パターンの網羅(拡張空間ID) | C32: 変換前拡張空間IDの精度を変えても精度変換結果が取得できる | D32: 変換前水平方向精度：35 変換後水平方向精度：34 | E32: 正常 | G32: 1. 引数に以下を指定して、integrate.ChangeExtendedSpatialIdsZoomを呼び出す。 拡張空間ID：35/10/10/2/10 水平方向精度： 34 垂直方向精度： 2 | H32: ・以下の拡張空間IDが取得できること [34/5/5/2/10] ・エラーインスタンスが返却されていないこと | I32: 44951 | J32: 宮原 | K32: OK | R32: =IF(ROW()<>3,IF(B31<>B32,R31+1,R31),1) -> 2 | S32: =IF(B31=B32,IF(C31<>C32,S31+1,S31),1) -> 4 | T32: =IF(B31<>B32,1,IF(C31=C32,T31+1,1)) -> 2
A33: =IF(B33<>"",表紙!$AB$1&"-"&"結合-"&TEXT($S$1,"00")&"-"&TEXT(R33,"00")&"-"&TEXT(S33,"00")&"-"&TEXT(T33,"０00"),"") -> 精度変換-結合-01-02-04-003 | B33: 精度変換の試験パターンの網羅(拡張空間ID) | C33: 変換前拡張空間IDの精度を変えても精度変換結果が取得できる | D33: 変換前垂直方向精度：0 変換後垂直方向精度：1 | E33: 正常 | G33: 1. 引数に以下を指定して、integrate.ChangeExtendedSpatialIdsZoomを呼び出す。 拡張空間ID：2/0/0/0/0 水平方向精度： 2 垂直方向精度： 1 | H33: ・以下の拡張空間IDが取得できること [2/0/0/1/0, 2/0/0/1/1] ・エラーインスタンスが返却されていないこと | I33: 44951 | J33: 宮原 | K33: OK | R33: =IF(ROW()<>3,IF(B32<>B33,R32+1,R32),1) -> 2 | S33: =IF(B32=B33,IF(C32<>C33,S32+1,S32),1) -> 4 | T33: =IF(B32<>B33,1,IF(C32=C33,T32+1,1)) -> 3
A34: =IF(B34<>"",表紙!$AB$1&"-"&"結合-"&TEXT($S$1,"00")&"-"&TEXT(R34,"00")&"-"&TEXT(S34,"00")&"-"&TEXT(T34,"０00"),"") -> 精度変換-結合-01-02-04-004 | B34: 精度変換の試験パターンの網羅(拡張空間ID) | C34: 変換前拡張空間IDの精度を変えても精度変換結果が取得できる | D34: 変換前垂直方向精度：35 変換後垂直方向精度：34 | E34: 正常 | G34: 1. 引数に以下を指定して、integrate.ChangeExtendedSpatialIdsZoomを呼び出す。 拡張空間ID：2/10/10/35/10 水平方向精度： 2 垂直方向精度： 34 | H34: ・以下の拡張空間IDが取得できること [2/10/10/34/5] ・エラーインスタンスが返却されていないこと | I34: 44951 | J34: 宮原 | K34: OK | R34: =IF(ROW()<>3,IF(B33<>B34,R33+1,R33),1) -> 2 | S34: =IF(B33=B34,IF(C33<>C34,S33+1,S33),1) -> 4 | T34: =IF(B33<>B34,1,IF(C33=C34,T33+1,1)) -> 4
A35: =IF(B35<>"",表紙!$AB$1&"-"&"結合-"&TEXT($S$1,"00")&"-"&TEXT(R35,"00")&"-"&TEXT(S35,"00")&"-"&TEXT(T35,"０00"),"") -> 精度変換-結合-01-02-05-001 | B35: 精度変換の試験パターンの網羅(拡張空間ID) | C35: 変換前拡張空間IDの精度における最大/最小の拡張空間ID入力 | D35: 経度インデクス値最小 | E35: 正常 | G35: 1. 引数に以下を指定して、integrate.ChangeExtendedSpatialIdsZoomを呼び出す。 "【別紙2】変換前の空間IDパターン"シート"拡張空間ID試験データ"のNo.1の「変換前拡張空間ID」「変換後水平方向精度」「変換後水平方向精度」 | H35: ・入力した座標パターンに対応した期待値が取得できること ・エラーインスタンスが返却されていないこと | I35: 44952 | J35: 宮原 | K35: OK | R35: =IF(ROW()<>3,IF(B34<>B35,R34+1,R34),1) -> 2 | S35: =IF(B34=B35,IF(C34<>C35,S34+1,S34),1) -> 5 | T35: =IF(B34<>B35,1,IF(C34=C35,T34+1,1)) -> 1
A36: =IF(B36<>"",表紙!$AB$1&"-"&"結合-"&TEXT($S$1,"00")&"-"&TEXT(R36,"00")&"-"&TEXT(S36,"00")&"-"&TEXT(T36,"０00"),"") -> 精度変換-結合-01-02-05-002 | B36: 精度変換の試験パターンの網羅(拡張空間ID) | C36: 変換前拡張空間IDの精度における最大/最小の拡張空間ID入力 | D36: 経度インデクス値最大 | E36: 正常 | G36: 1. 引数に以下を指定して、integrate.ChangeExtendedSpatialIdsZoomを呼び出す。 "【別紙2】変換前の空間IDパターン"シート"拡張空間ID試験データ"のNo.2の「変換前拡張空間ID」「変換後水平方向精度」「変換後水平方向精度」 | H36: ・入力した座標パターンに対応した期待値が取得できること ・エラーインスタンスが返却されていないこと | I36: 44952 | J36: 宮原 | K36: OK | R36: =IF(ROW()<>3,IF(B35<>B36,R35+1,R35),1) -> 2 | S36: =IF(B35=B36,IF(C35<>C36,S35+1,S35),1) -> 5 | T36: =IF(B35<>B36,1,IF(C35=C36,T35+1,1)) -> 2
A37: =IF(B37<>"",表紙!$AB$1&"-"&"結合-"&TEXT($S$1,"00")&"-"&TEXT(R37,"00")&"-"&TEXT(S37,"00")&"-"&TEXT(T37,"０00"),"") -> 精度変換-結合-01-02-05-003 | B37: 精度変換の試験パターンの網羅(拡張空間ID) | C37: 変換前拡張空間IDの精度における最大/最小の拡張空間ID入力 | D37: 緯度インデクス値最小 | E37: 正常 | G37: 1. 引数に以下を指定して、integrate.ChangeExtendedSpatialIdsZoomを呼び出す。 "【別紙2】変換前の空間IDパターン"シート"拡張空間ID試験データ"のNo.3の「変換前拡張空間ID」「変換後水平方向精度」「変換後水平方向精度」 | H37: ・入力した座標パターンに対応した期待値が取得できること ・エラーインスタンスが返却されていないこと | I37: 44952 | J37: 宮原 | K37: OK | R37: =IF(ROW()<>3,IF(B36<>B37,R36+1,R36),1) -> 2 | S37: =IF(B36=B37,IF(C36<>C37,S36+1,S36),1) -> 5 | T37: =IF(B36<>B37,1,IF(C36=C37,T36+1,1)) -> 3
A38: =IF(B38<>"",表紙!$AB$1&"-"&"結合-"&TEXT($S$1,"00")&"-"&TEXT(R38,"00")&"-"&TEXT(S38,"00")&"-"&TEXT(T38,"０00"),"") -> 精度変換-結合-01-02-05-004 | B38: 精度変換の試験パターンの網羅(拡張空間ID) | C38: 変換前拡張空間IDの精度における最大/最小の拡張空間ID入力 | D38: 緯度インデクス値最大 | E38: 正常 | G38: 1. 引数に以下を指定して、integrate.ChangeExtendedSpatialIdsZoomを呼び出す。 "【別紙2】変換前の空間IDパターン"シート"拡張空間ID試験データ"のNo.4の「変換前拡張空間ID」「変換後水平方向精度」「変換後水平方向精度」 | H38: ・入力した座標パターンに対応した期待値が取得できること ・エラーインスタンスが返却されていないこと | I38: 44952 | J38: 宮原 | K38: OK | R38: =IF(ROW()<>3,IF(B37<>B38,R37+1,R37),1) -> 2 | S38: =IF(B37=B38,IF(C37<>C38,S37+1,S37),1) -> 5 | T38: =IF(B37<>B38,1,IF(C37=C38,T37+1,1)) -> 4
A39: =IF(B39<>"",表紙!$AB$1&"-"&"結合-"&TEXT($S$1,"00")&"-"&TEXT(R39,"00")&"-"&TEXT(S39,"00")&"-"&TEXT(T39,"０00"),"") -> 精度変換-結合-01-02-05-005 | B39: 精度変換の試験パターンの網羅(拡張空間ID) | C39: 変換前拡張空間IDの精度における最大/最小の拡張空間ID入力 | D39: 高さインデクス値最小 | E39: 正常 | G39: 1. 引数に以下を指定して、integrate.ChangeExtendedSpatialIdsZoomを呼び出す。 "【別紙2】変換前の空間IDパターン"シート"拡張空間ID試験データ"のNo.5の「変換前拡張空間ID」「変換後水平方向精度」「変換後水平方向精度」 | H39: ・入力した座標パターンに対応した期待値が取得できること ・エラーインスタンスが返却されていないこと | I39: 44952 | J39: 宮原 | K39: OK | R39: =IF(ROW()<>3,IF(B38<>B39,R38+1,R38),1) -> 2 | S39: =IF(B38=B39,IF(C38<>C39,S38+1,S38),1) -> 5 | T39: =IF(B38<>B39,1,IF(C38=C39,T38+1,1)) -> 5
A40: =IF(B40<>"",表紙!$AB$1&"-"&"結合-"&TEXT($S$1,"00")&"-"&TEXT(R40,"00")&"-"&TEXT(S40,"00")&"-"&TEXT(T40,"０00"),"") -> 精度変換-結合-01-02-05-006 | B40: 精度変換の試験パターンの網羅(拡張空間ID) | C40: 変換前拡張空間IDの精度における最大/最小の拡張空間ID入力 | D40: 高さインデクス値最大 | E40: 正常 | G40: 1. 引数に以下を指定して、integrate.ChangeExtendedSpatialIdsZoomを呼び出す。 "【別紙2】変換前の空間IDパターン"シート"拡張空間ID試験データ"のNo.6の「変換前拡張空間ID」「変換後水平方向精度」「変換後水平方向精度」 | H40: ・入力した座標パターンに対応した期待値が取得できること ・エラーインスタンスが返却されていないこと | I40: 44952 | J40: 宮原 | K40: OK | R40: =IF(ROW()<>3,IF(B39<>B40,R39+1,R39),1) -> 2 | S40: =IF(B39=B40,IF(C39<>C40,S39+1,S39),1) -> 5 | T40: =IF(B39<>B40,1,IF(C39=C40,T39+1,1)) -> 6
... A71: =IF(B71<>"",表紙!$AB$1&"-"&"結合-"&TEXT($S$1,"00")&"-"&TEXT(R71,"00")&"-"&TEXT(S71,"00")&"-"&TEXT(T71,"０00"),"") -> 精度変換-結合-01-04-01-005 | B71: 精度変換の試験パターンの網羅(空間ID) | C71: 変換前後の精度差のパターン | D71: 精度: 2以上減少 | E71: 正常 | G71: 1. 引数に以下を指定して、integrate.ChangeSpatialIdsZoomを呼び出す。 "【別紙1】変換前後の精度差パターン"シート"空間ID試験データ"のNo.5の「変換前拡張空間ID」「変換後水平方向精度」「変換後水平方向精度」 | H71: ・入力した座標パターンに対応した期待値が取得できること ・変換後の拡張空間ID数が期待値通りになっていること ・エラーインスタンスが返却されていないこと | I71: 44956 | J71: 宮原 | K71: OK | R71: =IF(ROW()<>3,IF(B70<>B71,R70+1,R70),1) -> 4 | S71: =IF(B70=B71,IF(C70<>C71,S70+1,S70),1) -> 1 | T71: =IF(B70<>B71,1,IF(C70=C71,T70+1,1)) -> 5
A72: =IF(B72<>"",表紙!$AB$1&"-"&"結合-"&TEXT($S$1,"00")&"-"&TEXT(R72,"00")&"-"&TEXT(S72,"00")&"-"&TEXT(T72,"０00"),"") -> 精度変換-結合-01-04-02-001 | B72: 精度変換の試験パターンの網羅(空間ID) | C72: 変換前空間IDを1つ入力 | M72: =$A$67 -> 精度変換-結合-01-04-01-001 | R72: =IF(ROW()<>3,IF(B69<>B72,R69+1,R69),1) -> 4 | S72: =IF(B69=B72,IF(C69<>C72,S69+1,S69),1) -> 2 | T72: =IF(B69<>B72,1,IF(C69=C72,T69+1,1)) -> 1
A73: =IF(B73<>"",表紙!$AB$1&"-"&"結合-"&TEXT($S$1,"00")&"-"&TEXT(R73,"00")&"-"&TEXT(S73,"00")&"-"&TEXT(T73,"０00"),"") -> 精度変換-結合-01-04-03-001 | B73: 精度変換の試験パターンの網羅(空間ID) | C73: 変換前空間IDを複数入力 | D73: 入力数：2 | E73: 正常 | G73: 1. 引数に以下を指定して、integrate.ChangeExtendedSpatialIdsZoomを呼び出す。 "【別紙5】変換前拡張空間IDの複数入力パターン"シート"空間ID試験データ"のNo.1の「変換前空間ID」「変換後水平方向精度」「変換後水平方向精度」 | H73: ・入力した座標パターンに対応した期待値が取得できること ・エラーインスタンスが返却されていないこと | I73: 44956 | J73: 宮原 | K73: OK | R73: =IF(ROW()<>3,IF(B72<>B73,R72+1,R72),1) -> 4 | S73: =IF(B72=B73,IF(C72<>C73,S72+1,S72),1) -> 3 | T73: =IF(B72<>B73,1,IF(C72=C73,T72+1,1)) -> 1
A74: =IF(B74<>"",表紙!$AB$1&"-"&"結合-"&TEXT($S$1,"00")&"-"&TEXT(R74,"00")&"-"&TEXT(S74,"00")&"-"&TEXT(T74,"０00"),"") -> 精度変換-結合-01-04-03-002 | B74: 精度変換の試験パターンの網羅(空間ID) | C74: 変換前空間IDを複数入力 | D74: 入力数：10 | E74: 正常 | G74: 1. 引数に以下を指定して、integrate.ChangeExtendedSpatialIdsZoomを呼び出す。 "【別紙5】変換前拡張空間IDの複数入力パターン"シート"空間ID試験データ"のNo.2の「変換前空間ID」「変換後水平方向精度」「変換後水平方向精度」 | H74: ・入力した座標パターンに対応した期待値が取得できること ・エラーインスタンスが返却されていないこと | I74: 44956 | J74: 宮原 | K74: OK | R74: =IF(ROW()<>3,IF(B73<>B74,R73+1,R73),1) -> 4 | S74: =IF(B73=B74,IF(C73<>C74,S73+1,S73),1) -> 3 | T74: =IF(B73<>B74,1,IF(C73=C74,T73+1,1)) -> 2
A75: =IF(B75<>"",表紙!$AB$1&"-"&"結合-"&TEXT($S$1,"00")&"-"&TEXT(R75,"00")&"-"&TEXT(S75,"00")&"-"&TEXT(T75,"０00"),"") -> 精度変換-結合-01-04-04-001 | B75: 精度変換の試験パターンの網羅(空間ID) | C75: 変換前空間IDの精度を変えても精度変換結果が取得できる | D75: 変換前精度：0 変換後精度：1 | E75: 正常 | G75: 1. 引数に以下を指定して、integrate.ChangeSpatialIdsZoomを呼び出す。 空間ID：0/0/0/0 精度: 1 | H75: ・以下の空間IDが取得できること [1/0/1/1, 1/1/1/1, 1/0/0/0, 1/1/0/0, 1/0/1/0, 1/1/1/0, 1/0/0/1, 1/1/0/1] ・エラーインスタンスが返却されていないこと | I75: 44956 | J75: 宮原 | K75: OK | R75: =IF(ROW()<>3,IF(B74<>B75,R74+1,R74),1) -> 4 | S75: =IF(B74=B75,IF(C74<>C75,S74+1,S74),1) -> 4 | T75: =IF(B74<>B75,1,IF(C74=C75,T74+1,1)) -> 1
A76: =IF(B76<>"",表紙!$AB$1&"-"&"結合-"&TEXT($S$1,"00")&"-"&TEXT(R76,"00")&"-"&TEXT(S76,"00")&"-"&TEXT(T76,"０00"),"") -> 精度変換-結合-01-04-04-002 | B76: 精度変換の試験パターンの網羅(空間ID) | C76: 変換前空間IDの精度を変えても精度変換結果が取得できる | D76: 変換前精度：35 変換後精度：34 | E76: 正常 | G76: 1. 引数に以下を指定して、integrate.ChangeSpatialIdsZoomを呼び出す。 空間ID：35/10/10/10 精度: 34 | H76: ・以下の空間IDが取得できること [34/5/5/5] ・エラーインスタンスが返却されていないこと | I76: 44956 | J76: 宮原 | K76: OK | R76: =IF(ROW()<>3,IF(B75<>B76,R75+1,R75),1) -> 4 | S76: =IF(B75=B76,IF(C75<>C76,S75+1,S75),1) -> 4 | T76: =IF(B75<>B76,1,IF(C75=C76,T75+1,1)) -> 2
A77: =IF(B77<>"",表紙!$AB$1&"-"&"結合-"&TEXT($S$1,"00")&"-"&TEXT(R77,"00")&"-"&TEXT(S77,"00")&"-"&TEXT(T77,"０00"),"") -> 精度変換-結合-01-04-05-001 | B77: 精度変換の試験パターンの網羅(空間ID) | C77: 変換前空間IDの精度における最大/最小の空間ID入力 | D77: 経度インデクス値最小 | E77: 正常 | G77: 1. 引数に以下を指定して、integrate.ChangeSpatialIdsZoomを呼び出す。 "【別紙2】変換前の空間IDパターン"シート"拡張空間ID試験データ"のNo.1の「変換前空間ID」「変換後水平方向精度」「変換後水平方向精度」 | H77: ・入力した座標パターンに対応した期待値が取得できること ・エラーインスタンスが返却されていないこと | I77: 44956 | J77: 宮原 | K77: OK | R77: =IF(ROW()<>3,IF(B76<>B77,R76+1,R76),1) -> 4 | S77: =IF(B76=B77,IF(C76<>C77,S76+1,S76),1) -> 5 | T77: =IF(B76<>B77,1,IF(C76=C77,T76+1,1)) -> 1
A78: =IF(B78<>"",表紙!$AB$1&"-"&"結合-"&TEXT($S$1,"00")&"-"&TEXT(R78,"00")&"-"&TEXT(S78,"00")&"-"&TEXT(T78,"０00"),"") -> 精度変換-結合-01-04-05-002 | B78: 精度変換の試験パターンの網羅(空間ID) | C78: 変換前空間IDの精度における最大/最小の空間ID入力 | D78: 経度インデクス値最大 | E78: 正常 | G78: 1. 引数に以下を指定して、integrate.ChangeSpatialIdsZoomを呼び出す。 "【別紙2】変換前の空間IDパターン"シート"拡張空間ID試験データ"のNo.2の「変換前拡張空間ID」「変換後水平方向精度」「変換後水平方向精度」 | H78: ・入力した座標パターンに対応した期待値が取得できること ・エラーインスタンスが返却されていないこと | I78: 44956 | J78: 宮原 | K78: OK | R78: =IF(ROW()<>3,IF(B77<>B78,R77+1,R77),1) -> 4 | S78: =IF(B77=B78,IF(C77<>C78,S77+1,S77),1) -> 5 | T78: =IF(B77<>B78,1,IF(C77=C78,T77+1,1)) -> 2
A79: =IF(B79<>"",表紙!$AB$1&"-"&"結合-"&TEXT($S$1,"00")&"-"&TEXT(R79,"00")&"-"&TEXT(S79,"00")&"-"&TEXT(T79,"０00"),"") -> 精度変換-結合-01-04-05-003 | B79: 精度変換の試験パターンの網羅(空間ID) | C79: 変換前空間IDの精度における最大/最小の空間ID入力 | D79: 緯度インデクス値最小 | E79: 正常 | G79: 1. 引数に以下を指定して、integrate.ChangeSpatialIdsZoomを呼び出す。 "【別紙2】変換前の空間IDパターン"シート"拡張空間ID試験データ"のNo.3の「変換前拡張空間ID」「変換後水平方向精度」「変換後水平方向精度」 | H79: ・入力した座標パターンに対応した期待値が取得できること ・エラーインスタンスが返却されていないこと | I79: 44956 | J79: 宮原 | K79: OK | R79: =IF(ROW()<>3,IF(B78<>B79,R78+1,R78),1) -> 4 | S79: =IF(B78=B79,IF(C78<>C79,S78+1,S78),1) -> 5 | T79: =IF(B78<>B79,1,IF(C78=C79,T78+1,1)) -> 3
A80: =IF(B80<>"",表紙!$AB$1&"-"&"結合-"&TEXT($S$1,"00")&"-"&TEXT(R80,"00")&"-"&TEXT(S80,"00")&"-"&TEXT(T80,"０00"),"") -> 精度変換-結合-01-04-05-004 | B80: 精度変換の試験パターンの網羅(空間ID) | C80: 変換前空間IDの精度における最大/最小の空間ID入力 | D80: 緯度インデクス値最大 | E80: 正常 | G80: 1. 引数に以下を指定して、integrate.ChangeSpatialIdsZoomを呼び出す。 "【別紙2】変換前の空間IDパターン"シート"拡張空間ID試験データ"のNo.4の「変換前拡張空間ID」「変換後水平方向精度」「変換後水平方向精度」 | H80: ・入力した座標パターンに対応した期待値が取得できること ・エラーインスタンスが返却されていないこと | I80: 44956 | J80: 宮原 | K80: OK | R80: =IF(ROW()<>3,IF(B79<>B80,R79+1,R79),1) -> 4 | S80: =IF(B79=B80,IF(C79<>C80,S79+1,S79),1) -> 5 | T80: =IF(B79<>B80,1,IF(C79=C80,T79+1,1)) -> 4
A81: =IF(B81<>"",表紙!$AB$1&"-"&"結合-"&TEXT($S$1,"00")&"-"&TEXT(R81,"00")&"-"&TEXT(S81,"00")&"-"&TEXT(T81,"０00"),"") -> 精度変換-結合-01-04-05-005 | B81: 精度変換の試験パターンの網羅(空間ID) | C81: 変換前空間IDの精度における最大/最小の空間ID入力 | D81: 高さインデクス値最小 | E81: 正常 | G81: 1. 引数に以下を指定して、integrate.ChangeSpatialIdsZoomを呼び出す。 "【別紙2】変換前の空間IDパターン"シート"拡張空間ID試験データ"のNo.5の「変換前拡張空間ID」「変換後水平方向精度」「変換後水平方向精度」 | H81: ・入力した座標パターンに対応した期待値が取得できること ・エラーインスタンスが返却されていないこと | I81: 44956 | J81: 宮原 | K81: OK | R81: =IF(ROW()<>3,IF(B80<>B81,R80+1,R80),1) -> 4 | S81: =IF(B80=B81,IF(C80<>C81,S80+1,S80),1) -> 5 | T81: =IF(B80<>B81,1,IF(C80=C81,T80+1,1)) -> 5
...

Sheet 【別紙1】変換前後の精度差パターン
A1: ■ 変換前後の精度差 試験データパターン
B2: 精度変換前後の精度差に関する試験用データ
B4: 〇拡張空間ID試験データ
C5: 変換元として入力する"拡張空間ID"、"変換後の水平/垂直方向精度"及び、精度変換時に取得される期待値を以下に記載する。
C6: 試験実施時は以下に記載する入力値をAPIの引数に入力し、取得された値が期待値と同じであることを確認する。
C8: 期待値作成時の参考資料として、精度変換の仕様について"【参考】精度変換時の仕様"シートに記載している。
C10: No | D10: 変換前後の精度差パターン | E10: 変換前拡張空間ID | H10: 変換後水平方向精度 | K10: 変換後水平方向精度 | N10: 期待値 - 変換後ID値※1 | V10: 期待値 - 変換後ID数
C11: 1 | D11: 水平方向精度: 増加 垂直方向精度: 増加 | E11: 10/20/20/10/20 | H11: 11 | K11: 11 | N11: [11/40/40/11/40 11/41/40/11/40 11/40/41/11/40 11/41/41/11/40 11/40/40/11/41 11/41/40/11/41 11/40/41/11/41 11/41/41/11/41] | V11: 8
C12: 2 | D12: 水平方向精度: 減少 垂直方向精度: 増加 | E12: 10/20/20/10/20 | H12: 9 | K12: 11 | N12: [9/10/10/11/40 9/10/10/11/41] | V12: 2
C13: 3 | D13: 水平方向精度: 変更なし 垂直方向精度: 増加 | E13: 10/20/20/10/20 | H13: 10 | K13: 11 | N13: [10/20/20/11/40 10/20/20/11/41] | V13: 2
C14: 4 | D14: 水平方向精度: 増加 垂直方向精度: 減少 | E14: 10/20/20/10/20 | H14: 11 | K14: 9 | N14: [11/40/40/9/10 11/41/40/9/10 11/40/41/9/10 11/41/41/9/10] | V14: 4
C15: 5 | D15: 水平方向精度: 減少 垂直方向精度: 減少 | E15: 10/20/20/10/20 | H15: 9 | K15: 9 | N15: [9/10/10/9/10] | V15: 1
C16: 6 | D16: 水平方向精度: 変更なし 垂直方向精度: 減少 | E16: 10/20/20/10/20 | H16: 10 | K16: 9 | N16: [10/20/20/9/10] | V16: 1
C17: 7 | D17: 水平方向精度: 増加 垂直方向精度: 変更なし | E17: 10/20/20/10/20 | H17: 11 | K17: 10 | N17: [11/40/40/10/20 11/41/40/10/20 11/40/41/10/20 11/41/41/10/20] | V17: 4
C18: 8 | D18: 水平方向精度: 減少 垂直方向精度: 変更なし | E18: 10/20/20/10/20 | H18: 9 | K18: 10 | N18: [9/10/10/10/20] | V18: 1
C19: 9 | D19: 水平方向精度: 変更なし 垂直方向精度: 変更なし | E19: 10/20/20/10/20 | H19: 10 | K19: 10 | N19: [10/20/20/10/20] | V19: 1
C20: 10 | D20: 水平方向精度: 2以上増加 垂直方向精度: 2以上増加 | E20: 10/20/20/10/20 | H20: 12 | K20: 12 | N20: 12/80/80/12/80 12/80/81/12/80 12/80/82/12/80 12/80/83/12/80 12/81/80/12/80 12/81/81/12/80 12/81/82/12/80 12/81/83/12/80 12/82/80/12/80 12/82/81/12/80 12/82/82/12/80 12/82/83/12/80 12/83/80/12/80 12/83/81/12/80 12/83/82/12/80 12/83/83/12/80 12/80/80/12/81 12/80/81/12/81 12/80/82/12/81 12/80/83/12/81 12/81/80/12/81 12/81/81/12/81 12/81/82/12/81 12/81/83/12/81 12/82/80/12/81 12/82/81/12/81 12/82/82/12/81 12/82/83/12/81 12/83/80/12/81 12/83/81/12/81 12/83/82/12/81 12/83/83/12/81 12/80/80/12/82 12/80/81/12/82 12/80/82/12/82 12/80/83/12/82 12/81/80/12/82 12/81/81/12/82 12/81/82/12/82 12/81/83/12/82 12/82/80/12/82 12/82/81/12/82 12/82/82/12/82 12/82/83/12/82 12/83/80/12/82 12/83/81/12/82 12/83/82/12/82 12/83/83/12/82 12/80/80/12/83 12/80/81/12/83 12/80/82/12/83 12/80/83/12/83 12/81/80/12/83 12/81/81/12/83 12/81/82/12/83 12/81/83/12/83 12/82/80/12/83 12/82/81/12/83 12/82/82/12/83 12/82/83/12/83 12/83/80/12/83 12/83/81/12/83 12/83/82/12/83 12/83/83/12/83 | V20: 64
C21: 11 | D21: 水平方向精度: 2以上減少 垂直方向精度: 2以上減少 | E21: 10/20/20/10/20 | H21: 8 | K21: 8 | N21: [8/5/5/8/5] | V21: 1
B25: 〇空間ID試験データ
C26: 変換元として入力する"空間ID"、"変換後の精度"及び、精度変換時に取得される期待値を以下に記載する。
C27: 試験実施時は以下に記載する入力値をAPIの引数に入力し、取得された値が期待値と同じであることを確認する。
C29: No | D29: 変換前後の精度差パターン | E29: 変換前空間ID | H29: 変換後精度 | K29: 期待値 - 変換後ID値※1 | S29: 期待値 - 変換後ID数
C30: 1 | D30: 精度: 増加 | E30: 10/20/20/20 | H30: 11 | K30: [11/40/40/40 11/41/40/40 11/40/41/40 11/41/41/40 11/40/40/41 11/41/40/41 11/40/41/41 11/41/41/41] | S30: 8
C31: 2 | D31: 精度: 減少 | E31: 10/20/20/20 | H31: 9 | K31: [9/10/10/10] | S31: 1
C32: 3 | D32: 精度: 変更なし | E32: 10/20/20/20 | H32: 10 | K32: [10/20/20/20] | S32: 1
C33: 4 | D33: 精度: 2以上増加 | E33: 10/20/20/20 | H33: 12 | K33: [12/80/80/80 12/80/80/81 12/80/80/82 12/80/80/83 12/80/81/80 12/80/81/81 12/80/81/82 12/80/81/83 12/80/82/80 12/80/82/81 12/80/82/82 12/80/82/83 12/80/83/80 12/80/83/81 12/80/83/82 12/80/83/83 12/81/80/80 12/81/80/81 12/81/80/82 12/81/80/83 12/81/81/80 12/81/81/81 12/81/81/82 12/81/81/83 12/81/82/80 12/81/82/81 12/81/82/82 12/81/82/83 12/81/83/80 12/81/83/81 12/81/83/82 12/81/83/83 12/82/80/80 12/82/80/81 12/82/80/82 12/82/80/83 12/82/81/80 12/82/81/81 12/82/81/82 12/82/81/83 12/82/82/80 12/82/82/81 12/82/82/82 12/82/82/83 12/82/83/80 12/82/83/81 12/82/83/82 12/82/83/83 12/83/80/80 12/83/80/81 12/83/80/82 12/83/80/83 12/83/81/80 12/83/81/81 12/83/81/82 12/83/81/83 12/83/82/80 12/83/82/81 12/83/82/82 12/83/82/83 12/83/83/80 12/83/83/81 12/83/83/82 12/83/83/83] | S33: 64
C34: 5 | D34: 精度: 2以上減少 | E34: 10/20/20/20 | H34: 8 | K34: [8/5/5/5] | S34: 1
C37: ※1 配列に格納された空間IDの順番は不定

Sheet 【別紙2】変換前の空間IDパターン
A1: ■ 変換前の空間ID 試験データパターン
B2: 精度変換前の空間IDの精度において、空間IDの各成分がとりうる最大/最小の値が設定された空間IDを入力する際の試験用データ
B4: 〇拡張空間ID試験データ
C5: 変換元として入力する"拡張空間ID"、"変換後の水平/垂直方向精度"及び、精度変換時に取得される期待値を以下に記載する。
C6: 試験実施時は以下に記載する入力値をAPIの引数に入力し、取得された値が期待値と同じであることを確認する。
C8: 期待値作成時の参考資料として、精度の増減による空間IDの各成分の変化について"【参考】精度変換時の仕様"シートに記載している。
C10: No | D10: インデクス値パターン | E10: 変換前拡張空間ID | H10: 変換後水平方向精度 | K10: 変換後水平方向精度 | N10: 期待値 - 変換後ID値※1
C11: 1 | D11: 経度インデクス値最小 | E11: 10/0/20/10/20 | H11: 11 | K11: 11 | N11: [11/0/41/11/40 11/0/41/11/41 11/1/41/11/40 11/1/41/11/41 11/0/40/11/40 11/0/40/11/41 11/1/40/11/40 11/1/40/11/41]
C12: 2 | D12: 経度インデクス値最大 | E12: 10/1023/20/10/20 | H12: 11 | K12: 11 | N12: [11/2046/40/11/40 11/2046/40/11/41 11/2047/40/11/40 11/2047/40/11/41 11/2046/41/11/40 11/2046/41/11/41 11/2047/41/11/40 11/2047/41/11/41]
C13: 3 | D13: 緯度インデクス値最小 | E13: 10/20/0/10/20 | H13: 11 | K13: 11 | N13: [11/40/1/11/41 11/41/1/11/40 11/41/1/11/41 11/40/0/11/40 11/40/0/11/41 11/41/0/11/40 11/41/0/11/41 11/40/1/11/40]
C14: 4 | D14: 緯度インデクス値最大 | E14: 10/20/1023/10/20 | H14: 11 | K14: 11 | N14: [11/41/2046/11/41 11/40/2047/11/40 11/40/2047/11/41 11/41/2047/11/40 11/41/2047/11/41 11/40/2046/11/40 11/40/2046/11/41 11/41/2046/11/40]
C15: 5 | D15: 高さインデクス値最小 | E15: 10/20/20/10/0 | H15: 11 | K15: 11 | N15: [11/41/41/11/0 11/41/41/11/1 11/40/40/11/0 11/40/40/11/1 11/41/40/11/0 11/41/40/11/1 11/40/41/11/0 11/40/41/11/1]
C16: 6 | D16: 高さインデクス値最大 | E16: 10/20/20/10/1023 | H16: 11 | K16: 11 | N16: [11/41/40/11/2046 11/41/40/11/2047 11/40/41/11/2046 11/40/41/11/2047 11/41/41/11/2046 11/41/41/11/2047 11/40/40/11/2046 11/40/40/11/2047]
B20: 〇空間ID試験データ
C21: 変換元として入力する"空間ID"、"変換後の精度"及び、精度変換時に取得される期待値を以下に記載する。
C22: 試験実施時は以下に記載する入力値をAPIの引数に入力し、取得された値が期待値と同じであることを確認する。
C24: No | D24: インデクス値パターン | E24: 変換前空間ID | H24: 変換後精度 | K24: 期待値 - 変換後ID値※1
C25: 1 | D25: 経度インデクス値最小 | E25: 10/20/0/20 | H25: 11 | K25: [11/41/0/41 11/40/1/41 11/41/1/41 11/40/0/40 11/41/0/40 11/40/1/40 11/41/1/40 11/40/0/41]
C26: 2 | D26: 経度インデクス値最大 | E26: 10/20/1023/20 | H26: 11 | K26: [11/40/2047/40 11/41/2047/40 11/40/2046/41 11/41/2046/41 11/40/2047/41 11/41/2047/41 11/40/2046/40 11/41/2046/40]
C27: 3 | D27: 緯度インデクス値最小 | E27: 10/20/20/0 | H27: 11 | K27: [11/41/41/1 11/40/40/0 11/41/40/0 11/40/41/0 11/41/41/0 11/40/40/1 11/41/40/1 11/40/41/1]
C28: 4 | D28: 緯度インデクス値最大 | E28: 10/20/20/1023 | H28: 11 | K28: [11/40/40/2046 11/41/40/2046 11/40/41/2046 11/41/41/2046 11/40/40/2047 11/41/40/2047 11/40/41/2047 11/41/41/2047]
C29: 5 | D29: 高さインデクス値最小 | E29: 10/0/20/20 | H29: 11 | K29: [11/1/41/40 11/0/40/41 11/1/40/41 11/0/41/41 11/1/41/41 11/0/40/40 11/1/40/40 11/0/41/40]
C30: 6 | D30: 高さインデクス値最大 | E30: 10/1023/20/20 | H30: 11 | K30: [11/2047/40/40 11/2046/41/40 11/2047/41/40 11/2046/40/41 11/2047/40/41 11/2046/41/41 11/2047/41/41 11/2046/40/40]
C33: ※1 配列に格納された空間IDの順番は不定

Sheet 【別紙3】変換後拡張空間IDの重複パターン
A1: ■ 変換後拡張空間IDの重複 試験データパターン
B2: 精度変換前の空間IDの精度において、精度変換結果でIDの重複が発生する/発生しない場合の試験用データ
B4: 〇拡張空間ID試験データ
C5: 精度変換前の拡張空間IDの複数入力時、精度変換後の結果に重複する拡張空間IDが含まれていた場合、重複が解消された結果が取得できることを確認する。
C7: 変換元として入力する"拡張空間ID"、"変換後の水平/垂直方向精度"及び、精度変換時に取得される期待値を以下に記載する。
C8: 試験実施時は以下に記載する入力値をAPIの引数に入力し、取得された値が期待値と同じであることを確認する。
C10: No | D10: 重複パターン | E10: 変換前拡張空間ID | H10: 変換後水平方向精度 | K10: 変換後水平方向精度 | N10: 期待値 - 変換後ID値※1
C11: 1 | D11: 重複有り 精度を上げた場合 | E11: 10/20/20/10/20, 10/20/20/9/10 | H11: 11 | K11: 11 | N11: [11/40/40/11/40 11/40/40/11/41 11/40/40/11/42 11/40/40/11/43 11/40/41/11/40 11/40/41/11/41 11/40/41/11/42 11/40/41/11/43 11/41/40/11/40 11/41/40/11/41 11/41/40/11/42 11/41/40/11/43 11/41/41/11/40 11/41/41/11/41 11/41/41/11/42 11/41/41/11/43]
C12: 2 | D12: 重複有り 精度を下げた場合 | E12: 10/20/20/10/20, 10/20/20/9/10 | H12: 8 | K12: 8 | N12: [8/5/5/8/5]
C13: 3 | D13: 重複無し 精度を上げた場合 | E13: 10/20/20/10/20, 10/200/400/10/10 | H13: 11 | K13: 11 | N13: [11/41/40/11/41 11/400/800/11/21 11/401/800/11/21 11/400/801/11/20 11/401/801/11/20 11/41/40/11/40 11/40/41/11/40 11/40/41/11/41 11/401/801/11/21 11/41/41/11/40 11/41/41/11/41 11/401/800/11/20 11/400/801/11/21 11/40/40/11/40 11/40/40/11/41 11/400/800/11/20]
C14: 4 | D14: 重複無し 精度を下げた場合 | E14: 10/20/20/10/20, 9/20/20/9/10 | H14: 8 | K14: 8 | N14: [8/5/5/8/5 8/10/10/8/5]
B18: 〇空間ID試験データ
C19: 変換元として入力する"空間ID"、"変換後の精度"及び、精度変換時に取得される期待値を以下に記載する。
C20: 試験実施時は以下に記載する入力値をAPIの引数に入力し、取得された値が期待値と同じであることを確認する。
C22: No | D22: 重複パターン | E22: 変換前空間ID | H22: 変換後精度 | K22: 期待値 - 変換後ID値※1
C23: 1 | D23: 重複有り 精度を上げた場合 | E23: 10/21/20/20, 9/10/10/10 | H23: 11 | K23: [11/40/40/41 11/41/42/42 11/43/43/40 11/43/40/41 11/40/40/40 11/43/40/42 11/43/43/42 11/41/42/43 11/41/43/43 11/43/41/40 11/43/41/41 11/41/42/40 11/40/43/41 11/41/43/41 11/41/43/42 11/43/40/40 11/43/42/42 11/42/41/42 11/40/41/40 11/43/42/41 11/42/40/42 11/43/41/42 11/43/40/43 11/41/40/40 11/40/41/41 11/41/42/41 11/40/41/43 11/42/42/40 11/42/42/41 11/40/40/42 11/41/40/42 11/42/42/42 11/42/41/43 11/41/41/41 11/40/43/40 11/40/40/43 11/42/40/41 11/42/43/42 11/41/40/43 11/43/42/43 11/41/41/40 11/41/40/41 11/41/41/42 11/40/43/42 11/42/40/43 11/40/42/43 11/41/43/40 11/40/41/42 11/42/43/41 11/42/43/40 11/43/43/41 11/43/43/43 11/40/42/40 11/40/42/42 11/42/41/41 11/41/41/43 11/43/41/43 11/42/40/40 11/40/42/41 11/40/43/43 11/42/43/43 11/43/42/40 11/42/42/43 11/42/41/40]
C24: 2 | D24: 重複有り 精度を下げた場合 | E24: 10/21/20/20, 9/10/10/10 | H24: 8 | K24: [8/5/5/5]
C25: 3 | D25: 重複無し 精度を上げた場合 | E25: 10/400/400/400, 9/10/10/10 | H25: 11 | K25: [11/43/41/40 11/42/41/41 11/40/43/43 11/800/800/801 11/801/801/801 11/40/42/42 11/41/40/43 11/43/40/40 11/41/43/41 11/42/43/41 11/41/43/43 11/41/42/43 11/800/801/801 11/41/41/40 11/42/42/41 11/43/42/42 11/41/41/42 11/43/43/43 11/800/801/800 11/40/43/40 11/41/43/40 11/40/41/41 11/42/42/40 11/42/40/41 11/40/40/43 11/42/40/43 11/43/43/41 11/41/40/40 11/42/40/40 11/40/41/40 11/40/42/41 11/43/42/41 11/42/42/42 11/40/42/43 11/42/43/43 11/43/43/42 11/43/40/43 11/43/41/43 11/43/42/43 11/41/41/41 11/43/40/42 11/41/42/42 11/41/43/42 11/801/800/800 11/801/800/801 11/43/43/40 11/42/43/42 11/43/40/41 11/40/43/42 11/40/41/43 11/41/41/43 11/801/801/800 11/42/41/40 11/41/42/40 11/42/43/40 11/42/42/43 11/40/40/41 11/41/40/42 11/42/40/42 11/42/41/43 11/40/40/40 11/41/40/41 11/43/41/41 11/40/40/42 11/800/800/800 11/40/42/40 11/43/42/40 11/43/41/42 11/40/41/42 11/42/41/42 11/41/42/41 11/40/43/41]
C26: 4 | D26: 重複無し 精度を下げた場合 | E26: 10/21/20/20, 9/20/20/10 | H26: 8 | K26: [8/5/5/5 8/10/10/5]
C29: ※1 配列に格納された空間IDの順番は不定

Sheet 【別紙4】変換後の角に接するパターン
A1: ■ 変換後の角に接する 試験データパターン
B2: 変換で精度を減少させた際に変換前拡張空間IDが変換後の拡張空間IDの角に接するようなIDを入力する試験データ
B4: 〇拡張空間ID試験データ
C5: 変換で精度を減少させた際に変換前拡張空間IDが変換後の拡張空間IDの角に接するようなIDを変換前のIDとして用意する。
C7: 変換元として入力する"拡張空間ID"、"変換後の水平/垂直方向精度"及び、精度変換時に取得される期待値を以下に記載する。
C8: 試験実施時は以下に記載する入力値をAPIの引数に入力し、取得された値が期待値と同じであることを確認する。
C10: No | D10: 試験パターン | E10: 変換前拡張空間ID | H10: 変換後水平方向精度 | K10: 変換後水平方向精度 | N10: 期待値 - 変換後ID値※1
C11: 1 | D11: 底面左下 | E11: 12/80/80/12/80 | H11: 10 | K11: 10 | N11: [10/20/20/10/20]
C12: 2 | D12: 底面右下 | E12: 12/83/80/12/80 | H12: 10 | K12: 10 | N12: [10/20/20/10/20]
C13: 3 | D13: 底面左上 | E13: 12/80/83/12/80 | H13: 10 | K13: 10 | N13: [10/20/20/10/20]
C14: 4 | D14: 底面右上 | E14: 12/83/83/12/80 | H14: 10 | K14: 10 | N14: [10/20/20/10/20]
C15: 5 | D15: 上面左下 | E15: 12/80/80/12/83 | H15: 10 | K15: 10 | N15: [10/20/20/10/20]
C16: 6 | D16: 上面右下 | E16: 12/83/80/12/83 | H16: 10 | K16: 10 | N16: [10/20/20/10/20]
C17: 7 | D17: 上面左上 | E17: 12/80/83/12/83 | H17: 10 | K17: 10 | N17: [10/20/20/10/20]
C18: 8 | D18: 上面右上 | E18: 12/83/83/12/83 | H18: 10 | K18: 10 | N18: [10/20/20/10/20]
B22: 〇空間ID試験データ
C23: 変換元として入力する"空間ID"、"変換後の精度"及び、精度変換時に取得される期待値を以下に記載する。
C24: 試験実施時は以下に記載する入力値をAPIの引数に入力し、取得された値が期待値と同じであることを確認する。
C26: No | D26: 試験パターン | E26: 変換前空間ID | H26: 変換後精度 | K26: 期待値 - 変換後ID値※1
C27: 1 | D27: 底面左下 | E27: 12/80/80/80 | H27: 10 | K27: [10/20/20/20]
C28: 2 | D28: 底面右下 | E28: 12/80/83/80 | H28: 10 | K28: [10/20/20/20]
C29: 3 | D29: 底面左上 | E29: 12/80/80/83 | H29: 10 | K29: [10/20/20/20]
C30: 4 | D30: 底面右上 | E30: 12/80/83/83 | H30: 10 | K30: [10/20/20/20]
C31: 5 | D31: 上面左下 | E31: 12/83/80/80 | H31: 10 | K31: [10/20/20/20]
C32: 6 | D32: 上面右下 | E32: 12/83/83/80 | H32: 10 | K32: [10/20/20/20]
C33: 7 | D33: 上面左上 | E33: 12/83/80/83 | H33: 10 | K33: [10/20/20/20]
C34: 8 | D34: 上面右上 | E34: 12/83/83/83 | H34: 10 | K34: [10/20/20/20]
C37: ※1 配列に格納された空間IDの順番は不定

Sheet 【別紙5】変換前拡張空間IDの複数入力パターン
A1: ■ 変換前拡張空間IDの複数入力 試験データパターン
B2: 変換前拡張空間IDを複数入力する試験用データ
B4: 〇拡張空間ID試験データ
C5: 変換元として入力する"拡張空間ID"、"変換後の水平/垂直方向精度"及び、精度変換時に取得される期待値を以下に記載する。
C6: 試験実施時は以下に記載する入力値をAPIの引数に入力し、取得された値が期待値と同じであることを確認する。
C8: No | D8: 試験パターン | E8: 変換前拡張空間ID | H8: 変換後水平方向精度 | K8: 変換後水平方向精度 | N8: 期待値 - 変換後ID値※1
C9: 1 | D9: 入力数：2 | E9: 20/10023/10023/20/10023, 20/10024/10024/20/10024 | H9: 21 | K9: 21 | N9: [21/20046/20046/21/20046 21/20046/20047/21/20046 21/20047/20046/21/20046 21/20047/20047/21/20046 21/20046/20046/21/20047 21/20046/20047/21/20047 21/20047/20046/21/20047 21/20047/20047/21/20047 21/20048/20048/21/20048 21/20048/20049/21/20048 21/20049/20048/21/20048 21/20049/20049/21/20048 21/20048/20048/21/20049 21/20048/20049/21/20049 21/20049/20048/21/20049 21/20049/20049/21/20049]
C10: 2 | D10: 入力数：10 | E10: 20/10023/10023/20/10023, 20/10024/10024/20/10024, 20/10025/10025/20/10025, 20/10026/10026/20/10026, 20/10027/10027/20/10027, 22/40112/40112/22/40112, 22/40114/40114/22/40114, 22/40116/40116/22/40116, 22/40118/40118/22/40118, 22/40120/40120/22/40120 | H10: 21 | K10: 21 | N10: [21/20046/20046/21/20046 21/20046/20047/21/20046 21/20047/20046/21/20046 21/20047/20047/21/20046 21/20046/20046/21/20047 21/20046/20047/21/20047 21/20047/20046/21/20047 21/20047/20047/21/20047 21/20048/20048/21/20048 21/20048/20049/21/20048 21/20049/20048/21/20048 21/20049/20049/21/20048 21/20048/20048/21/20049 21/20048/20049/21/20049 21/20049/20048/21/20049 21/20049/20049/21/20049 21/20050/20050/21/20050 21/20051/20050/21/20050 21/20050/20051/21/20050 21/20051/20051/21/20050 21/20050/20050/21/20051 21/20051/20050/21/20051 21/20050/20051/21/20051 21/20051/20051/21/20051 21/20052/20052/21/20052 21/20053/20052/21/20052 21/20052/20053/21/20052 21/20053/20053/21/20052 21/20052/20052/21/20053 21/20053/20052/21/20053 21/20052/20053/21/20053 21/20053/20053/21/20053 21/20054/20054/21/20054 21/20055/20054/21/20054 21/20054/20055/21/20054 21/20055/20055/21/20054 21/20054/20054/21/20055 21/20055/20054/21/20055 21/20054/20055/21/20055 21/20055/20055/21/20055 21/20056/20056/21/20056 21/20057/20057/21/20057 21/20058/20058/21/20058 21/20059/20059/21/20059 21/20060/20060/21/20060]
B14: 〇空間ID試験データ
C15: 変換元として入力する"空間ID"、"変換後の精度"及び、精度変換時に取得される期待値を以下に記載する。
C16: 試験実施時は以下に記載する入力値をAPIの引数に入力し、取得された値が期待値と同じであることを確認する。
C18: No | D18: 試験パターン | E18: 変換前空間ID | H18: 変換後精度 | K18: 期待値 - 変換後ID値※1
C19: 1 | D19: 入力数：2 | E19: 20/10023/10023/10023, 20/10024/10024/10024 | H19: 21 | K19: [21/20046/20046/20046 21/20046/20047/20046 21/20047/20046/20046 21/20047/20047/20046 21/20046/20046/20047 21/20046/20047/20047 21/20047/20046/20047 21/20047/20047/20047 21/20048/20048/20048 21/20048/20049/20048 21/20049/20048/20048 21/20049/20049/20048 21/20048/20048/20049 21/20048/20049/20049 21/20049/20048/20049 21/20049/20049/20049]
C20: 2 | D20: 入力数：10 | E20: 20/10023/10023/10023, 20/10024/10024/10024, 20/10025/10025/10025, 20/10026/10026/10026, 20/10027/10027/10027, 22/40112/40112/40112, 22/40114/40114/40114, 22/40116/40116/40116, 22/40118/40118/40118, 22/40120/40120/40120 | H20: 21 | K20: [21/20046/20046/20046 21/20046/20046/20047 21/20046/20047/20046 21/20046/20047/20047 21/20047/20046/20046 21/20047/20046/20047 21/20047/20047/20046 21/20047/20047/20047 21/20048/20048/20048 21/20048/20048/20049 21/20048/20049/20048 21/20048/20049/20049 21/20049/20048/20048 21/20049/20048/20049 21/20049/20049/20048 21/20049/20049/20049 21/20050/20050/20050 21/20050/20051/20050 21/20050/20050/20051 21/20050/20051/20051 21/20051/20050/20050 21/20051/20051/20050 21/20051/20050/20051 21/20051/20051/20051 21/20052/20052/20052 21/20052/20053/20052 21/20052/20052/20053 21/20052/20053/20053 21/20053/20052/20052 21/20053/20053/20052 21/20053/20052/20053 21/20053/20053/20053 21/20054/20054/20054 21/20054/20055/20054 21/20054/20054/20055 21/20054/20055/20055 21/20055/20054/20054 21/20055/20055/20054 21/20055/20054/20055 21/20055/20055/20055 21/20056/20056/20056 21/20057/20057/20057 21/20058/20058/20058 21/20059/20059/20059 21/20060/20060/20060]
C23: ※1 配列に格納された空間IDの順番は不定

Sheet 【参考】精度変換時の仕様
A1: ■精度変換APIの仕様
B2: 精度変換APIによる精度変換の仕様について以下に記載する。
B3: 試験用の入力値、期待値を作成する際は、以下の情報を参考にデータを作成する。
C5: ◆拡張空間IDにおける精度を上げる場合
C6: 水平精度が1上がるごとに経度ID、緯度IDがそれぞれ2のべき乗で増加する。
C7: 垂直方向精度が1上がるごとに、高さIDが2のべき乗で増加する。
C9: 例)水平方向精度を2増加させる場合
C10: 〇入力値
C11: 変換前拡張空間ID ：10/20/20/10/20
C12: 変換後水平方向精度：12
C13: 変換後垂直方向精度：12
C15: 〇変換後の拡張空間IDの成分
C16: 変換後最小の拡張空間ID：12/80/80/12/80
C17: 変換後最大の拡張空間ID：12/83/83/12/83
C19: 試験用データを作成する際は、上記の仕様を満たす入力値、期待値となるよう検討する。
... C32: 変換後の拡張空間ID：8/5/5/8/5
A36: ■精度の増減による拡張空間IDの各成分の変化について
B37: 精度が増加する際に拡張空間IDの各成分の個数が増加する仕様について以下に記載する。
B39: 成分の開始値は"0"で、水平/垂直方向精度0の場合の拡張空間IDの個数は1個となる。
B41: 水平精度が1上がるごとに経度ID、緯度IDの個数はそれぞれ2のべき乗で増加する。
B42: 垂直方向精度が1上がるごとに、高さIDの個数は2のべき乗で増加する。
B44: そのため、試験対象の精度における拡張空間IDの成分最大値を求める際は、
B45: 以下の計算式に当てはめて成分を求める。
C47: 成分の最大値 = 2^精度 - 1
B49: 精度における成分の最大値の例を以下に記載する。
C51: 例)水平/垂直方向精度2の場合の拡張空間ID最小/最大
C52: 最小の拡張空間ID：2/0/0/2/0
C53: 最大の拡張空間ID：2/3/3/2/3
C55: 例)水平/垂直方向精度10の場合の拡張空間ID最小/最大
C56: 最小の拡張空間ID：10/0/0/10/0
C57: 最大の拡張空間ID：10/1023/1023/10/1023
